File: sample-data/QD-MH.dat
[Header]
; MPMS3 Data File (default extension .dat)
; Copyright (c) 2007, Quantum Design, Inc. All rights reserved.
TITLE,
FILEOPENTIME,3636630659.7765,03/27/2015,3:09 pm
BYAPP,SQUID AC,0.9.1.0
INFO,MPMS3 Measurement Release 1.1.15 Build 40, MultiVu Release 2.1.0.6,APPNAME
INFO,0,MOMENT_UNITS
INFO,Er,SAMPLE_MATERIAL
INFO,,SAMPLE_COMMENT
INFO,,SAMPLE_MASS
INFO,,SAMPLE_VOLUME
INFO,,SAMPLE_MOLECULAR_WEIGHT
INFO,,SAMPLE_SIZE
INFO,,SAMPLE_SHAPE
INFO,Straw,SAMPLE_HOLDER
INFO,67.06,SAMPLE_OFFSET
DATATYPE,COMMENT,1
DATATYPE,TIME,2
STARTUPAXIS,X,2
STARTUPAXIS,Y1,5
FIELDGROUP, VSM,2,3,4,5,6,8,9,10,11,14,15
FIELDGROUP, DC, 2,3,4,14,56,57,58,59,60,61,62,63,64,65,66,67,68,69
FIELDGROUP, AC, 2,3,4,11,16,17,18,19,20,21,22,23,24,25,26,27,28,29,30
STARTUPGROUP, All
[Data]
Comment,Time Stamp (sec),Temperature (K),Magnetic Field (Oe),Moment (emu),M. Std. Err. (emu),Transport Action,Averaging Time (sec),Frequency (Hz),Peak Amplitude (mm),Center Position (mm),Lockin Signal' (V),Lockin Signal" (V),Range,M. Quad. Signal (emu),AC Moment (emu),AC M. Std Err. (emu),AC Phase (deg),AC Phase Std. Err.(deg),AC Susceptibility (emu/Oe),AC Suscept. Std Err. (emu/Oe),AC X' (emu/Oe),AC X' Std Err. (emu/Oe),AC X'' (emu/Oe),AC X'' Std Err. (emu/Oe),AC Drive (Oe),AC Frequency (Hz),AC Averaging Time (sec),AC Cycles,AC Range,AC Measure Type,AC Signal' (V),AC Signal'' (V),AC Trim Coil Ratio,AC Trim Coil Phase,Min. Temperature (K),Max. Temperature (K),Min. Field (Oe),Max. Field (Oe),Mass (grams),Motor Lag (deg),Pressure (Torr),Measure Count,Measurement Number,SQUID Status (code),Motor Status (code),Measure Status (code),Motor Current (amps),Motor Temp. (C),Temp. Status (code),Field Status (code),Chamber Status (code),Chamber Temp (K),Redirection State,Average Temp (K),Rotation Angle (deg),Rotator state,DC Moment Fixed Ctr (emu),DC Moment Err Fixed Ctr(emu),DC Moment Free Ctr (emu),DC Moment Err Free Ctr(emu),DC Fixed Fit,DC Free Fit,DC Calculated Center (mm),DC Calculated Center Err,DC Scan Length (mm),DC Scan Time (s),DC Number of Points,DC Squid Drift,DC Min V (V),DC Max V (V),DC Scans per Measure,Map 01,Map 02,Map 03,Map 04,Map 05,Map 06,Map 07,Map 08,Map 09,Map 10,Map 11,Map 12,Map 13,Map 14,Map 15,Map 16
,3636631733.368,1.99957114458084,0.175663441419601,-5.79088111144718E-6,6.60409009722166E-9,1,4,13.0063810348511,5.00360974703688,30.7299997657537,-0.00707669602650564,-0.00106764064980094,1,-2.35968186357986E-9,,,,,,,,,,,,,,,,,,,,,1.99953293800354,1.99960935115814,0.175663441419601,0.175663441419601,49.8049784311303,5.29604006759806,1.84285521507263,52,1,0,0,1,0.2734375,30.3030319213867,1,1,1,1.99960935115814,0,,1.99957114458084,0,,,,,,,,,,,,,,,,,,,,,,,,,,,,,,,
,3636632612.620,1.99971300363541,28000.30078125,0.00853299834178646,8.8694588790579E-7,1,4,13.0063810348511,4.99953203453589,30.7299997657537,10.4173562792285,1.56108287669141,10,-4.97636656471895E-6,,,,,,,,,,,,,,,,,,,,,1.99945139884949,1.99997460842133,28000.30078125,28000.30078125,50.4111313477938,5.31482925145983,1.81757760047913,52,1,0,0,1,0.274429321289062,32.2580642700195,1,1,1,1.99945139884949,0,,1.99971300363541,0,,,,,,,,,,,,,,,,,,,,,,,,,,,,,,,
,3636633506.298,1.99980175495148,56000.41015625,0.00855442112724806,7.95205991543357E-7,1,4,13.0063810348511,4.99809928062783,30.7299997657537,10.4397314126069,1.56168435744737,10,-7.19405389580908E-6,,,,,,,,,,,,,,,,,,,,,1.9994695186615,2.00013399124146,56000.41015625,56000.41015625,51.3334530004862,5.32138830637164,1.80106246471405,52,1,0,0,1,0.271835327148438,32.7468223571777,1,1,1,2.00013399124146,0,,1.99980175495148,0,,,,,,,,,,,,,,,,,,,,,,,,,,,,,,,
,3636634571.862,3.99995231628418,23500.40625,0.00723467150877774,7.04876750037484E-7,1,4,13.0063810348511,4.99709186331032,30.7299997657537,8.82651380328667,1.3211796692365,10,-5.42894943796494E-6,,,,,,,,,,,,,,,,,,,,,3.99984407424927,4.00006055831909,23500.40625,23500.40625,50.1410786943995,5.32335683067373,2.51600241661072,52,1,0,0,1,0.274658203125,32.7468223571777,1,1,1,3.99984407424927,0,,3.99995231628418,0,,,,,,,,,,,,,,,,,,,,,,,,,,,,,,,
,3636635465.447,3.99997627735138,51500.39453125,0.00857138218662382,5.89239461679061E-7,1,4,13.0063810348511,4.99642026254936,30.7299997657537,10.4558130947314,1.56208337343833,10,-8.81735513559467E-6,,,,,,,,,,,,,,,,,,,,,3.99982523918152,4.00012731552124,51500.39453125,51500.39453125,50.7847497799861,5.32722328878666,2.50892114639282,52,1,0,0,1,0.276870727539062,32.7468223571777,1,1,1,3.99982523918152,0,,3.99997627735138,0,,,,,,,,,,,,,,,,,,,,,,,,,,,,,,,
,3636636533.728,5.9999988079071,19000.197265625,0.00587576374966189,5.54816648341836E-7,1,4,13.0063810348511,4.98393063898125,30.7299997657537,7.14238681545036,1.0678125841256,10,-5.44061400717097E-6,,,,,,,,,,,,,,,,,,,,,5.99995994567871,6.0000376701355,19000.197265625,19000.197265625,49.9437174932937,5.33492255049807,2.9585268497467,52,1,0,0,1,0.266189575195313,32.2580642700195,1,1,1,5.99995994567871,0,,5.9999988079071,0,,,,,,,,,,,,,,,,,,,,,,,,,,,,,,,
,3636637422.141,6.00013828277588,47000.34765625,0.00857312057637324,8.97276006487492E-7,1,4,13.0063810348511,4.98317653780919,30.7299997657537,10.4187867887785,1.55907613614979,10,-6.7873251010454E-6,,,,,,,,,,,,,,,,,,,,,6.00009965896606,6.00017690658569,47000.34765625,47000.34765625,50.2610586721015,5.338658912733,2.95821738243103,52,1,0,0,1,0.271835327148438,32.2580642700195,1,1,1,6.00009965896606,0,,6.00013828277588,0,,,,,,,,,,,,,,,,,,,,,,,,,,,,,,,
,3636638523.420,8.00000381469727,14500.138671875,0.00451748187924862,3.93743820057386E-7,1,4,13.0063810348511,4.98223296625872,30.7299997657537,5.48884419858888,0.819510391521646,10,-5.06173525670309E-6,,,,,,,,,,,,,,,,,,,,,7.9998950958252,8.00011253356934,14500.138671875,14500.138671875,50.0191446453995,5.3401775521785,3.24746131896973,52,1,0,0,1,0.274200439453125,32.2580642700195,1,1,1,7.99984407424927,0,,8.00000381469727,0,,,,,,,,,,,,,,,,,,,,,,,,,,,,,,,
,3636639405.637,8.00035095214844,42500.3671875,0.00856619946583255,7.42886932018345E-7,1,4,13.0063810348511,4.97954790576235,30.7299997657537,10.3999760269081,1.55476276209122,10,-7.98912841005981E-6,,,,,,,,,,,,,,,,,,,,,8.00024127960205,8.00046062469482,42500.3671875,42500.3671875,50.3063931262169,5.3523938217423,3.25847268104553,52,1,0,0,1,0.27496337890625,31.7693061828613,1,1,1,8.00024127960205,0,,8.00035095214844,0,,,,,,,,,,,,,,,,,,,,,,,,,,,,,,,
,3636640490.440,10.0000405311584,10000.4326171875,0.0031360787911687,2.451121446985E-7,1,4,13.0063810348511,5.0003354207947,30.7299997657537,3.83009843468074,0.569785224462755,10,-5.16925406589657E-6,,,,,,,,,,,,,,,,,,,,,10.0000038146973,10.0000772476196,10000.4326171875,10000.4326171875,49.7983345887168,5.34937634445504,3.48186659812927,52,1,0,0,1,0.278778076171875,32.2580642700195,1,1,1,10.0000038146973,0,,10.0000405311584,0,,,,,,,,,,,,,,,,,,,,,,,,,,,,,,,
,3636641363.884,10.0002999305725,38000.45703125,0.00854975804832782,6.219451878979E-7,1,4,13.0063810348511,4.999426229346,30.7299997657537,10.4379478794304,1.56118107243134,10,-7.37959940298871E-6,,,,,,,,,,,,,,,,,,,,,10.0001745223999,10.0004253387451,38000.45703125,38000.45703125,50.1524123079284,5.35444968018139,3.48481154441833,52,1,0,0,1,0.27587890625,32.7468223571777,1,1,1,10.0004253387451,0,,10.0002999305725,0,,,,,,,,,,,,,,,,,,,,,,,,,,,,,,,
,3636642459.968,11.9999570846558,5500.47412109375,0.0017455116099919,1.50107629190568E-7,1,4,13.0063810348511,4.99947522013379,30.7299997657537,2.13138871702528,0.316363415401575,10,-3.44844187602318E-6,,,,,,,,,,,,,,,,,,,,,11.9998741149902,12.0000400543213,5500.47412109375,5500.47412109375,49.863209755813,5.35276829568477,3.64777398109436,52,1,0,0,1,0.277862548828125,32.2580642700195,1,1,1,11.9998741149902,0,,11.9999570846558,0,,,,,,,,,,,,,,,,,,,,,,,,,,,,,,,
,3636643331.011,11.9995322227478,33500.34765625,0.00852153404454795,9.45778242507643E-7,1,4,13.0063810348511,4.99988159149662,30.7299997657537,10.4052209648539,1.55352803124699,10,-9.56473308053744E-6,,,,,,,,,,,,,,,,,,,,,11.9994134902954,11.9996509552002,33500.34765625,33500.34765625,49.9011187389957,5.35186067321448,3.64630770683289,52,1,0,0,1,0.275650024414062,32.2580642700195,1,1,1,11.9994134902954,0,,11.9995322227478,0,,,,,,,,,,,,,,,,,,,,,,,,,,,,,,,
,3636644433.480,14.0001864433289,999.913940429688,0.000407181922681133,5.30155895434199E-8,1,4,13.0063810348511,4.99893124659944,30.7299997657537,0.497046467199953,0.074285305674749,1,-3.97005882343001E-7,,,,,,,,,,,,,,,,,,,,,14.0001173019409,14.0002555847168,999.913940429688,999.913940429688,49.8069325024283,5.35453609720658,3.78028345108032,52,1,0,0,1,0.275955200195313,31.2805480957031,1,1,1,14.0001173019409,0,,14.0001864433289,0,,,,,,,,,,,,,,,,,,,,,,,,,,,,,,,
,3636645305.128,14.000316619873,29000.365234375,0.00846753120872542,6.88115667092724E-7,1,4,13.0063810348511,4.998748673874,30.7299997657537,10.3358894996217,1.54397065285158,10,-8.8678364867093E-6,,,,,,,,,,,,,,,,,,,,,14.0003089904785,14.0003242492676,29000.365234375,29000.365234375,50.0023396322361,5.35434797282678,3.79160737991333,52,1,0,0,1,0.282058715820313,31.7693061828613,1,1,1,14.0003242492676,0,,14.000316619873,0,,,,,,,,,,,,,,,,,,,,,,,,,,,,,,,
,3636646201.708,13.9998440742493,57000.40234375,0.00848250477733785,6.36919667069405E-7,1,4,13.0063810348511,4.99871227831903,30.7299997657537,10.3543621117054,1.54468778172493,10,-1.05201436010368E-5,,,,,,,,,,,,,,,,,,,,,13.9997091293335,13.999979019165,57000.40234375,57000.40234375,50.2227588746592,5.35587095717839,3.78638482093811,52,1,0,0,1,0.282135009765625,31.7693061828613,1,1,1,13.999979019165,0,,13.9998440742493,0,,,,,,,,,,,,,,,,,,,,,,,,,,,,,,,
,3636647287.740,16.0001249313354,24500.34375,0.00762198791524132,8.40605817005507E-7,1,4,13.0063810348511,4.99841714962674,30.7299997657537,9.30309176676539,1.38848901149132,10,-8.9462532954598E-6,,,,,,,,,,,,,,,,,,,,,16.0001163482666,16.0001335144043,24500.34375,24500.34375,49.9034636245534,5.35509632251629,3.80144238471985,52,1,0,0,1,0.282440185546875,31.7693061828613,1,1,1,16.0001335144043,0,,16.0001249313354,0,,,,,,,,,,,,,,,,,,,,,,,,,,,,,,,
,3636648183.835,15.9999394416809,52500.40625,0.00847963850872725,6.67920914907198E-7,1,4,13.0063810348511,4.99888735215679,30.7299997657537,10.3511139066559,1.54594423241572,10,-9.12142277417516E-6,,,,,,,,,,,,,,,,,,,,,15.9998817443848,15.999997138977,52500.40625,52500.40625,50.1414695086592,5.35303354977196,3.7938129901886,52,1,0,0,1,0.27679443359375,31.7693061828613,1,1,1,15.9998817443848,0,,15.9999394416809,0,,,,,,,,,,,,,,,,,,,,,,,,,,,,,,,
,3636649264.553,17.99986743927,20000.375,0.00615357914441628,5.51369335293868E-7,1,4,13.0063810348511,4.99849035317673,30.7299997657537,7.51101144312878,1.12070403770194,10,-7.47636418790102E-6,,,,,,,,,,,,,,,,,,,,,17.9998149871826,17.9999198913574,20000.375,20000.375,49.756517462938,5.35397461347724,3.88960599899292,52,1,0,0,1,0.283355712890625,32.7468223571777,1,1,1,17.9999198913574,0,,17.99986743927,0,,,,,,,,,,,,,,,,,,,,,,,,,,,,,,,
,3636650158.298,18.0001134872437,48000.3125,0.0084665171975322,6.13429652603257E-7,1,4,13.0063810348511,4.99949216917049,30.7299997657537,10.3367650947778,1.54434139213059,10,-8.67453475128504E-6,,,,,,,,,,,,,,,,,,,,,18.0000648498535,18.0001621246338,48000.3125,48000.3125,50.0007763751976,5.34945108859861,3.90058469772339,52,1,0,0,1,0.277023315429687,31.2805480957031,1,1,1,18.0000648498535,0,,18.0001134872437,0,,,,,,,,,,,,,,,,,,,,,,,,,,,,,,,
,3636651244.389,19.9999980926514,15500.2294921875,0.00457854371306585,4.66412239706558E-7,1,4,13.0063810348511,4.99814424101545,30.7299997657537,5.58811056200177,0.833001769628636,10,-6.19579464058933E-6,,,,,,,,,,,,,,,,,,,,,19.9999713897705,20.0000247955322,15500.2294921875,15500.2294921875,49.8366343861591,5.35387601343306,3.97494745254517,52,1,0,0,1,0.274887084960938,31.7693061828613,1,1,1,20.0000247955322,0,,19.9999980926514,0,,,,,,,,,,,,,,,,,,,,,,,,,,,,,,,
,3636652122.842,20.0001029968262,43500.48046875,0.00844416257629048,7.96097320578408E-7,1,4,13.0063810348511,4.99706810206428,30.7299997657537,10.3026881099468,1.53787102147822,10,-9.75735534515285E-6,,,,,,,,,,,,,,,,,,,,,20.0000381469727,20.0001678466797,43500.48046875,43500.48046875,49.9288665514284,5.35873832961012,3.97183084487915,52,1,0,0,1,0.27130126953125,31.7693061828613,1,1,1,20.0000381469727,0,,20.0001029968262,0,,,,,,,,,,,,,,,,,,,,,,,,,,,,,,,
,3636653247.085,21.9999952316284,11000.107421875,0.00290511699963174,2.11593537396701E-7,1,4,13.0063810348511,4.99822591201469,30.7299997657537,3.54602466206634,0.526897895443529,10,-5.29116224604111E-6,,,,,,,,,,,,,,,,,,,,,21.9999618530273,22.0000286102295,11000.107421875,11000.107421875,49.8335078720822,5.35531279323086,4.04530429840088,52,1,0,0,1,0.276870727539062,31.7693061828613,1,1,1,21.9999618530273,0,,21.9999952316284,0,,,,,,,,,,,,,,,,,,,,,,,,,,,,,,,
,3636654127.272,21.9999074935913,39000.2578125,0.00840732850853029,6.87489998854176E-7,1,4,13.0063810348511,4.99816594617158,30.7299997657537,10.2608464101358,1.53197481530962,10,-9.43470228162695E-6,,,,,,,,,,,,,,,,,,,,,21.9998970031738,21.9999179840088,39000.2578125,39000.2578125,49.9042452530726,5.35424626785048,4.05504179000854,52,1,0,0,1,0.275802612304687,31.2805480957031,1,1,1,21.9999179840088,0,,21.9999074935913,0,,,,,,,,,,,,,,,,,,,,,,,,,,,,,,,
,3636655219.248,24.0002136230469,6500.42578125,0.00118798572133799,9.77553026423256E-8,1,4,13.0063810348511,4.99883019706356,30.7299997657537,1.44997955086493,0.217738590451435,1,-3.29598969118621E-7,,,,,,,,,,,,,,,,,,,,,24.0001983642578,24.0002288818359,6500.42578125,6500.42578125,49.8628189415534,5.35225197247743,4.10258197784424,51,1,68,0,0,0.27587890625,31.7693061828613,1,1,1,24.0001983642578,0,,24.0002136230469,0,,,,,,,,,,,,,,,,,,,,,,,,,,,,,,,
,3636656100.311,24.0000352859497,34500.4140625,0.00835146399942935,7.18416085288716E-7,1,4,13.0063810348511,4.99832708289555,30.7299997657537,10.1926802758446,1.52482063405308,10,-6.9490215004472E-6,,,,,,,,,,,,,,,,,,,,,23.9999732971191,24.0000972747803,34500.4140625,34500.4140625,49.7854377181495,5.35362846840935,4.11307096481323,52,1,0,0,1,0.275726318359375,31.2805480957031,1,1,1,23.9999732971191,0,,24.0000352859497,0,,,,,,,,,,,,,,,,,,,,,,,,,,,,,,,
,3636657198.273,25.9998846054077,1999.58947753906,0.000160109175350286,1.49447357139914E-8,1,4,13.0063810348511,4.98843536399293,30.7299997657537,0.194879157473802,0.0290719133500611,1,-1.99061809021765E-7,,,,,,,,,,,,,,,,,,,,,25.9998798370361,25.9998893737793,1999.58947753906,1999.58947753906,49.7952080746399,5.34940356174458,4.15887451171875,52,1,0,0,1,0.275192260742187,31.2805480957031,1,1,1,25.9998893737793,0,,25.9998846054077,0,,,,,,,,,,,,,,,,,,,,,,,,,,,,,,,
,3636658075.127,25.999885559082,30000.416015625,0.00819741213038338,7.70010187925166E-7,1,4,13.0063810348511,4.98917556334387,30.7299997657537,9.9788063572251,1.494492771092,10,-5.48096744939281E-6,,,,,,,,,,,,,,,,,,,,,25.9998416900635,25.9999294281006,30000.416015625,30000.416015625,49.9069809528899,5.34802598520758,4.16800212860107,52,1,0,0,1,0.273590087890625,31.7693061828613,1,1,1,25.9998435974121,0,,25.999885559082,0,,,,,,,,,,,,,,,,,,,,,,,,,,,,,,,
,3636658971.573,26.0001440048218,58000.390625,0.00835419896834598,5.13430263464218E-7,1,4,13.0063810348511,4.98875288667825,30.7299997657537,10.1686170213195,1.52184545070243,10,-6.44932796206325E-6,,,,,,,,,,,,,,,,,,,,,26.0001392364502,26.0001487731934,58000.390625,58000.390625,49.8983830391784,5.35028421831086,4.15981245040894,52,1,0,0,1,0.277938842773438,31.7693061828613,1,1,1,26.0001392364502,0,,26.0001440048218,0,,,,,,,,,,,,,,,,,,,,,,,,,,,,,,,
,3636660049.072,28.0001049041748,25500.185546875,0.00686525811931644,6.15492528058881E-7,1,4,13.0063810348511,4.98827251434664,30.74000030756,8.35565952769178,1.24720450756932,10,-7.96158480797937E-6,,,,,,,,,,,,,,,,,,,,,27.9999408721924,28.0002689361572,25500.185546875,25500.185546875,49.753390948861,5.35057644729879,4.21326017379761,52,1,0,0,1,0.2728271484375,31.7693061828613,1,1,1,28.0002689361572,0,,28.0001049041748,0,,,,,,,,,,,,,,,,,,,,,,,,,,,,,,,
,3636660945.431,27.9998264312744,53500.38671875,0.00831889332375432,7.50033422350268E-7,1,4,13.0063810348511,4.98733902371855,30.74000030756,10.1217908782831,1.513719743891,10,-7.32054483956497E-6,,,,,,,,,,,,,,,,,,,,,27.9997501373291,27.9999027252197,53500.38671875,53500.38671875,49.9788907766591,5.35503095897138,4.21287059783936,52,1,0,0,1,0.273513793945313,31.7693061828613,1,1,1,27.9997501373291,0,,27.9998264312744,0,,,,,,,,,,,,,,,,,,,,,,,,,,,,,,,
,3636662027.106,29.9999713897705,21000.4765625,0.005220496186095,4.83986438057039E-7,1,4,13.0063810348511,4.99805262118335,30.74000030756,6.37163078982304,0.948569960147601,10,-8.04933322567871E-6,,,,,,,,,,,,,,,,,,,,,29.9999256134033,30.0000171661377,21000.4765625,21000.4765625,49.8288181009668,5.35256928769121,4.26174592971802,52,1,0,0,1,0.27435302734375,31.7693061828613,1,1,1,29.9999256134033,0,,29.9999713897705,0,,,,,,,,,,,,,,,,,,,,,,,,,,,,,,,
,3636662921.916,29.999885559082,49000.2421875,0.00826379571742896,5.32793782264159E-7,1,4,13.0063810348511,4.99873909291723,30.74000030756,10.0874356433117,1.50507045679618,10,-1.00859078845732E-5,,,,,,,,,,,,,,,,,,,,,29.9997291564941,30.0000419616699,49000.2421875,49000.2421875,49.9370736508803,5.34965997267967,4.25675964355469,52,1,0,0,1,0.280532836914062,31.7693061828613,1,1,1,29.9997291564941,0,,29.999885559082,0,,,,,,,,,,,,,,,,,,,,,,,,,,,,,,,
,3636664024.634,31.9998502731323,16500.255859375,0.00351030917162377,3.45475220603559E-7,1,4,13.0063810348511,4.99880440244012,30.74000030756,4.28538249020339,0.637036979490536,10,-6.16970392178025E-6,,,,,,,,,,,,,,,,,,,,,31.9997787475586,31.9999217987061,16500.255859375,16500.255859375,49.8866586113899,5.34927114906859,4.29298162460327,52,1,0,0,1,0.279159545898438,31.7693061828613,1,1,1,31.9997787475586,0,,31.9998502731323,0,,,,,,,,,,,,,,,,,,,,,,,,,,,,,,,
,3636664909.278,31.9999151229858,44500.35546875,0.00819473085771843,5.98627928120209E-7,1,4,13.0063810348511,4.99951782647415,30.74000030756,10.0055267894627,1.49136240089255,10,-1.11930457364513E-5,,,,,,,,,,,,,,,,,,,,,31.9999141693115,31.9999160766602,44500.35546875,44500.35546875,49.8858769828707,5.3469636460413,4.2921199798584,52,1,0,0,1,0.279617309570313,31.7693061828613,1,1,1,31.9999160766602,0,,31.9999151229858,0,,,,,,,,,,,,,,,,,,,,,,,,,,,,,,,
,3636665999.178,34.0001106262207,12000.2216796875,0.00179473742993468,1.39534750197544E-7,1,4,13.0063810348511,4.99794413508957,30.74000030756,2.18990056976645,0.329520400486967,1,3.93005760111565E-8,,,,,,,,,,,,,,,,,,,,,34.0000839233398,34.0001373291016,12000.2216796875,12000.2216796875,49.7326777931014,5.35218721917187,4.30418586730957,51,1,68,0,0,0.270462036132813,31.2805480957031,1,1,1,34.0000839233398,0,,34.0001106262207,0,,,,,,,,,,,,,,,,,,,,,,,,,,,,,,,
,3636666880.199,34.0001125335693,40000.28515625,0.0081023943112381,6.61918411080815E-7,1,4,13.0063810348511,4.99853344265025,30.74000030756,9.89027352054236,1.47275936389334,10,-1.22082517821166E-5,,,,,,,,,,,,,,,,,,,,,34.0001106262207,34.000114440918,40000.28515625,40000.28515625,49.936292022361,5.35045712631427,4.32986736297607,52,1,0,0,1,0.279006958007813,31.2805480957031,1,1,1,34.000114440918,0,,34.0001125335693,0,,,,,,,,,,,,,,,,,,,,,,,,,,,,,,,
,3636667976.547,36.0001659393311,7500.2392578125,0.000614097028133663,3.51303259423523E-8,1,4,13.0063810348511,4.99927424116221,30.74000030756,0.749680326129982,0.112171765863462,1,-4.95022637151993E-7,,,,,,,,,,,,,,,,,,,,,36.0001182556152,36.0002136230469,7500.2392578125,7500.2392578125,49.7811387612937,5.35021086243224,4.3561520576477,52,1,0,0,1,0.276870727539062,31.7693061828613,1,1,1,36.0002136230469,0,,36.0001659393311,0,,,,,,,,,,,,,,,,,,,,,,,,,,,,,,,
,3636668858.447,35.9999351501465,35500.265625,0.00795070727156284,5.93898169658033E-7,1,4,13.0063810348511,4.99892650092355,30.74000030756,9.70551854806688,1.44975561810449,10,-8.36704411528129E-6,,,,,,,,,,,,,,,,,,,,,35.9998779296875,35.9999923706055,35500.265625,35500.265625,49.7682418907264,5.35026437639976,4.35684680938721,52,1,0,0,1,0.278091430664062,31.2805480957031,1,1,1,35.9998779296875,0,,35.9999351501465,0,,,,,,,,,,,,,,,,,,,,,,,,,,,,,,,
,3636669961.582,37.999719619751,3000.28149414063,0.000232798039671897,2.44591156192777E-8,1,4,13.0063810348511,4.98883717325757,30.74000030756,0.283389737585579,0.0422463022149705,1,-3.13179242600363E-7,,,,,,,,,,,,,,,,,,,,,37.9996452331543,37.9997940063477,3000.28149414063,3000.28149414063,49.8229558870726,5.34793395695417,4.37862110137939,52,1,0,0,1,0.2752685546875,31.2805480957031,1,1,1,37.9997940063477,0,,37.999719619751,0,,,,,,,,,,,,,,,,,,,,,,,,,,,,,,,
,3636670855.048,37.9996547698975,31000.408203125,0.00706485018369378,4.57266534098735E-7,1,4,13.0063810348511,4.98852319023166,30.74000030756,8.59942601113584,1.28196294371913,10,-9.50084206553896E-6,,,,,,,,,,,,,,,,,,,,,37.9995460510254,37.9997634887695,31000.408203125,31000.408203125,49.8424966000534,5.3490148211218,4.39254140853882,52,1,0,0,1,0.28167724609375,31.2805480957031,1,1,1,37.9997634887695,0,,37.9996547698975,0,,,,,,,,,,,,,,,,,,,,,,,,,,,,,,,
,3636671753.924,37.9997901916504,59000.28125,0.00803411104015144,5.99502740005779E-7,1,4,13.0063810348511,4.98898087026676,30.74000030756,9.78032606953833,1.45904279770808,10,-9.97123373646647E-6,,,,,,,,,,,,,,,,,,,,,37.9997673034668,37.999813079834,59000.28125,59000.28125,49.7873917894476,5.34770143866796,4.39602851867676,52,1,0,0,1,0.27069091796875,31.2805480957031,1,1,1,37.9997673034668,0,,37.9997901916504,0,,,,,,,,,,,,,,,,,,,,,,,,,,,,,,,
,3636672852.935,40.0000419616699,26500.349609375,0.00540459695186371,6.12157589188297E-7,1,4,13.0063810348511,4.98895555875955,30.7500008493662,6.57949532808568,0.979803499526388,10,-8.10181520927822E-6,,,,,,,,,,,,,,,,,,,,,39.9999084472656,40.0001754760742,26500.349609375,26500.349609375,49.7733224761014,5.34794521927093,4.41371536254883,52,1,0,0,1,0.274658203125,30.7917900085449,1,1,1,39.9999122619629,0,,40.0000419616699,0,,,,,,,,,,,,,,,,,,,,,,,,,,,,,,,
,3636673746.519,39.9998264312744,54500.421875,0.00793161677435905,4.31058801274128E-7,1,4,13.0063810348511,4.98899399814551,30.7500008493662,9.65558826042339,1.44044758910739,10,-9.83329660993132E-6,,,,,,,,,,,,,,,,,,,,,39.9997749328613,39.9998779296875,54500.421875,54500.421875,49.7795755042553,5.34713799914908,4.42410564422607,52,1,0,0,1,0.26947021484375,31.2805480957031,1,1,1,39.9997749328613,0,,39.9998264312744,0,,,,,,,,,,,,,,,,,,,,,,,,,,,,,,,
,3636674857.059,41.9998989105225,22000.365234375,0.00365417710016377,2.2638359550678E-7,1,4,13.0063810348511,4.97999313859312,30.7500008493662,4.43778083886131,0.658039428763836,10,-7.75360582083896E-6,,,,,,,,,,,,,,,,,,,,,41.9998321533203,41.9999656677246,22000.365234375,22000.365234375,49.7522185060822,5.34366185398829,4.44826316833496,52,1,0,0,1,0.27496337890625,31.2805480957031,1,1,1,41.9999656677246,0,,41.9998989105225,0,,,,,,,,,,,,,,,,,,,,,,,,,,,,,,,
,3636675752.233,41.9998893737793,50000.078125,0.00779396537601888,5.63925568906305E-7,1,4,13.0063810348511,4.98004783646748,30.7500008493662,9.46463147858242,1.40901093381457,10,-1.20384898732474E-5,,,,,,,,,,,,,,,,,,,,,41.9998817443848,41.9998970031738,50000.078125,50000.078125,49.8120130878034,5.34361538910639,4.44887256622314,52,1,0,0,1,0.277023315429687,30.7917900085449,1,1,1,41.9998970031738,0,,41.9998893737793,0,,,,,,,,,,,,,,,,,,,,,,,,,,,,,,,
,3636676878.654,43.9999752044678,17500.220703125,0.00195869619790325,2.20172347237031E-7,1,4,13.0063810348511,4.98048799649684,30.7500008493662,2.37913109290266,0.352238450792853,10,-4.59264259251411E-6,,,,,,,,,,,,,,,,,,,,,43.9999580383301,43.9999923706055,17500.220703125,17500.220703125,49.9581776208995,5.34096827018925,4.46405982971191,52,1,0,0,1,0.273361206054687,31.2805480957031,1,1,1,43.9999580383301,0,,43.9999752044678,0,,,,,,,,,,,,,,,,,,,,,,,,,,,,,,,
,3636677767.817,43.9996166229248,45500.33203125,0.00762003561916726,5.84977921197639E-7,1,4,13.0063810348511,4.9798093573082,30.7500008493662,9.25273942270124,1.37786586746622,10,-1.14479236630894E-5,,,,,,,,,,,,,,,,,,,,,43.9996109008789,43.9996223449707,45500.33203125,45500.33203125,49.929257365688,5.34391267338144,4.46441316604614,52,1,0,0,1,0.275344848632813,31.2805480957031,1,1,1,43.9996223449707,0,,43.9996166229248,0,,,,,,,,,,,,,,,,,,,,,,,,,,,,,,,
,3636678878.848,45.9999485015869,13000.3369140625,0.000897419789354328,8.29423842997771E-8,1,4,13.0063810348511,5.00042952172313,30.7500008493662,1.09588109273178,0.164171042575161,1,-5.64343413883776E-7,,,,,,,,,,,,,,,,,,,,,45.9999160766602,45.9999809265137,13000.3369140625,13000.3369140625,49.7866101609283,5.34189806106932,4.48220634460449,52,1,0,0,1,0.2783203125,31.2805480957031,1,1,1,45.9999809265137,0,,45.9999485015869,0,,,,,,,,,,,,,,,,,,,,,,,,,,,,,,,
,3636679773.854,46.0000953674316,41000.42578125,0.00737714697032776,6.45370765776434E-7,1,4,13.0063810348511,4.99954982566776,30.7500008493662,9.0072673067065,1.34320703756922,10,-9.56429213363524E-6,,,,,,,,,,,,,,,,,,,,,45.9999237060547,46.0002670288086,41000.42578125,41000.42578125,49.7830928325918,5.34489994460754,4.49198627471924,52,1,0,0,1,0.279464721679687,30.7917900085449,1,1,1,46.0002822875977,0,,46.0000953674316,0,,,,,,,,,,,,,,,,,,,,,,,,,,,,,,,
,3636680886.975,48.0000877380371,8500.3662109375,0.000548652073113145,3.36128374146277E-8,1,4,13.0063810348511,4.98888339584535,30.7500008493662,0.667844526302133,0.0998941921895512,1,-4.68623511963207E-7,,,,,,,,,,,,,,,,,,,,,48.0000190734863,48.0001564025879,8500.3662109375,8500.3662109375,49.8014611027937,5.34479036994542,4.49805068969727,52,1,0,0,1,0.275421142578125,30.7917900085449,1,1,1,48.0000190734863,0,,48.0000877380371,0,,,,,,,,,,,,,,,,,,,,,,,,,,,,,,,
,3636681809.360,47.9999885559082,36500.48046875,0.00679309463647014,4.38641923105037E-7,1,4,13.0063810348511,4.98894159444267,30.7500008493662,8.26951804050019,1.23342341021745,10,-8.61977153278818E-6,,,,,,,,,,,,,,,,,,,,,47.9999542236328,48.0000228881836,36500.48046875,36500.48046875,49.8362435718995,5.34587909543326,4.51411771774292,52,1,0,0,1,0.272674560546875,30.7917900085449,1,1,1,47.9999542236328,0,,47.9999885559082,0,,,,,,,,,,,,,,,,,,,,,,,,,,,,,,,
,3636682920.281,49.9999122619629,4000.25805664063,0.000267443925612617,1.8848503121996E-8,1,4,13.0063810348511,4.99855760108225,30.7599995285273,0.326453413828419,0.0486600799002014,1,-3.64545370209153E-7,,,,,,,,,,,,,,,,,,,,,49.9998550415039,49.9999694824219,4000.25805664063,4000.25805664063,49.8354619433803,5.34831390734955,4.52432346343994,52,1,0,0,1,0.278396606445313,30.7917900085449,1,1,1,49.9998550415039,0,,49.9999122619629,0,,,,,,,,,,,,,,,,,,,,,,,,,,,,,,,
,3636683826.978,49.9999446868897,32000.296875,0.00525488310790891,3.89443779144209E-7,1,4,13.0063810348511,4.99831597059671,30.7599995285273,6.4141311067292,0.95449923166098,10,-8.4212904273637E-6,,,,,,,,,,,,,,,,,,,,,49.9998626708984,50.0000267028809,32000.296875,32000.296875,49.812403902063,5.35115552607784,4.51605701446533,52,1,0,0,1,0.283966064453125,31.2805480957031,1,1,1,49.9998626708984,0,,49.9999446868897,0,,,,,,,,,,,,,,,,,,,,,,,,,,,,,,,
,3636684728.459,50.0000076293945,60000.4609375,0.00722907027559297,6.32136112969195E-7,1,4,13.0063810348511,4.99818113576766,30.7599995285273,8.82313968462164,1.31543031147664,10,-9.62777967441462E-6,,,,,,,,,,,,,,,,,,,,,49.9998970031738,50.0001182556152,60000.4609375,60000.4609375,49.748310363486,5.35212038364655,4.53249645233154,52,1,0,0,1,0.276641845703125,30.7917900085449,1,1,1,49.9998970031738,0,,50.0000076293945,0,,,,,,,,,,,,,,,,,,,,,,,,,,,,,,,
,3636685839.967,52.000150680542,27500.376953125,0.00357165301346919,2.565671847035E-7,1,4,13.0063810348511,4.99864715057352,30.7599995285273,4.36019048994224,0.647401635065363,10,-6.88327827410737E-6,,,,,,,,,,,,,,,,,,,,,52.000114440918,52.000186920166,27500.376953125,27500.376953125,49.8647730128514,5.35089224979068,4.53832292556763,52,1,0,0,1,0.279693603515625,31.2805480957031,1,1,1,52.000114440918,0,,52.000150680542,0,,,,,,,,,,,,,,,,,,,,,,,,,,,,,,,
,3636686733.829,51.999942779541,55500.328125,0.00699877876560907,4.21610654415534E-7,1,4,13.0063810348511,4.99809338952016,30.7599995285273,8.5417702499036,1.27407332213877,10,-8.84655642126244E-6,,,,,,,,,,,,,,,,,,,,,51.9998779296875,52.0000076293945,55500.328125,55500.328125,49.8585199846976,5.35327971378818,4.54863882064819,52,1,0,0,1,0.281143188476562,31.2805480957031,1,1,1,52.0000076293945,0,,51.999942779541,0,,,,,,,,,,,,,,,,,,,,,,,,,,,,,,,
,3636687869.421,54.000036239624,23000.35546875,0.00197540159393779,1.87343950138832E-7,1,4,13.0063810348511,4.99867322339409,30.7599995285273,2.41084233925399,0.362714206262274,1,1.66107961559932E-9,,,,,,,,,,,,,,,,,,,,,53.9999809265137,54.0000915527344,23000.35546875,23000.35546875,49.8053692453899,5.35050778257073,4.54968976974487,52,1,0,0,1,0.28167724609375,30.7917900085449,1,1,1,53.9999885559082,0,,54.000036239624,0,,,,,,,,,,,,,,,,,,,,,,,,,,,,,,,
,3636688770.159,54.0000343322754,51000.16796875,0.00670742236762597,8.56101175240149E-7,1,4,13.0063810348511,4.99836496115571,30.7599995285273,8.18691011871672,1.22040516758772,10,-9.06970365375642E-6,,,,,,,,,,,,,,,,,,,,,53.9999656677246,54.0001029968262,51000.16796875,51000.16796875,49.7827020183322,5.35158294485289,4.56305122375488,52,1,0,0,1,0.282440185546875,31.2805480957031,1,1,1,54.0001029968262,0,,54.0000343322754,0,,,,,,,,,,,,,,,,,,,,,,,,,,,,,,,
,3636689910.436,56.0000686645508,18500.41015625,0.00105206919023485,7.56621859648874E-8,1,4,13.0063810348511,4.99788288709261,30.7700000703335,1.28382382637253,0.192274506087044,1,-7.03063916280311E-7,,,,,,,,,,,,,,,,,,,,,55.9998474121094,56.0002899169922,18500.41015625,18500.41015625,49.8741525550822,5.35313146579779,4.58322954177856,52,1,0,0,1,0.283966064453125,31.2805480957031,1,1,1,55.9998474121094,0,,56.0000686645508,0,,,,,,,,,,,,,,,,,,,,,,,,,,,,,,,
,3636690818.483,55.9998931884766,46500.38671875,0.00632822730551734,5.68184946714909E-7,1,4,13.0063810348511,4.99720551421485,30.7700000703335,7.72187380080397,1.14901493551164,10,-1.02151653901865E-5,,,,,,,,,,,,,,,,,,,,,55.9998397827148,55.9999465942383,46500.38671875,46500.38671875,49.9284757371687,5.35545404532558,4.55545616149902,52,1,0,0,1,0.278091430664062,31.2805480957031,1,1,1,55.9999465942383,0,,55.9998931884766,0,,,,,,,,,,,,,,,,,,,,,,,,,,,,,,,
,3636691929.141,58.0001449584961,14000.3134765625,0.000742848500450322,3.3213682403035E-8,1,4,13.0063810348511,4.9978209678276,30.7700000703335,0.906501830339778,0.135553761106129,1,-6.65015314044769E-7,,,,,,,,,,,,,,,,,,,,,57.9999847412109,58.0003051757812,14000.3134765625,14000.3134765625,49.9898335759284,5.35288021927953,4.59251260757446,52,1,0,0,1,0.271148681640625,31.2805480957031,1,1,1,58.0003051757812,0,,58.0001449584961,0,,,,,,,,,,,,,,,,,,,,,,,,,,,,,,,
,3636692836.706,58.0001411437988,42000.2890625,0.00582249400470986,5.5066097624404E-7,1,4,13.0063810348511,4.9976603980494,30.7700000703335,7.10562330334857,1.05762454479634,10,-9.15213246403469E-6,,,,,,,,,,,,,,,,,,,,,58.0000877380371,58.0001945495606,42000.2890625,42000.2890625,49.849922070986,5.35403621851684,4.59467363357544,52,1,0,0,1,0.277481079101562,31.2805480957031,1,1,1,58.0000877380371,0,,58.0001411437988,0,,,,,,,,,,,,,,,,,,,,,,,,,,,,,,,
,3636693945.687,60.0001049041748,9500.28125,0.00049549455508354,3.59125689523703E-8,1,4,13.0063810348511,4.99818090477092,30.7700000703335,0.604738754356337,0.0902710448696936,1,-5.70667539703063E-7,,,,,,,,,,,,,,,,,,,,,60.0000724792481,60.0001373291016,9500.28125,9500.28125,49.8999462962168,5.35308825826529,4.61006593704224,52,1,0,0,1,0.276947021484375,31.2805480957031,1,1,1,60.0000724792481,0,,60.0001049041748,0,,,,,,,,,,,,,,,,,,,,,,,,,,,,,,,
,3636694878.089,60.000093460083,37500.44140625,0.00506486942482166,4.36630396955727E-7,1,4,13.0063810348511,4.99819213455869,30.7700000703335,6.18204660686529,0.919547277381607,10,-8.44943260951076E-6,,,,,,,,,,,,,,,,,,,,,60.0000190734863,60.0001678466797,37500.44140625,37500.44140625,49.9308206227264,5.3517081403103,4.60872650146484,52,1,0,0,1,0.28076171875,31.2805480957031,1,1,1,60.0001678466797,0,,60.000093460083,0,,,,,,,,,,,,,,,,,,,,,,,,,,,,,,,
,3636695987.290,62.0001010894775,5000.32275390625,0.000265369629318447,1.77476236195882E-8,1,4,13.0063810348511,4.99757840812614,30.7700000703335,0.323838926987845,0.0482282937312737,1,-3.95451056097559E-7,,,,,,,,,,,,,,,,,,,,,61.9999885559082,62.0002136230469,5000.32275390625,5000.32275390625,49.822565072813,5.35443488395321,4.59458065032959,52,1,0,0,1,0.284423828125,31.2805480957031,1,1,1,61.9999885559082,0,,62.0001010894775,0,,,,,,,,,,,,,,,,,,,,,,,,,,,,,,,
,3636696948.280,62.0001220703125,33000.44921875,0.00380265360286483,3.39151660709025E-7,1,4,13.0063810348511,4.99667845516738,30.7700000703335,4.63971231189147,0.688377931316363,10,-7.75118821464846E-6,,,,,,,,,,,,,,,,,,,,,62.0000495910644,62.0001945495606,33000.44921875,33000.44921875,49.6658485547072,5.35747488859545,4.6116418838501,52,1,0,0,1,0.28564453125,31.2805480957031,1,1,1,62.0000495910644,0,,62.0001220703125,0,,,,,,,,,,,,,,,,,,,,,,,,,,,,,,,
,3636698070.106,63.9988040924072,499.662139892578,3.18683272612967E-5,5.95137647549602E-9,1,4,13.0063810348511,4.99833591077965,30.7800006121397,0.0389055145262556,0.00574413393648456,1,-8.75165519571649E-8,,,,,,,,,,,,,,,,,,,,,63.9986419677734,63.998966217041,499.662139892578,499.662139892578,49.8663362698899,5.35084109294172,4.63105726242065,52,1,0,0,1,0.281448364257813,31.2805480957031,1,1,1,63.9989700317383,0,,63.9988040924072,0,,,,,,,,,,,,,,,,,,,,,,,,,,,,,,,
,3636698962.884,63.9996509552002,28500.33984375,0.00250137778332028,2.21784504739806E-7,1,4,13.0063810348511,4.99693073414532,30.7800006121397,3.05229596745708,0.452265873548339,10,-5.57393689623415E-6,,,,,,,,,,,,,,,,,,,,,63.9996452331543,63.9996566772461,28500.33984375,28500.33984375,49.9366828366207,5.35757772407499,4.63752794265747,52,1,0,0,1,0.273590087890625,31.7693061828613,1,1,1,63.9996452331543,0,,63.9996509552002,0,,,,,,,,,,,,,,,,,,,,,,,,,,,,,,,
,3636699861.028,63.999792098999,56500.0859375,0.00553109095492771,4.27206967968763E-7,1,4,13.0063810348511,4.99775700009125,30.7800006121397,6.75035350902698,1.00359892334565,10,-9.61283799313041E-6,,,,,,,,,,,,,,,,,,,,,63.9997215270996,63.9998626708984,56500.0859375,56500.0859375,49.9269124801303,5.35466335852758,4.63509464263916,52,1,0,0,1,0.277099609375,31.7693061828613,1,1,1,63.9998626708984,0,,63.999792098999,0,,,,,,,,,,,,,,,,,,,,,,,,,,,,,,,
,3636700999.085,66.000186920166,24000.51953125,0.00154949726974773,6.4239962134742E-8,1,4,13.0063810348511,4.99744397031527,30.7800006121397,1.89051613012023,0.283676467891295,1,-6.03058338451525E-7,,,,,,,,,,,,,,,,,,,,,66.0001831054687,66.0001907348633,24000.51953125,24000.51953125,49.9308206227264,5.3554479395645,4.64500904083252,52,1,0,0,1,0.27191162109375,31.2805480957031,1,1,1,66.0001907348633,0,,66.000186920166,0,,,,,,,,,,,,,,,,,,,,,,,,,,,,,,,
,3636701898.958,66.0001220703125,52000.43359375,0.00503853416297108,4.10261787399186E-7,1,4,13.0063810348511,4.99793933595477,30.7800006121397,6.14967808631635,0.91330256038836,10,-9.55185772870861E-6,,,,,,,,,,,,,,,,,,,,,66.0000305175781,66.0002136230469,52000.43359375,52000.43359375,49.9359012081014,5.35329936453683,4.64167308807373,52,1,0,0,1,0.274124145507813,31.7693061828613,1,1,1,66.0002136230469,0,,66.0001220703125,0,,,,,,,,,,,,,,,,,,,,,,,,,,,,,,,
,3636703037.679,67.9997138977051,19500.298828125,0.00114270815409388,6.93203366232203E-8,1,4,13.0063810348511,4.9778495686844,30.7800006121397,1.38663690349113,0.207494616787363,1,-9.07026844041894E-7,,,,,,,,,,,,,,,,,,,,,67.9996337890625,67.9997940063477,19500.298828125,19500.298828125,49.9312114369861,5.35315033875926,4.6598072052002,52,1,0,0,1,0.274124145507813,31.7693061828613,1,1,1,67.9997940063477,0,,67.9997138977051,0,,,,,,,,,,,,,,,,,,,,,,,,,,,,,,,
,3636703935.708,68.0000114440918,47500.38671875,0.00447702690818575,3.79624702967183E-7,1,4,13.0063810348511,4.97656339500373,30.7800006121397,5.4317502109098,0.806001082476388,10,-9.03608403873308E-6,,,,,,,,,,,,,,,,,,,,,67.9999847412109,68.0000381469727,47500.38671875,47500.38671875,50.0484557148707,5.35676586374865,4.65184497833252,52,1,0,0,1,0.274581909179687,31.7693061828613,1,1,1,67.9999847412109,0,,68.0000114440918,0,,,,,,,,,,,,,,,,,,,,,,,,,,,,,,,
,3636705071.085,69.9999313354492,15000.1787109375,0.000852197926220979,6.56946324576723E-8,1,4,13.0063810348511,4.99727485527393,30.7899992913008,1.03978489475337,0.155468843346115,1,-7.75254953325672E-7,,,,,,,,,,,,,,,,,,,,,69.9998626708984,70,15000.1787109375,15000.1787109375,50.0883187693515,5.3539181998474,4.65901184082031,51,1,68,0,0,0.283737182617187,32.2580642700195,1,1,1,70,0,,69.9999313354492,0,,,,,,,,,,,,,,,,,,,,,,,,,,,,,,,
,3636705977.774,69.9998588562012,43000.23828125,0.00387448079711851,2.53638577606061E-7,1,4,13.0063810348511,4.99649006468619,30.7899992913008,4.72714572952279,0.701047820863943,10,-8.14003831802549E-6,,,,,,,,,,,,,,,,,,,,,69.9997863769531,69.9999313354492,43000.23828125,43000.23828125,50.0437659437553,5.35757107350688,4.67038249969482,52,1,0,0,1,0.2740478515625,32.2580642700195,1,1,1,69.9999313354492,0,,69.9998588562012,0,,,,,,,,,,,,,,,,,,,,,,,,,,,,,,,
,3636707083.348,71.9999656677246,10500.3828125,0.000596102009877647,3.72120052633417E-8,1,4,13.0063810348511,4.99694824077915,30.7899992913008,0.727278980202231,0.108548210197016,1,-6.98370068483357E-7,,,,,,,,,,,,,,,,,,,,,71.9999008178711,72.0000305175781,10500.3828125,10500.3828125,50.0746402702649,5.35720023700646,4.67299556732178,52,1,0,0,1,0.278091430664062,32.2580642700195,1,1,1,71.9999008178711,0,,71.9999656677246,0,,,,,,,,,,,,,,,,,,,,,,,,,,,,,,,
,3636707998.739,71.9998626708984,38500.4453125,0.00327555497834117,2.68496224015497E-7,1,4,13.0063810348511,4.99682148311095,30.7899992913008,3.99684183932969,0.592347057317675,10,-7.1983496866194E-6,,,,,,,,,,,,,,,,,,,,,71.9998474121094,71.9998779296875,38500.4453125,38500.4453125,50.0019488179764,5.35727818565972,4.67032670974731,52,1,0,0,1,0.272979736328125,31.7693061828613,1,1,1,71.9998779296875,0,,71.9998626708984,0,,,,,,,,,,,,,,,,,,,,,,,,,,,,,,,
,3636709109.051,73.9999847412109,6000.22412109375,0.000350222690076955,2.29486483964594E-8,1,4,13.0063810348511,4.99754493050556,30.7899992913008,0.427383355213563,0.0636517896585473,1,-5.19528429547377E-7,,,,,,,,,,,,,,,,,,,,,73.9999313354492,74.0000381469727,6000.22412109375,6000.22412109375,50.1696081353515,5.35403056412488,4.68555450439453,52,1,0,0,1,0.277633666992187,31.7693061828613,1,1,1,73.9999313354492,0,,73.9999847412109,0,,,,,,,,,,,,,,,,,,,,,,,,,,,,,,,
,3636710003.978,73.9999542236328,34000.38671875,0.00271366286415569,2.23348572594908E-7,1,4,13.0063810348511,4.99805891649708,30.7899992913008,3.31240025353132,0.490676981118492,10,-6.1505201147418E-6,,,,,,,,,,,,,,,,,,,,,73.9998626708984,74.0000457763672,34000.38671875,34000.38671875,50.0988707543611,5.35292934115767,4.68885135650635,52,1,0,0,1,0.282669067382813,31.7693061828613,1,1,1,73.9998626708984,0,,73.9999542236328,0,,,,,,,,,,,,,,,,,,,,,,,,,,,,,,,
,3636711125.464,75.9979057312012,1499.68896484375,9.7488425222431E-5,8.93435821381914E-9,1,4,13.0063810348511,4.99714635235737,30.799999833107,0.118960652682304,0.017669996440848,1,-1.82504222340109E-7,,,,,,,,,,,,,,,,,,,,,75.9977340698242,75.9980773925781,1499.68896484375,1499.68896484375,50.1399062516207,5.35472003208729,4.6894211769104,52,1,0,0,1,0.279159545898438,31.7693061828613,1,1,1,75.9980773925781,0,,75.9979057312012,0,,,,,,,,,,,,,,,,,,,,,,,,,,,,,,,
,3636712034.645,76.0000991821289,29500.330078125,0.00220510560051548,1.35047658223933E-7,1,4,13.0063810348511,4.99690728152986,30.799999833107,2.69082904478001,0.398192441327321,10,-5.32594416587634E-6,,,,,,,,,,,,,,,,,,,,,76.0000610351562,76.0001373291016,29500.330078125,29500.330078125,50.1191930958611,5.35558824350468,4.70028495788574,52,1,0,0,1,0.277633666992187,32.2580642700195,1,1,1,76.0001373291016,0,,76.0000991821289,0,,,,,,,,,,,,,,,,,,,,,,,,,,,,,,,
,3636712931.149,76.0002326965332,57500.49609375,0.0039270174048338,2.92099313629927E-7,1,4,13.0063810348511,4.99619696993487,30.799999833107,4.7908387200671,0.710578320789473,10,-8.18250743659892E-6,,,,,,,,,,,,,,,,,,,,,76.0001831054687,76.0002822875977,57500.49609375,57500.49609375,49.9726377485053,5.35862637591283,4.69512987136841,52,1,0,0,1,0.27496337890625,32.2580642700195,1,1,1,76.0002822875977,0,,76.0002326965332,0,,,,,,,,,,,,,,,,,,,,,,,,,,,,,,,
,3636714045.251,78.0002861022949,25000.521484375,0.00175286056671886,1.17190226505897E-7,1,4,13.0063810348511,4.99708668804294,30.799999833107,2.13912181540764,0.316227781199438,10,-4.49209211290791E-6,,,,,,,,,,,,,,,,,,,,,78.0002593994141,78.0003128051758,25000.521484375,25000.521484375,50.0894912121303,5.35568198171732,4.70231676101685,52,1,0,0,1,0.279464721679687,32.2580642700195,1,1,1,78.0002593994141,0,,78.0002861022949,0,,,,,,,,,,,,,,,,,,,,,,,,,,,,,,,
,3636714944.130,78.0000953674316,53000.41015625,0.00347130872678318,3.49476315435515E-7,1,4,13.0063810348511,4.9971428038469,30.799999833107,4.23601433368808,0.628252961279403,10,-7.25997589900894E-6,,,,,,,,,,,,,,,,,,,,,78.0000610351562,78.000129699707,53000.41015625,53000.41015625,49.9781091481399,5.35545761290546,4.7003960609436,52,1,0,0,1,0.277633666992187,32.2580642700195,1,1,1,78.0000610351562,0,,78.0000953674316,0,,,,,,,,,,,,,,,,,,,,,,,,,,,,,,,
,3636716065.847,79.9996070861816,20500.375,0.00135270883130284,8.67566466228839E-8,1,4,13.0063810348511,4.99757965281729,30.799999833107,1.65100467457703,0.244174111156108,10,-3.38242029625422E-6,,,,,,,,,,,,,,,,,,,,,79.9995346069336,79.9996795654297,20500.375,20500.375,50.020707902438,5.35429421855542,4.70629787445068,52,1,0,0,1,0.277862548828125,32.2580642700195,1,1,1,79.9996795654297,0,,79.9996070861816,0,,,,,,,,,,,,,,,,,,,,,,,,,,,,,,,
,3636716958.133,80.0000343322754,48500.33984375,0.00302889286367744,3.14379949071086E-7,1,4,13.0063810348511,4.99794553026068,30.799999833107,3.69701690854338,0.547976564489592,10,-6.60442196237468E-6,,,,,,,,,,,,,,,,,,,,,79.9999923706055,80.0000762939453,48500.33984375,48500.33984375,49.9589592494187,5.3537641939494,4.71709203720093,52,1,0,0,1,0.276260375976562,32.2580642700195,1,1,1,80.0000762939453,0,,80.0000343322754,0,,,,,,,,,,,,,,,,,,,,,,,,,,,,,,,
,3636718101.802,82.0000305175781,16000.1923828125,0.000996738412634069,8.09383052350516E-8,1,4,13.0063810348511,4.99831894668912,30.8100003749132,1.21646666691727,0.182092973052946,1,-7.41139807222085E-7,,,,,,,,,,,,,,,,,,,,,82.0000228881836,82.0000381469727,16000.1923828125,16000.1923828125,50.0648699137745,5.35280891470266,4.71692991256714,52,1,0,0,1,0.275421142578125,32.2580642700195,1,1,1,82.0000228881836,0,,82.0000305175781,0,,,,,,,,,,,,,,,,,,,,,,,,,,,,,,,
,3636718989.097,82.0004539489746,44000.203125,0.00261201883841626,2.52126077634499E-7,1,4,13.0063810348511,4.99796833030111,30.8100003749132,3.18827346816014,0.472122727244294,10,-6.05397258037541E-6,,,,,,,,,,,,,,,,,,,,,82.0003890991211,82.0005187988281,44000.203125,44000.203125,49.9714653057264,5.35461986758683,4.71555519104004,52,1,0,0,1,0.269546508789062,32.2580642700195,1,1,1,82.0005187988281,0,,82.0004539489746,0,,,,,,,,,,,,,,,,,,,,,,,,,,,,,,,
,3636720099.732,84.0000457763672,11500.1708984375,0.000679919093237723,6.95644947629647E-8,1,4,13.0063810348511,4.99792204164844,30.8100003749132,0.829748045618098,0.123968765041805,1,-6.94937663005923E-7,,,,,,,,,,,,,,,,,,,,,84.0000228881836,84.0000686645508,11500.1708984375,11500.1708984375,49.974982634063,5.35534320639506,4.71840763092041,52,1,0,0,1,0.275955200195313,32.2580642700195,1,1,1,84.0000228881836,0,,84.0000457763672,0,,,,,,,,,,,,,,,,,,,,,,,,,,,,,,,
,3636721034.265,84.0000953674316,39500.43359375,0.00222439864455951,1.51853177222929E-7,1,4,13.0063810348511,4.99820762894729,30.8100003749132,2.71532963067598,0.402020397494198,10,-5.21034851457495E-6,,,,,,,,,,,,,,,,,,,,,84.0000228881836,84.0001678466797,39500.43359375,39500.43359375,49.9433266790341,5.35366242995635,4.73138284683228,52,1,0,0,1,0.281906127929687,31.7693061828613,1,1,1,84.0000228881836,0,,84.0000953674316,0,,,,,,,,,,,,,,,,,,,,,,,,,,,,,,,
,3636722171.409,86.0003128051758,7000.2255859375,0.00039646602430289,3.35049893687075E-8,1,4,13.0063810348511,4.99926674297331,30.8200009167194,0.48404314325772,0.072123362373296,1,-5.61668095665879E-7,,,,,,,,,,,,,,,,,,,,,86.0002136230469,86.0004119873047,7000.2255859375,7000.2255859375,49.9550511068226,5.34993794913793,4.73109865188599,52,1,0,0,1,0.281295776367187,32.2580642700195,1,1,1,86.0004119873047,0,,86.0003128051758,0,,,,,,,,,,,,,,,,,,,,,,,,,,,,,,,
,3636723066.917,85.9998435974121,35000.328125,0.00186706822285252,2.02455300862119E-7,1,4,13.0063810348511,4.99915174825827,30.8200009167194,2.27900475045585,0.342396808483708,1,-3.84794887506446E-7,,,,,,,,,,,,,,,,,,,,,85.9998321533203,85.9998550415039,35000.328125,35000.328125,50.0500189719091,5.35004867855961,4.7295503616333,52,1,0,0,1,0.27801513671875,32.2580642700195,1,1,1,85.9998321533203,0,,85.9998435974121,0,,,,,,,,,,,,,,,,,,,,,,,,,,,,,,,
,3636724223.277,87.9974021911621,2499.4775390625,0.000141676311309494,1.04851158697726E-8,1,4,13.0063810348511,4.99919364315131,30.8200009167194,0.172976451301108,0.0257182805969701,1,-2.45218675753513E-7,,,,,,,,,,,,,,,,,,,,,87.9970779418945,87.9977264404297,2499.4775390625,2499.4775390625,49.9577868066399,5.34949049656113,4.7371506690979,52,1,0,0,1,0.2789306640625,31.7693061828613,1,1,1,87.9977264404297,0,,87.9974021911621,0,,,,,,,,,,,,,,,,,,,,,,,,,,,,,,,
,3636725091.461,87.9999389648438,30500.46875,0.00154351759136237,1.32510286354503E-7,1,4,13.0063810348511,4.99814922114497,30.8200009167194,1.88360900144447,0.282524343490971,1,-6.93448787472127E-7,,,,,,,,,,,,,,,,,,,,,87.999885559082,87.9999923706055,30500.46875,30500.46875,49.995304975563,5.35337209142858,4.73651456832886,52,1,0,0,1,0.283126831054687,31.7693061828613,1,1,1,87.9999923706055,0,,87.9999389648438,0,,,,,,,,,,,,,,,,,,,,,,,,,,,,,,,
,3636725997.725,88,58500.41796875,0.00278870919157143,2.96440848721981E-7,1,4,13.0063810348511,4.99841982692721,30.8200009167194,3.40428677906225,0.504706357288505,10,-5.98562107514263E-6,,,,,,,,,,,,,,,,,,,,,87.999870300293,88.000129699707,58500.41796875,58500.41796875,49.8698535982264,5.35079525960517,4.74156427383423,52,1,0,0,1,0.28106689453125,31.7693061828613,1,1,1,87.999870300293,0,,88,0,,,,,,,,,,,,,,,,,,,,,,,,,,,,,,,
,3636727133.062,90.0002784729004,26000.3359375,0.00124901977202547,1.0997852959017E-7,1,4,13.0063810348511,4.99871766086646,30.8200009167194,1.52453836185691,0.228170069796968,1,-9.59317953058217E-7,,,,,,,,,,,,,,,,,,,,,90.0001983642578,90.000358581543,26000.3359375,26000.3359375,50.0234436022553,5.35067108059181,4.74836587905884,52,1,0,0,1,0.281982421875,31.7693061828613,1,1,1,90.000358581543,0,,90.0002784729004,0,,,,,,,,,,,,,,,,,,,,,,,,,,,,,,,
,3636728034.801,89.9996109008789,54000.47265625,0.00246235368665577,2.2193474552966E-7,1,4,13.0063810348511,4.99870076059688,30.8200009167194,3.00610953328581,0.445799428755349,10,-5.18472267538922E-6,,,,,,,,,,,,,,,,,,,,,89.9995574951172,89.9996643066406,54000.47265625,54000.47265625,49.8675087126687,5.35159190255126,4.7499532699585,52,1,0,0,1,0.283203125,31.7693061828613,1,1,1,89.9995574951172,0,,89.9996109008789,0,,,,,,,,,,,,,,,,,,,,,,,,,,,,,,,
,3636729242.752,92.0000610351562,21500.201171875,0.000981736239348373,9.27575456116084E-8,1,4,13.0063810348511,4.99828698660106,30.8299995958805,1.1981495878142,0.179330753042911,1,-7.46281847661332E-7,,,,,,,,,,,,,,,,,,,,,91.9999389648438,92.0001831054687,21500.201171875,21500.201171875,50.0121099887264,5.35387913031054,4.74989557266235,52,1,0,0,1,0.283203125,31.7693061828613,1,1,1,91.9999389648438,0,,92.0000610351562,0,,,,,,,,,,,,,,,,,,,,,,,,,,,,,,,
,3636730162.158,91.9999465942383,50000.3046875,0.00217563843154896,2.47969991950316E-7,1,4,13.0063810348511,4.99870271525655,30.8299995958805,2.65615023723781,0.393431216391087,10,-4.95773292561539E-6,,,,,,,,,,,,,,,,,,,,,91.9997482299805,92.0001449584961,50000.3046875,50000.3046875,49.9214410804957,5.3518896676656,4.75011968612671,52,1,0,0,1,0.273666381835938,31.7693061828613,1,1,1,92.0001449584961,0,,91.9999465942383,0,,,,,,,,,,,,,,,,,,,,,,,,,,,,,,,
,3636731342.917,94.000186920166,17500.24609375,0.000760454813697226,4.79594119520431E-8,1,4,13.0063810348511,4.99891912746521,30.8299995958805,0.928286817130366,0.13871040269163,1,-7.61689344939503E-7,,,,,,,,,,,,,,,,,,,,,94.0001602172852,94.0002136230469,17500.24609375,17500.24609375,49.9718561199861,5.35071005879793,4.76402378082275,52,1,0,0,1,0.279769897460938,31.7693061828613,1,1,1,94.0001602172852,0,,94.000186920166,0,,,,,,,,,,,,,,,,,,,,,,,,,,,,,,,
,3636732238.204,93.9997177124023,45500.28515625,0.00188805330624311,1.65220175773362E-7,1,4,13.0063810348511,4.9996234929643,30.8299995958805,2.30478607308634,0.347206384993512,1,3.60830743819018E-7,,,,,,,,,,,,,,,,,,,,,93.9996109008789,93.9998245239258,45500.28515625,45500.28515625,50.0285241876303,5.34682492530483,4.76343011856079,52,1,0,0,1,0.276107788085938,31.7693061828613,1,1,1,93.9998245239258,0,,93.9997177124023,0,,,,,,,,,,,,,,,,,,,,,,,,,,,,,,,
,3636733371.020,95.9997406005859,13000.2861328125,0.000540392413184619,3.87705381703551E-8,1,4,13.0063810348511,4.99817815250633,30.8400001376867,0.659534023312596,0.0984568766628812,1,-6.1725641403225E-7,,,,,,,,,,,,,,,,,,,,,95.9996185302734,95.9998626708984,13000.2861328125,13000.2861328125,49.9796724051784,5.35392330645638,4.75966358184814,52,1,0,0,1,0.282745361328125,31.7693061828613,1,1,1,95.9996185302734,0,,95.9997406005859,0,,,,,,,,,,,,,,,,,,,,,,,,,,,,,,,
,3636734284.565,95.9999961853027,41000.26171875,0.00162337470868481,1.17911205705775E-7,1,4,13.0063810348511,4.99827455537001,30.8400001376867,1.981089107195,0.297429582604289,1,-5.01648414102067E-7,,,,,,,,,,,,,,,,,,,,,95.9999465942383,96.0000457763672,41000.26171875,41000.26171875,49.980063219438,5.35440888710812,4.7628664970398,52,1,0,0,1,0.2825927734375,31.7693061828613,1,1,1,96.0000457763672,0,,95.9999961853027,0,,,,,,,,,,,,,,,,,,,,,,,,,,,,,,,
,3636735429.614,97.9998588562012,8500.4794921875,0.000341011832625797,1.85703886975222E-8,1,4,13.0063810348511,4.9992378362328,30.8400001376867,0.416332888842995,0.0620560020362798,1,-4.65800442572588E-7,,,,,,,,,,,,,,,,,,,,,97.9998245239258,97.9998931884766,8500.4794921875,8500.4794921875,49.8721984837841,5.3496825222682,4.77147054672241,52,1,0,0,1,0.278549194335938,31.7693061828613,1,1,1,97.9998245239258,0,,97.9998588562012,0,,,,,,,,,,,,,,,,,,,,,,,,,,,,,,,
,3636736318.379,97.9997673034668,36500.40234375,0.00137935217348968,8.60163222021407E-8,1,4,13.0063810348511,4.99876830500083,30.8400001376867,1.68357939135886,0.252414444964035,1,-7.05642554641038E-7,,,,,,,,,,,,,,,,,,,,,97.9996337890625,97.9999008178711,36500.40234375,36500.40234375,50.0121099887264,5.352707155148,4.77019214630127,52,1,0,0,1,0.279006958007813,31.7693061828613,1,1,1,97.9996337890625,0,,97.9997673034668,0,,,,,,,,,,,,,,,,,,,,,,,,,,,,,,,
,3636737473.492,99.998607635498,4000.29565429687,0.000160141873327543,1.28766735585555E-8,1,4,13.0063810348511,4.99964938577143,30.8400001376867,0.195536710828694,0.0291388826201198,1,-2.24038294541861E-7,,,,,,,,,,,,,,,,,,,,,99.998420715332,99.9987945556641,4000.29565429687,4000.29565429687,49.8678995269284,5.34905666988102,4.77832460403442,52,1,0,0,1,0.279388427734375,31.7693061828613,1,1,1,99.9987945556641,0,,99.998607635498,0,,,,,,,,,,,,,,,,,,,,,,,,,,,,,,,
,3636738376.013,100.00008392334,32000.259765625,0.00115415441195669,9.56407002807822E-8,1,4,13.0063810348511,4.99923522836484,30.8400001376867,1.40893242808227,0.210992408334955,1,-7.8670236015032E-7,,,,,,,,,,,,,,,,,,,,,100.000053405762,100.000114440918,32000.259765625,32000.259765625,49.9636490205341,5.35035976950931,4.78087759017944,52,1,0,0,1,0.281295776367187,31.2805480957031,1,1,1,100.000114440918,0,,100.00008392334,0,,,,,,,,,,,,,,,,,,,,,,,,,,,,,,,
,3636739286.607,99.9998931884766,60000.26171875,0.00206621293169584,1.64250523037105E-7,1,4,13.0063810348511,4.99933065787689,30.8400001376867,2.52296935441587,0.373912330146868,10,-4.54171126560771E-6,,,,,,,,,,,,,,,,,,,,,99.9998016357422,99.9999847412109,60000.26171875,60000.26171875,49.8210018157745,5.34838189139422,4.78200387954712,52,1,0,0,1,0.27740478515625,31.7693061828613,1,1,1,99.9998016357422,0,,99.9998931884766,0,,,,,,,,,,,,,,,,,,,,,,,,,,,,,,,