File: sample-data/QD-PPMS2.dat
[Header]
; VSM Data File (default extension .dat)
; Copyright (c) 2003, Quantum Design, Inc. All rights reserved.
TITLE,
FILEOPENTIME,28214732.41,11/22/2016,2:28 pm
BYAPP,VSM,1.0,1.0
INFO,PPMS VSM Option Release 1.3.6 Build 0,APPNAME
INFO,381,COIL_SERIAL_NUMBER
INFO,0,MOMENT_UNITS
INFO,,SAMPLE_MATERIAL
INFO,,SAMPLE_COMMENT
INFO,15.3,SAMPLE_MASS
INFO,,SAMPLE_VOLUME
INFO,,SAMPLE_MOLECULAR_WEIGHT
INFO,,SAMPLE_SIZE
INFO,,SAMPLE_SHAPE
INFO,35.79,SAMPLE_OFFSET
DATATYPE,COMMENT,1
DATATYPE,TIME,2
STARTUPAXIS,X,2
STARTUPAXIS,Y1,5
[Data]
Comment,Time Stamp (sec),Temperature (K),Magnetic Field (Oe),Moment (emu),M. Std. Err. (emu),Transport Action,Averaging Time (sec),Frequency (Hz),Peak Amplitude (mm),Center Position (mm),Coil Signal' (mV),Coil Signal" (mV),Range (mV),M. Quad. Signal (emu),M. Raw' (emu),M. Raw" (emu),Min. Temperature (K),Max. Temperature (K),Min. Field (Oe),Max. Field (Oe),Mass (grams),Motor Lag (deg),Pressure (Torr),VSM Status (code),Motor Status (code),Measure Status (code),PPMS Status (code),System Temp. (K),System Field (Oe),Sample Position (deg),Bridge 1 Resistance (ohms),Bridge 1 Excitation (에),Bridge 2 Resistance (ohms),Bridge 2 Excitation (에),Bridge 3 Resistance (ohms),Bridge 3 Excitation (에),Bridge 4 Resistance (ohms),Bridge 4 Excitation (에),Signal 1 Vin (V),Signal 2 Vin (V),Digital Inputs (code),Drive 1 Iout (mA),Drive 1 Ipower (W),Drive 2 Iout (mA),Drive 2 Ipower (W),Pressure (),Map 20 (),Map 21 (),Map 22 (),Map 23 (),Map 24 (),Map 25 (),Map 26 (),Map 27 (),Map 28 (),Map 29 ()
,28214785.27,300.0066833,499.903472900391,0.253376820142176,2.2051223759493E-5,1,0.999253354069792,40.0298881530762,2.00967022881211,7.53999646753073,2.81069308371912,0.48862617107288,2.5,-0.000205283451456644,0.25336933665653,-3.72633687134064E-5,300.0066833,300.0066833,499.903472900391,499.903472900391,55.1735939154674,19.5657856962453,26.1347828,1,0,0,4369,300.34875,499.903472900391,,,,,,,,,,,,,,,,,52.959648,,,,,,300.0066833,,,,
,28214799.55,300.0066223,499.903472900391,0.320191325193571,3.42938897027109E-5,1,0.999253354069792,40.0298881530762,2.00934414776205,7.53999646753073,3.55296463052793,0.615566828400837,25,-0.000443121919487493,0.320181990898587,-0.00023078988761638,300.0066223,300.0066223,499.903472900391,499.903472900391,55.7324583067174,19.5735855017505,26.3971481,0,0,0,4369,300.34855,499.903472900391,,,,,,,,,,,,,,,,,54.480885,,,,,,300.0066223,,,,
,28214812.465,300.0086975,499.903472900391,0.320188292698764,2.65657652441883E-5,1,0.999253354069792,40.0298881530762,2.00865870730035,7.53999646753073,3.55176691911693,0.615227026339912,25,-0.000454697670015026,0.320178940302718,-0.000242365982464671,300.0084839,300.0089111,499.903472900391,499.903472900391,55.5167288354097,19.5813423982665,25.88013935,0,0,0,4369,300.347,499.903472900391,,,,,,,,,,,,,,,,,54.100574,,,,,,300.0086975,,,,
,28214825.49,300.0088501,499.903472900391,0.320200969470554,3.08861488477156E-5,1,0.999253354069792,40.0298881530762,2.00843759507263,7.54999607801437,3.55148784712175,0.615396851430152,25,-0.000435620373201853,0.320191602036706,-0.000223279596407538,300.0082703,300.0094299,499.903472900391,499.903472900391,55.4385659834866,19.5862879704489,25.88013935,0,0,0,4369,300.3455,499.903472900391,,,,,,,,,,,,,,,,,52.959648,,,,,,300.0088501,,,,
,28214838.515,300.0105133,499.903472900391,0.320203563880924,2.29807316779897E-5,1,0.999253354069792,40.0298881530762,2.00830784032469,7.53999646753073,3.55134505712631,0.615058135846008,25,-0.000463109362318785,0.320194193855649,-0.000250764888574948,300.0104065,300.0106201,499.903472900391,499.903472900391,55.6558587118328,19.5899046413112,26.26596545,0,0,0,4369,300.34415,499.903472900391,,,,,,,,,,,,,,,,,54.100574,,,,,,300.0105133,,,,
,28214851.5,300.011322,499.747436523438,0.32019675038889,1.03125671713081E-5,1,0.999253354069792,40.0298881530762,2.00812943764825,7.53999646753073,3.55090939865998,0.615284486733991,25,-0.000436720858380447,0.320187349218675,-0.000224338687879748,300.011322,300.011322,499.725158691406,499.769714355469,55.6073977436405,19.5913154280626,26.52967355,0,0,0,4385,300.29285,499.747436523438,,,,,,,,,,,,,,,,,54.480885,,,,,,300.011322,,,,
,28214864.51,300.01376345,499.797592163086,0.320081118040464,1.9336379406493E-5,1,0.999253354069792,40.0298881530762,2.00808590502723,7.53999646753073,3.54953928184755,0.615118928162079,25,-0.000430218943663288,0.320071690570308,-0.00021796772935514,300.0126648,300.0148621,499.769714355469,499.825469970703,55.7340215637559,19.5928568661702,26.3971481,0,0,0,4385,300.3574,499.797592163086,,,,,,,,,,,,,,,,,54.480885,,,,,,300.01376345,,,,
,28214877.46,300.01683045,1119.81384277344,0.615935721810283,0.0017554112479306,1,0.999253354069792,40.0298881530762,2.00809979211355,7.53999646753073,6.82990640406141,1.18688070570451,25,-0.000539926578260108,0.615917315993155,-0.000131494732199083,300.0164185,300.0172424,1069.92517089844,1169.70251464844,55.7097910796597,19.5917284001988,26.26596545,0,0,0,4449,300.33905,1119.81384277344,,,,,,,,,,,,,,,,,54.480885,,,,,,300.01683045,,,,
,28214890.49,300.0166473,2422.91101074219,0.894795452734724,0.000398535810569514,1,0.999253354069792,40.0298881530762,2.00817685908299,7.53999646753073,9.92277223380286,1.72252027794523,25,-0.000944426577463641,0.89476883384518,-0.000351160312725439,300.016571,300.0167236,2367.94482421875,2477.87719726562,55.6691463966597,19.5943863355599,25.88013935,0,0,0,4449,300.33485,2422.91101074219,,,,,,,,,,,,,,,,,54.480885,,,,,,300.0166473,,,,
,28214903.46,300.0149078,3716.44653320313,0.950528836923554,0.000107510976875308,1,0.999253354069792,40.0298881530762,2.00814918203083,7.54999607801437,10.5406442525936,1.8300030764861,25,-0.000983476131820859,0.950500619902703,-0.000353357988203305,300.014801,300.0150146,3676.52661132812,3756.36645507812,55.690250366679,19.5935067262443,26.0126648,0,0,0,4449,300.3302,3716.44653320313,,,,,,,,,,,,,,,,,54.480885,,,,,,300.0149078,,,,
,28214916.465,300.01371765,5014.83935546875,0.968242966259569,0.000112253955065394,1,0.999253354069792,40.0298881530762,2.00813220832782,7.53999646753073,10.7369717077561,1.86420974125032,25,-0.000991052524464891,0.968214271403661,-0.0003493095453613,300.0132141,300.0142212,4954.91162109375,5074.76708984375,55.7121359652174,19.5955438552841,26.3971481,0,0,0,4449,300.32845,5014.83935546875,,,,,,,,,,,,,,,,,54.100574,,,,,,300.01371765,,,,
,28214931.44,300.01295475,6513.810546875,0.977887561837329,0.000109893984178922,1,0.999253354069792,40.0298881530762,2.00819246066793,7.53999646753073,10.8747173415573,1.88682005230868,250,-0.00111475618343829,0.977858699475954,-0.000466774495826833,300.0127869,300.0131226,6463.6376953125,6563.9833984375,55.7426194774674,19.5961539487129,25.88013935,0,0,0,4449,300.331,6513.810546875,,,,,,,,,,,,,,,,,52.959648,,,,,,300.01295475,,,,
,28214944.44,300.0132904,7813.4189453125,0.983209756208662,8.700078535516E-5,1,0.999253354069792,40.0298881530762,2.00821759606006,7.53999646753073,10.9340352536286,1.89712465515386,250,-0.00111957571158032,0.983180735987806,-0.000468211885256014,300.0126953,300.0138855,7763.45263671875,7863.38525390625,55.8090579016021,19.5954708345203,26.52967355,0,0,0,4449,300.3339,7813.4189453125,,,,,,,,,,,,,,,,,54.480885,,,,,,300.0132904,,,,
,28214957.375,300.0133972,9107.97265625,0.987224554744063,0.000109892142702157,1,0.999253354069792,40.0298881530762,2.00819067536317,7.53999646753073,10.978444622663,1.90538589690191,250,-0.00107549320555899,0.98719539070786,-0.000421594845887136,300.0133972,300.0133972,9062.9873046875,9152.9580078125,55.8926921531598,19.5940636968434,25.88013935,0,0,0,4449,300.32695,9107.97265625,,,,,,,,,,,,,,,,,54.480885,,,,,,300.0133972,,,,
,28214970.37,300.0128784,9999.7080078125,0.989503043918948,8.8757831911299E-5,1,0.999253354069792,40.0298881530762,2.00819010920086,7.53999646753073,11.0040513972198,1.90822860085167,250,-0.00121768259092201,0.989473933675545,-0.000562368571698212,300.0126648,300.013092,9999.7080078125,9999.7080078125,55.893473781679,19.5954178723028,26.0126648,0,0,0,4401,300.326,9999.7080078125,,,,,,,,,,,,,,,,,54.861191,,,,,,300.0128784,,,,
,28214983.42,300.0107422,9999.7080078125,0.989503705825793,9.47371003331107E-5,1,0.999253354069792,40.0298881530762,2.00818381759894,7.53999646753073,11.0037772284961,1.90964788691377,250,-0.0010896396768513,0.989474592155007,-0.000434323058160659,300.0105591,300.0109253,9999.7080078125,9999.7080078125,55.8715881831405,19.5945485234664,26.3971481,0,0,0,4401,300.32365,9999.7080078125,,,,,,,,,,,,,,,,,52.959648,,,,,,300.0107422,,,,
,28214996.335,300.0087738,9999.7080078125,0.989565175336911,0.000112553922649039,1,0.999253354069792,40.0298881530762,2.00832772952092,7.53999646753073,11.005264375152,1.90972379279014,250,-0.00110561680724712,0.989536145257347,-0.00045025193207049,300.0086975,300.0088501,9999.7080078125,9999.7080078125,55.8864391250059,19.5954136387983,26.3971481,0,0,0,4401,300.3209,9999.7080078125,,,,,,,,,,,,,,,,,54.861191,,,,,,300.0087738,,,,
,28215009.41,300.00912475,9999.7080078125,0.989599949453862,0.000104099026612812,1,0.999253354069792,40.0298881530762,2.00830823850496,7.53999646753073,11.0054920995849,1.9100838185739,250,-0.00107765713154784,0.989570888245501,-0.000422291368436943,300.0090332,300.0092163,9999.7080078125,9999.7080078125,55.9505326635828,19.5948859768757,26.3971481,0,0,0,4369,300.32915,9999.7080078125,,,,,,,,,,,,,,,,,52.959648,,,,,,300.00912475,,,,
,28215022.36,300.00975035,9999.42919921875,0.989472246416453,0.000108127766679963,1,0.999253354069792,40.0298881530762,2.00835420485645,7.53999646753073,11.0042378041751,1.91033996692382,250,-0.00103615707706566,0.989443137631081,-0.000380877734842264,300.0092163,300.0102844,9999.4072265625,9999.451171875,56.0310404010636,19.5950508954124,26.52967355,0,0,0,4385,300.3294,9999.42919921875,,,,,,,,,,,,,,,,,54.480885,,,,,,300.00975035,,,,
,28215035.335,300.01202395,9529.68310546875,0.988443031540902,0.000100934075456243,1,0.999253354069792,40.0298881530762,2.00835366000716,7.53999646753073,10.9928732843707,1.90786185709971,250,-0.0010792387387157,0.988413889849502,-0.000424579713521675,300.0114441,300.0126038,9479.802734375,9579.5634765625,56.0169710877175,19.5940438395776,25.88013935,0,0,0,4449,300.3267,9529.68310546875,,,,,,,,,,,,,,,,,52.959648,,,,,,300.01202395,,,,
,28215048.355,300.01119995,8232.8330078125,0.984276534852407,0.000111154596566708,1,0.999253354069792,40.0298881530762,1.99697512027958,7.53999646753073,10.8850917227606,1.89334298053873,250,-0.000707320046389051,0.98424729066749,-5.52808266214389E-5,300.0107117,300.0116882,8182.9921875,8282.673828125,56.0177527162367,19.5958610657839,26.3971481,0,0,0,4449,300.3236,8232.8330078125,,,,,,,,,,,,,,,,,54.480885,,,,,,300.01119995,,,,
,28215061.33,300.0110321,6940.51879882813,0.979479112250759,0.000107901376129143,1,0.999253354069792,40.0298881530762,1.99708322201807,7.53999646753073,10.8327076083567,1.88366506696908,250,-0.000753713961982841,0.979450037200402,-0.000104707982462235,300.0091858,300.0128784,6885.5390625,6995.49853515625,56.0130629451213,19.5963434177801,26.26596545,0,0,0,4449,300.32125,6940.51879882813,,,,,,,,,,,,,,,,,53.339954,,,,,,300.0110321,,,,
,28215074.34,300.01000975,5637.14624023438,0.972435587280057,0.000102614411011825,1,0.999253354069792,40.0298881530762,1.99709213471742,7.53999646753073,10.7549024903433,1.86986112339183,250,-0.000772535077651974,0.972406763787133,-0.000128059647670347,300.0092773,300.0107422,5587.1962890625,5687.09619140625,56.0232241158713,19.5975103021003,26.3971481,0,0,0,4449,300.31995,5637.14624023438,,,,,,,,,,,,,,,,,54.480885,,,,,,300.01000975,,,,
,28215087.29,300.00726315,4343.25756835937,0.960267408689237,0.000118843387699422,1,0.999253354069792,40.0298881530762,1.99702630518832,7.53999646753073,10.6200647346093,1.84593808139173,250,-0.000805127141649452,0.960239064291376,-0.000168582518362133,300.0066833,300.007843,4288.2861328125,4398.22900390625,56.0982604537175,19.5990068676181,26.52967355,0,0,0,4449,300.31665,4343.25756835937,,,,,,,,,,,,,,,,,54.480885,,,,,,300.00726315,,,,
,28215100.295,300.0090332,3043.87512207031,0.931065920095366,0.000189102660830666,1,0.999253354069792,40.0298881530762,1.99706957886068,7.53999646753073,10.2973640063111,1.78964148021569,250,-0.000798828326965517,0.931038376644659,-0.000181537423277207,300.0090332,300.0090332,2998.95532226562,3088.794921875,56.0396383147752,19.6001077485052,26.3971481,0,0,0,4449,300.3211,3043.87512207031,,,,,,,,,,,,,,,,,54.480885,,,,,,300.0090332,,,,
,28215113.28,300.00849915,1744.72680664062,0.802583245708972,0.000942345132550709,1,0.999253354069792,40.0298881530762,1.99696590062953,7.53999646753073,8.87647016933615,1.53948147251054,250,-0.000970806057626811,0.80255969842383,-0.000438595239131388,300.0081787,300.0088196,1689.76220703125,1799.69140625,56.0294771440252,19.6007875870119,26.3971481,0,0,0,4449,300.3188,1744.72680664062,,,,,,,,,,,,,,,,,54.480885,,,,,,300.00849915,,,,
,28215129.32,300.0075378,140.621482849121,0.169630121574879,0.00305218591624306,1,0.999253354069792,40.0298881530762,1.9970320540393,7.53999646753073,1.87150529087209,0.321183533414257,25,-0.000504385907993005,0.16962534774404,-0.000391871802497807,300.0075378,300.0075378,130.653167724609,150.589797973633,56.0693401985059,19.5995108691653,25.3631306,0,0,0,4449,300.3175,140.621482849121,,,,,,,,,,,,,,,,,53.339954,,,,,,300.0075378,,,,
,28215141.23,300.0072174,-1047.86227416992,-0.609805765095981,0.0017841356357539,1,0.999253354069792,40.0298881530762,1.99695171487599,7.53999646753073,-6.72481086697453,-1.17075621595051,25,0.000346349381341245,-0.609787641419284,-5.80504329242858E-5,300.007019,300.0074158,-1097.76135253906,-997.963195800781,56.1482846789482,19.5992061356127,26.0126648,0,0,0,4449,300.31695,-1047.86227416992,,,,,,,,,,,,,,,,,54.861191,,,,,,300.0072174,,,,
,28215154.315,300.00616455,-2356.650390625,-0.8925166745631,0.000403985903255075,1,0.999253354069792,40.0298881530762,1.99687922331965,7.53999646753073,-9.84256124876396,-1.71104586849858,25,0.000726445629496975,-0.892490338879638,0.000134648905175629,300.0061035,300.0062256,-2406.24877929687,-2307.05200195313,56.0396383147752,19.6004514341086,25.88013935,0,0,0,4449,300.3165,-2356.650390625,,,,,,,,,,,,,,,,,54.861191,,,,,,300.00616455,,,,
,28215167.245,300.00476075,-3645.11193847656,-0.9495023302757,0.000112829168593894,1,0.999253354069792,40.0298881530762,1.99694071311713,7.53999646753073,-10.4712551859486,-1.82065336727731,25,0.000745043011059184,-0.949474356501869,0.000115575695001564,300.0045166,300.0050049,-3705.134765625,-3585.08911132812,56.1725151630444,19.6037335033023,26.26596545,0,0,0,4449,300.3179,-3645.11193847656,,,,,,,,,,,,,,,,,54.861191,,,,,,300.00476075,,,,
,28215180.265,300.002121,-4950.2392578125,-0.967564196633149,9.84443321427295E-5,1,0.999253354069792,40.0298881530762,1.99693566948969,7.53999646753073,-10.6703563674177,-1.85564084346803,25,0.000726557733615686,-0.967535780627293,8.52579586320212E-5,300.0016785,300.0025635,-4995.22998046875,-4905.24853515625,56.167825391929,19.6014105221321,26.0126648,0,0,0,4449,300.3251,-4950.2392578125,,,,,,,,,,,,,,,,,54.480885,,,,,,300.002121,,,,
,28215193.18,300.00151065,-6240.00634765625,-0.976665980411376,6.05971920335302E-5,1,0.999253354069792,40.0298881530762,1.99691425659273,7.53999646753073,-10.7706705708803,-1.87277949183685,25,0.000760262924816875,-0.976637348401723,0.000113046094797813,300.0011292,300.0018921,-6284.96435546875,-6195.04833984375,56.2647473283136,19.6018671274716,26.0126648,0,0,0,4449,300.3203,-6240.00634765625,,,,,,,,,,,,,,,,,54.861191,,,,,,300.00151065,,,,
,28215208.165,300.0004425,-7739.89331054687,-0.982738706930748,5.6655972069542E-5,1,0.999253354069792,40.0298881530762,1.99692171971483,7.53999646753073,-10.8678565988814,-1.89003852021538,250,0.000733192399189446,-0.982709930071262,8.2104182901155E-5,300.0001831,300.0007019,-7794.9345703125,-7684.85205078125,56.2162863601213,19.6027130896191,26.3971481,0,0,0,4449,300.3182,-7739.89331054687,,,,,,,,,,,,,,,,,54.861191,,,,,,300.0004425,,,,
,28215221.15,299.99617005,-9034.3642578125,-0.986730969133728,9.36986910454999E-5,1,0.999253354069792,40.0298881530762,1.99686010021333,7.53999646753073,-10.9118078019032,-1.89691665849299,250,0.000803204843910981,-0.986702296840825,0.000149622886082799,299.9956055,299.9967346,-9084.359375,-8984.369140625,56.231918930506,19.6022752704389,25.88013935,0,0,0,4449,300.3228,-9034.3642578125,,,,,,,,,,,,,,,,,54.861191,,,,,,299.99617005,,,,
,28215234.15,299.9972992,-9999.86376953125,-0.989255833239282,7.56790754444971E-5,1,0.999253354069792,40.0298881530762,1.99681130957197,7.53999646753073,-10.9393753440958,-1.90224873974122,250,0.000757769214602513,-0.989227023155121,0.000102631986468408,299.9967651,299.9978333,-9999.8857421875,-9999.841796875,56.0466729714482,19.6015048164657,26.26596545,0,0,0,4417,300.32565,-9999.86376953125,,,,,,,,,,,,,,,,,55.241501,,,,,,299.9972992,,,,
,28215247.215,299.99580385,-8851.74658203125,-0.986217164418263,4.68184809308931E-5,1,0.999253354069792,40.0298881530762,1.99689703039994,7.53999646753073,-10.90644584289,-1.8952636840052,250,0.00086608208971687,-0.986188560833473,0.00021281454177451,299.9953308,299.9962769,-8891.62890625,-8811.8642578125,56.2397352156983,19.604791701286,26.3984909,0,0,0,4449,300.3213,-8851.74658203125,,,,,,,,,,,,,,,,,54.480885,,,,,,299.99580385,,,,
,28215260.15,299.99827575,-7559.7822265625,-0.98203779505851,8.79723894050244E-5,1,0.999253354069792,40.0298881530762,1.99686235754905,7.53999646753073,-10.8597198710608,-1.88903703542041,250,0.000696355971986471,-0.982009098191305,4.57450243765785E-5,299.9980774,299.9984741,-7614.64892578125,-7504.91552734375,56.0161894591982,19.6037009364534,25.88013935,0,0,0,4449,300.3303,-7559.7822265625,,,,,,,,,,,,,,,,,54.861191,,,,,,299.99827575,,,,
,28215273.12,300.00149535,-6266.85229492188,-0.976282467397735,4.96596720236096E-5,1,0.999253354069792,40.0298881530762,1.9969590345777,7.53999646753073,-10.7966214253488,-1.87785273342447,250,0.0007107076247128,-0.976253816397726,6.37668784415074E-5,300.0012817,300.001709,-6316.72705078125,-6216.9775390625,56.1389051367175,19.6019778077495,26.52967355,0,0,0,4449,300.32725,-6266.85229492188,,,,,,,,,,,,,,,,,54.861191,,,,,,300.00149535,,,,
,28215286.15,300.002533,-4963.34497070313,-0.967188497607988,8.31932760221487E-5,1,0.999253354069792,40.0298881530762,1.99702261700695,7.53999646753073,-10.6966579127762,-1.85885709939407,250,0.000845451118373633,-0.967160155298687,0.000204386931877008,300.0023499,300.0027161,-5018.3125,-4908.37744140625,56.2162863601213,19.6023392828023,25.88013935,0,0,0,4449,300.3207,-4963.34497070313,,,,,,,,,,,,,,,,,54.861191,,,,,,300.002533,,,,
,28215299.125,300.00183105,-3669.36779785156,-0.948971854437102,9.88937907205362E-5,1,0.999253354069792,40.0298881530762,1.99700777889503,7.53999646753073,-10.4951873378181,-1.82341321238383,250,0.000867604804174165,-0.948944086439588,0.000238495235642513,300.001709,300.0019531,-3719.3916015625,-3619.34399414063,56.2616208142367,19.6064447011948,25.88013935,0,0,0,4449,300.32095,-3669.36779785156,,,,,,,,,,,,,,,,,54.861191,,,,,,300.00183105,,,,
,28215312.07,300.00170895,-2370.02819824219,-0.891012444025726,0.000391644814894541,1,0.999253354069792,40.0298881530762,1.99712284085811,7.53999646753073,-9.85461837329994,-1.71283634660379,250,0.000752028920956292,-0.890986325149996,0.000161237541397909,300.0014343,300.0019836,-2419.97729492187,-2320.0791015625,56.2788166416598,19.6035116970348,26.3971481,0,0,0,4449,300.3198,-2370.02819824219,,,,,,,,,,,,,,,,,54.480885,,,,,,300.00170895,,,,
,28215325.095,300.0016785,-1075.65173339844,-0.604116048536322,0.00179631766717362,1,0.999253354069792,40.0298881530762,1.99706758230176,7.53999646753073,-6.681928228562,-1.15801625228972,250,0.00080599768402096,-0.60409853122815,0.00040536423094181,300.0013123,300.0020447,-1120.6025390625,-1030.70092773438,56.1858028478713,19.6052580823076,26.3971481,0,0,0,4449,300.3206,-1075.65173339844,,,,,,,,,,,,,,,,,55.241501,,,,,,300.0016785,,,,
,28215342.465,300.0009766,662.809204101562,0.413608006206102,0.00238654027981874,1,0.999253354069792,40.0298881530762,1.99692472660467,7.53999646753073,4.56098552477671,0.794859277528202,25,-0.000163252760613765,0.413595765368576,0.000111042556638556,300.0009766,300.0009766,647.815124511719,677.803283691406,56.1834579623136,19.6041582864153,26.26596545,0,0,0,4449,300.31945,662.809204101562,,,,,,,,,,,,,,,,,53.339954,,,,,,300.0009766,,,,
,28215355.06,299.99880985,1920.87109375,0.840821145535959,0.000706521170076854,1,0.999253354069792,40.0298881530762,1.99685856106169,7.53999646753073,9.27213444796318,1.61331915456454,25,-0.000557890069390694,0.840796489331658,-3.55295224779119E-7,299.9987183,299.9989014,1865.98608398438,1975.75610351562,56.1748600486021,19.6048834811799,26.26596545,0,0,0,4449,300.32175,1920.87109375,,,,,,,,,,,,,,,,,54.861191,,,,,,299.99880985,,,,
,28215368.07,299.9992218,3224.35559082031,0.938049320998085,0.000159027325000448,1,0.999253354069792,40.0298881530762,1.99696525128699,7.53999646753073,10.3449478219363,1.79945064056826,25,-0.000669323392650226,0.938021839165139,-4.74214415014569E-5,299.9989624,299.9994812,3174.20263671875,3274.50854492188,56.3905895199098,19.6035898628319,25.3631306,0,0,0,4449,300.32085,3224.35559082031,,,,,,,,,,,,,,,,,53.720264,,,,,,299.9992218,,,,
,28215381.03,300.0001068,4514.69482421875,0.962611259241847,0.00010499758941743,1,0.999253354069792,40.0298881530762,1.99699598072332,7.53999646753073,10.6160744710755,1.8460565818267,25,-0.000735589357841608,0.96258306782096,-9.75218949418015E-5,299.9994507,300.0007629,4464.7060546875,4564.68359375,56.221757759756,19.6059734684644,26.3971481,0,0,0,4449,300.32165,4514.69482421875,,,,,,,,,,,,,,,,,55.241501,,,,,,300.0001068,,,,
,28215394.025,299.99790955,5814.46484375,0.973500393879429,6.42188712180355E-5,1,0.999253354069792,40.0298881530762,1.9970502216777,7.53999646753073,10.7363684749733,1.86746222953334,25,-0.000700890396654071,0.973471948862439,-5.5728566006209E-5,299.9978027,299.9980164,5764.54736328125,5864.38232421875,56.218631245679,19.60391063818,25.88013935,0,0,0,4449,300.3197,5814.46484375,,,,,,,,,,,,,,,,,53.720264,,,,,,299.99790955,,,,
,28215409.335,299.9976807,7349.46850585938,0.980437093136772,0.00010267297755906,1,0.999253354069792,40.0298881530762,1.99698221393091,7.53999646753073,10.8429327547787,1.88448802006351,250,-0.000838225227466601,0.980408557083469,-0.000188633371829092,299.9976807,299.9976807,7344.47705078125,7354.4599609375,56.1263990804098,19.6023364005877,25.3631306,0,0,0,4449,300.3245,7349.46850585938,,,,,,,,,,,,,,,,,53.720264,,,,,,299.9976807,,,,
,28215422.01,299.998703,8614.0634765625,0.985031608051315,9.5800746191706E-5,1,0.999253354069792,40.0298881530762,1.99688944781612,7.53999646753073,10.8932567493031,1.89318658841244,250,-0.000846189539971787,0.985002915175301,-0.000193702163755536,299.9980164,299.9993896,8564.0927734375,8664.0341796875,56.1514111930252,19.6036201673895,26.3971481,0,0,0,4449,300.32925,8614.0634765625,,,,,,,,,,,,,,,,,54.861191,,,,,,299.998703,,,,
,28215435.03,299.99813845,9913.77490234375,0.98838162707625,0.000102034796462877,1,0.999253354069792,40.0298881530762,1.99697044437758,7.53999646753073,10.9306014331849,1.90048640541365,250,-0.000777893583038239,0.988352821903449,-0.00012331036576599,299.9979248,299.9983521,9863.8173828125,9963.732421875,56.1615723637752,19.6061182625258,25.3631306,0,0,0,4449,300.32,9913.77490234375,,,,,,,,,,,,,,,,,54.861191,,,,,,299.99813845,,,,
,28215447.99,299.99795535,9999.7861328125,0.988573797428319,0.000101340891708978,1,0.999253354069792,40.0298881530762,1.9968366904047,7.53999646753073,10.9320814506185,1.90031786712182,250,-0.000815409965223309,0.988545019812588,-0.000160714038458077,299.9973145,299.9985962,9999.7861328125,9999.7861328125,56.282724784256,19.6048546443112,26.3971481,0,0,0,4401,300.3223,9999.7861328125,,,,,,,,,,,,,,,,,55.241501,,,,,,299.99795535,,,,
,28215460.975,299.99673465,9999.7861328125,0.988613862142792,0.000117780772170076,1,0.999253354069792,40.0298881530762,1.9968240358926,7.53999646753073,10.9324828486217,1.90023595599155,250,-0.000828758576702924,0.988585138860311,-0.000174034697918567,299.9966431,299.9968262,9999.7861328125,9999.7861328125,56.1295255944867,19.6035497260242,26.26596545,0,0,0,4401,300.3219,9999.7861328125,,,,,,,,,,,,,,,,,53.720264,,,,,,299.99673465,,,,
,28215473.945,299.99554445,9999.7861328125,0.98860766037274,0.000121240896526069,1,0.999253354069792,40.0298881530762,1.99679519305689,7.53999646753073,10.9322182010434,1.90043681410912,250,-0.000807072962609783,0.988578969552462,-0.000152365449487928,299.9947815,299.9963074,9999.7861328125,9999.7861328125,56.127180708929,19.6020925116855,26.52967355,0,0,0,4369,300.3264,9999.7861328125,,,,,,,,,,,,,,,,,55.241501,,,,,,299.99554445,,,,
,28215486.965,299.99635315,9999.501953125,0.988561631725665,0.000107461302732632,1,0.999253354069792,40.0298881530762,1.99686654795985,7.53999646753073,10.9320570584449,1.90061263088981,250,-0.000789168142698846,0.988532897292737,-0.000134467740690177,299.9960938,299.9966125,9999.4853515625,9999.5185546875,56.2280107879098,19.6039467720841,26.26596545,0,0,0,4385,300.31715,9999.501953125,,,,,,,,,,,,,,,,,54.861191,,,,,,299.99635315,,,,
,28215499.945,299.99842835,9913.94873046875,0.988193312751765,7.56210913768494E-5,1,0.999253354069792,40.0298881530762,1.99673070140004,7.53999646753073,10.9273293643609,1.89935014441995,250,-0.000827514704094033,0.988164537867995,-0.000173087753731539,299.9981079,299.9987488,9830.7890625,9997.1083984375,56.2921043264867,19.6037682723468,26.3971481,0,0,0,4449,300.3328,9913.94873046875,,,,,,,,,,,,,,,,,55.241501,,,,,,299.99842835,,,,
,28215512.945,300.0010681,7328.57788085938,0.980368690636305,0.000107069635069711,1,0.999253354069792,40.0298881530762,1.99681628006769,7.53999646753073,10.8412329053913,1.88454181054868,250,-0.000807502329425731,0.980340008479525,-0.000157967151691504,300.0005798,300.0015564,7238.7373046875,7418.41845703125,56.1858028478713,19.6075632289998,25.88013935,0,0,0,4449,300.32945,7328.57788085938,,,,,,,,,,,,,,,,,54.861191,,,,,,300.0010681,,,,
,28215525.91,300.002655,4741.97705078125,0.964181927380265,0.000157217568885844,1,0.999253354069792,40.0298881530762,1.9966876970198,7.53999646753073,10.6617394147811,1.8522865995414,250,-0.000886934424404498,0.964153696973921,-0.00024785185538283,300.0026245,300.0026855,4642.08740234375,4841.86669921875,56.3085185253906,19.6036068108588,26.3971481,0,0,0,4449,300.3252,4741.97705078125,,,,,,,,,,,,,,,,,55.241501,,,,,,300.002655,,,,
,28215538.925,300.00611875,2143.24395751953,0.864490301565907,0.00114140073050859,1,0.999253354069792,40.0298881530762,1.99676854619614,7.53999646753073,9.55994683888746,1.65968672663775,250,-0.000899304186908439,0.864464923399128,-0.000326076637470975,300.0059814,300.0062561,2043.30383300781,2243.18408203125,56.2639656997944,19.6063481367669,25.88013935,0,0,0,4449,300.3198,2143.24395751953,,,,,,,,,,,,,,,,,55.241501,,,,,,300.00611875,,,,
,28215556.28,300.0041809,-0.0891649797558785,-0.010699041625294,7.69472978908077E-7,1,0.999253354069792,40.0298881530762,1.99673088235731,7.53999646753073,-0.117937139557205,-0.0204931716741316,2.5,9.52023159952884E-6,-0.010698727129122,2.42427257502167E-6,300.0041809,300.0041809,-0.0891649797558785,-0.0891649797558785,56.2545861575636,19.605903377735,26.3971481,0,0,0,4401,300.31775,-0.0891649797558785,,,,,,,,,,,,,,,,,54.861191,,,,,,300.0041809,,,,
,28215568.885,300.0029602,-0.0891649797558785,-0.0100849689226482,1.96953710804803E-6,1,0.999253354069792,40.0298881530762,1.99678677760132,7.53999646753073,-0.111169897948783,-0.0193248263873611,2.5,8.30860420911887E-6,-0.0100846725126325,1.61993461695819E-6,300.0028076,300.0031128,-0.0891649797558785,-0.0891649797558785,56.1990905326983,19.6053702110896,26.0126648,0,0,0,4401,300.3176,-0.0891649797558785,,,,,,,,,,,,,,,,,55.241501,,,,,,300.0029602,,,,
,28215581.875,300.0024109,-0.0891649797558785,-0.00965811167000489,1.33571552438905E-6,1,0.999253354069792,40.0298881530762,1.99687143442654,7.53999646753073,-0.106470655852895,-0.018497808321981,2.5,8.84994794773639E-6,-0.00965782860418869,2.44436192818505E-6,300.0023499,300.0024719,-0.0891649797558785,-0.0891649797558785,56.3905895199098,19.6082648827789,25.88013935,0,0,0,4369,300.3178,-0.0891649797558785,,,,,,,,,,,,,,,,,55.241501,,,,,,300.0024109,,,,
,28215594.905,300.00190735,-0.0891649797558785,-0.00937748101959273,7.15969515695962E-7,1,0.999253354069792,40.0298881530762,1.99679125640045,7.53999646753073,-0.103372403958576,-0.0179626279590484,2.5,8.31985116890957E-6,-0.00937720619238503,2.10052842965965E-6,300.0010681,300.0027466,-0.0891649797558785,-0.0891649797558785,56.1060767389098,19.608452650341,26.0126648,0,0,0,4369,300.32315,-0.0891649797558785,,,,,,,,,,,,,,,,,53.720264,,,,,,300.00190735,,,,
,28215607.84,300.001236,-0.0891649797558785,-0.00917067091615329,9.24859542024555E-7,1,0.999253354069792,40.0298881530762,1.99686425920497,7.53999646753073,-0.101098746612759,-0.0175528909191395,2.5,9.4266180844731E-6,-0.00917040323838684,3.3443512066055E-6,300.0006409,300.0018311,-0.0891649797558785,-0.0891649797558785,56.1263990804098,19.6101228850062,26.26596545,0,0,0,4369,300.3204,-0.0891649797558785,,,,,,,,,,,,,,,,,55.241501,,,,,,300.001236,,,,
,28215620.86,300.0013428,-0.0891649797558785,-0.00900665478475533,4.8290206868801E-7,1,0.999253354069792,40.0298881530762,1.99686779083549,7.53999646753073,-0.0992880105190953,-0.0172548544884938,2.5,7.81862659931362E-6,-0.0090063909074223,1.84523858878477E-6,300.000824,300.0018616,-0.0891649797558785,-0.0891649797558785,56.2553677860829,19.6079408406293,26.00747395,0,0,0,4369,300.32275,-0.0891649797558785,,,,,,,,,,,,,,,,,53.720264,,,,,,300.0013428,,,,
,28215633.83,300.0041046,-0.0891649797558785,-0.00887239565205372,7.88820515931031E-7,1,0.999253354069792,40.0298881530762,1.99681217997345,7.53999646753073,-0.0977974442392592,-0.0170420258301215,2.5,3.63298072806987E-6,-0.0088721320586823,-2.25125615931442E-6,300.0040283,300.0041809,-0.0891649797558785,-0.0891649797558785,56.2905410694483,19.604878202772,26.0126648,0,0,0,4369,300.32215,-0.0891649797558785,,,,,,,,,,,,,,,,,55.241501,,,,,,300.0041046,,,,
,28215646.835,300.00390625,-0.0891649797558785,-0.00875867202412075,1.06074008088278E-6,1,0.999253354069792,40.0298881530762,1.99675343654766,7.53999646753073,-0.0965489660446043,-0.0167782106646721,2.5,7.6594809711092E-6,-0.00875841457276102,1.85048584353102E-6,300.0036011,300.0042114,-0.0891649797558785,-0.0891649797558785,56.1646988778521,19.6072614955273,26.3971481,0,0,0,4369,300.3196,-0.0891649797558785,,,,,,,,,,,,,,,,,54.100574,,,,,,300.00390625,,,,
,28215659.85,300.00413515,-0.0891649797558785,-0.00865277868576983,9.74456875690099E-7,1,0.999253354069792,40.0298881530762,1.99682719402826,7.53999646753073,-0.0953822387145963,-0.0165925093094341,2.5,6.06540280327076E-6,-0.00865252327336711,3.26671628811023E-7,300.0039368,300.0043335,-0.0891649797558785,-0.0891649797558785,56.3327490094867,19.6072701181012,26.3971481,0,0,0,4369,300.31905,-0.0891649797558785,,,,,,,,,,,,,,,,,55.241501,,,,,,300.00413515,,,,
,28215672.815,300.00245665,-0.0891649797558785,-0.00855941803851744,2.90525258081069E-7,1,0.999253354069792,40.0298881530762,1.99687747630344,7.53999646753073,-0.0943577958173773,-0.0164003425432203,2.5,7.22888267665984E-6,-0.00855916675049298,1.55199681126628E-6,300.0023193,300.002594,-0.0891649797558785,-0.0891649797558785,56.3788650921214,19.6085680404822,26.52967355,0,0,0,4369,300.3174,-0.0891649797558785,,,,,,,,,,,,,,,,,55.621811,,,,,,300.00245665,,,,
,28215685.82,300.0035858,-0.0891649797558785,-0.00847791798668999,8.2303715004613E-7,1,0.999253354069792,40.0298881530762,1.99692308781901,7.53999646753073,-0.0934599685747161,-0.0162529617703559,2.5,6.3966272836572E-6,-0.00847766821084301,7.7378221051483E-7,300.0031128,300.0040588,-0.0891649797558785,-0.0891649797558785,56.2373903301406,19.6084195233673,26.1399994,0,0,0,4369,300.3158,-0.0891649797558785,,,,,,,,,,,,,,,,,53.720264,,,,,,300.0035858,,,,
,28215698.79,300.0029907,-0.0891649797558785,-0.00840511006814799,8.53360384694462E-7,1,0.999253354069792,40.0298881530762,1.9968210791534,7.53999646753073,-0.0926570024732795,-0.0160879662473689,2.5,8.57438204352198E-6,-0.00840486412216551,2.99987327074294E-6,300.0029602,300.0030212,-0.0891649797558785,-0.0891649797558785,56.289759440929,19.6096111403986,26.52967355,0,0,0,4369,300.321,-0.0891649797558785,,,,,,,,,,,,,,,,,55.241501,,,,,,300.0029907,,,,
,28215711.775,300.00209045,-0.0891649797558785,-0.008337298925292,6.06588741907638E-7,1,0.999253354069792,40.0298881530762,1.99674240248921,7.53999646753073,-0.0919060367816312,-0.0159568563571113,2.5,8.5687218982648E-6,-0.00833705528871823,3.03909721286882E-6,300.0018921,300.0022888,-0.0891649797558785,-0.0891649797558785,56.3327490094867,19.6097364129324,25.88013935,0,0,0,4369,300.31695,-0.0891649797558785,,,,,,,,,,,,,,,,,55.241501,,,,,,300.00209045,,,,
,28215724.77,300.00209045,-0.0891649797558785,-0.00827645839628395,9.84814787873114E-7,1,0.999253354069792,40.0298881530762,1.99682495805592,7.53999646753073,-0.0912354314049828,-0.0158618193515908,2.5,6.62234831138818E-6,-0.00827621527962781,1.13303536824791E-6,300.0014954,300.0026855,-0.0891649797558785,-0.0891649797558785,56.2483331294098,19.6076506339529,25.88013935,0,0,0,4369,300.3125,-0.0891649797558785,,,,,,,,,,,,,,,,,55.621811,,,,,,300.00209045,,,,
,28215737.79,300.00201415,-0.0891649797558785,-0.00822273598954875,6.86526564960554E-7,1,0.999253354069792,40.0298881530762,1.99680751098197,7.53999646753073,-0.0906454487906029,-0.0157415442106399,2.5,8.13805325547269E-6,-0.00822249552303784,2.68448193609395E-6,300.0014038,300.0026245,-0.0891649797558785,-0.0891649797558785,56.3475999513521,19.6096191232678,25.88013935,0,0,0,4369,300.3198,-0.0891649797558785,,,,,,,,,,,,,,,,,55.241501,,,,,,300.00201415,,,,
,28215750.78,300.0027771,-0.0891649797558785,-0.00817032156969275,4.98127840161746E-7,1,0.999253354069792,40.0298881530762,1.99682219880203,7.53999646753073,-0.0900663384227806,-0.015652495068388,2.5,7.07182054662204E-6,-0.00817008172023873,1.65302632040466E-6,300.0019531,300.0036011,-0.0891649797558785,-0.0891649797558785,56.1693886489675,19.6107816318902,26.52967355,0,0,0,4369,300.31905,-0.0891649797558785,,,,,,,,,,,,,,,,,55.241501,,,,,,300.0027771,,,,
,28215763.785,300.00579835,-0.0891649797558785,-0.00812118152219587,5.59900768586196E-7,1,0.999253354069792,40.0298881530762,1.9967914433625,7.53999646753073,-0.0895228928678568,-0.0155603143587916,2.5,6.82998345578856E-6,-0.00812094202807379,1.44374041809676E-6,300.0054016,300.0061951,-0.0891649797558785,-0.0891649797558785,56.3577611221021,19.6074993779274,26.00747395,0,0,0,4369,300.3169,-0.0891649797558785,,,,,,,,,,,,,,,,,55.241501,,,,,,300.00579835,,,,
,28215776.75,300.00512695,-0.0891649797558785,-0.00807639231965273,8.81012530652339E-7,1,0.999253354069792,40.0298881530762,1.99688718740892,7.53999646753073,-0.0890341845258523,-0.0154704446927145,2.5,7.22602300988261E-6,-0.00807615464275581,1.86945684867079E-6,300.0044861,300.0057678,-0.0891649797558785,-0.0891649797558785,56.2788166416598,19.6094418830359,26.662199,0,0,0,4369,300.31615,-0.0891649797558785,,,,,,,,,,,,,,,,,55.621811,,,,,,300.00512695,,,,
,28215789.715,300.00546265,-0.0891649797558785,-0.00803430207496397,3.58656119885345E-7,1,0.999253354069792,40.0298881530762,1.99674643608315,7.53999646753073,-0.0885677814550583,-0.0153674707850025,2.5,9.11971968463642E-6,-0.00803406681196133,3.79099869818362E-6,300.0053711,300.0055542,-0.0891649797558785,-0.0891649797558785,56.1756416771213,19.6092866594052,25.88013935,0,0,0,4369,300.31555,-0.0891649797558785,,,,,,,,,,,,,,,,,55.241501,,,,,,300.00546265,,,,
,28215802.71,300.0031128,-0.0891649797558785,-0.00799298054189654,8.01409085637467E-7,1,0.999253354069792,40.0298881530762,1.99677345520925,7.53999646753073,-0.0881114968039351,-0.0152997697480549,2.5,8.06283803144118E-6,-0.00799274654487636,2.76152991878176E-6,300.0029602,300.0032654,-0.0891649797558785,-0.0891649797558785,56.350726465429,19.6115849946634,26.52967355,0,0,0,4369,300.3144,-0.0891649797558785,,,,,,,,,,,,,,,,,55.621811,,,,,,300.0031128,,,,
,28215815.755,300.0022125,-0.0891649797558785,-0.00795617841405116,7.53385496924764E-7,1,0.999253354069792,40.0298881530762,1.99673101754466,7.53999646753073,-0.0877030206699236,-0.0152345061980575,2.5,7.5269169435251E-6,-0.00795594543770813,2.24999311200895E-6,300.0015869,300.0028381,-0.0891649797558785,-0.0891649797558785,56.3874630058329,19.6110311659552,26.26596545,0,0,0,4369,300.3125,-0.0891649797558785,,,,,,,,,,,,,,,,,55.241501,,,,,,300.0022125,,,,
,28215828.72,300.0018921,-0.0891649797558785,-0.00791804349286397,7.45305730391067E-7,1,0.999253354069792,40.0298881530762,1.99666569144376,7.53999646753073,-0.0872797032268441,-0.0151618548872042,2.5,7.41309363284712E-6,-0.00791781169207743,2.16160086815131E-6,300.00177,300.0020142,-0.0891649797558785,-0.0891649797558785,56.2952308405636,19.6105805954262,26.3971481,0,0,0,4369,300.31905,-0.0891649797558785,,,,,,,,,,,,,,,,,55.241501,,,,,,300.0018921,,,,
,28215841.74,300.0014496,-0.0891649797558785,-0.00788457596629732,9.20451506272241E-7,1,0.999253354069792,40.0298881530762,1.99678750947744,7.53999646753073,-0.0869164327291211,-0.0150961470165861,2.5,7.61098956039556E-6,-0.00788434542396574,2.38159070046354E-6,300.0013733,300.0015259,-0.0891649797558785,-0.0891649797558785,56.2913226979675,19.6112288767083,25.88013935,0,0,0,4369,300.3144,-0.0891649797558785,,,,,,,,,,,,,,,,,54.100574,,,,,,300.0014496,,,,
,28215854.71,300.002182,-0.0891649797558785,-0.00785077365282218,7.8763170827034E-7,1,0.999253354069792,40.0298881530762,1.99677185191205,7.53999646753073,-0.0865424449236753,-0.0150353029977582,2.5,7.21615654803617E-6,-0.00785054364256727,2.0092636901647E-6,300.0012817,300.0030823,-0.0891649797558785,-0.0891649797558785,56.2881961838906,19.6107934319645,26.3971481,0,0,0,4369,300.3181,-0.0891649797558785,,,,,,,,,,,,,,,,,55.621811,,,,,,300.002182,,,,
,28215867.66,299.9993286,-0.0891649797558785,-0.0078198775499197,5.10602471040317E-7,1,0.999253354069792,40.0298881530762,1.9967094500802,7.53999646753073,-0.0862002659839863,-0.0149697660403554,2.5,7.72407608129884E-6,-0.00781964965569038,2.53755027288796E-6,299.9985962,300.000061,-0.0891649797558785,-0.0891649797558785,56.343691808756,19.6102929942497,25.88013935,0,0,0,4369,300.3128,-0.0891649797558785,,,,,,,,,,,,,,,,,54.100574,,,,,,299.9993286,,,,
,28215880.64,300.00001525,-0.0891649797558785,-0.00778988465679148,8.43284177481594E-7,1,0.999253354069792,40.0298881530762,1.99669783063498,7.53999646753073,-0.08587148634368,-0.0148989223575745,2.5,8.90497392514084E-6,-0.00778965823788714,3.73836894714707E-6,299.9990234,300.0010071,-0.0891649797558785,-0.0891649797558785,56.2866329268521,19.6116809590068,26.3971481,0,0,0,4369,300.31595,-0.0891649797558785,,,,,,,,,,,,,,,,,55.241501,,,,,,300.00001525,,,,
,28215893.665,299.99710085,-0.0891649797558785,-0.00775907013097577,4.63201654250918E-7,1,0.999253354069792,40.0298881530762,1.99666987361234,7.53999646753073,-0.0855262894228274,-0.0148646893453182,2.5,6.61004148682432E-6,-0.00775884398341087,1.46391829817246E-6,299.9968872,299.9973145,-0.0891649797558785,-0.0891649797558785,56.3319673809675,19.6111824166691,26.3971481,0,0,0,4369,300.3148,-0.0891649797558785,,,,,,,,,,,,,,,,,54.100574,,,,,,299.99710085,,,,
,28215906.66,299.99980165,-0.0891649797558785,-0.00773100669141147,7.50117886597721E-7,1,0.999253354069792,40.0298881530762,1.99673620408367,7.53999646753073,-0.0852236810022137,-0.0147887210379965,2.5,8.6443259526853E-6,-0.00773078192691129,3.51685928255921E-6,299.9994202,300.0001831,-0.0891649797558785,-0.0891649797558785,56.2178496171598,19.6136399171944,26.0126648,0,0,0,4369,300.32,-0.0891649797558785,,,,,,,,,,,,,,,,,55.621811,,,,,,299.99980165,,,,
,28215919.64,299.99954225,-0.0891649797558785,-0.00770178748686854,4.8879464448574E-7,1,0.999253354069792,40.0298881530762,1.99669690591978,7.53999646753073,-0.0849001628333071,-0.0147312853460718,2.5,8.7258291622949E-6,-0.00770156372223426,3.61770704103772E-6,299.9989014,300.0001831,-0.0891649797558785,-0.0891649797558785,56.2311373019867,19.6137058565264,25.88013935,0,0,0,4369,300.31845,-0.0891649797558785,,,,,,,,,,,,,,,,,55.621811,,,,,,299.99954225,,,,
,28215932.665,299.9974213,-0.0891649797558785,-0.00767706029991377,9.50711428370414E-7,1,0.999253354069792,40.0298881530762,1.99667079538222,7.53999646753073,-0.0846233857761828,-0.0147016693300434,2.5,7.07672957256322E-6,-0.00767683680384267,1.98499063147601E-6,299.9966431,299.9981995,-0.0891649797558785,-0.0891649797558785,56.2311373019867,19.6108897399675,25.88013935,0,0,0,4369,300.3152,-0.0891649797558785,,,,,,,,,,,,,,,,,55.621811,,,,,,299.9974213,,,,
,28215945.66,299.9955902,-0.0891649797558785,-0.0076514733257318,4.80714441644299E-7,1,0.999253354069792,40.0298881530762,1.99659694579896,7.53999646753073,-0.0843391232593098,-0.0146473853555199,2.5,7.4845057947695E-6,-0.00765125140911136,2.40978562453853E-6,299.9953918,299.9957886,-0.0891649797558785,-0.0891649797558785,56.2608391857175,19.6119644032061,26.3971481,0,0,0,4369,300.31825,-0.0891649797558785,,,,,,,,,,,,,,,,,55.621811,,,,,,299.9955902,,,,
,28215958.61,299.9958649,-0.0891649797558785,-0.00762513831594561,8.2099821802339E-7,1,0.999253354069792,40.0298881530762,1.9966818465801,7.53999646753073,-0.0840528135194159,-0.0145948929365606,2.5,7.70251734809877E-6,-0.00762491724467672,2.6452681831714E-6,299.995575,299.9961548,-0.0891649797558785,-0.0891649797558785,56.432015831429,19.6148675889432,26.26596545,0,0,0,4369,300.31885,-0.0891649797558785,,,,,,,,,,,,,,,,,55.621811,,,,,,299.9958649,,,,
,28215971.62,299.9962616,-0.0891649797558785,-0.00760088949932301,6.16959266347855E-7,1,0.999253354069792,40.0298881530762,1.99666954875994,7.53999646753073,-0.083786285349074,-0.014541083760975,2.5,8.3412089735658E-6,-0.00760066944306486,3.299899338687E-6,299.9958191,299.9967041,-0.0891649797558785,-0.0891649797558785,56.3022654972367,19.6135716144755,26.26596545,0,0,0,4369,300.31265,-0.0891649797558785,,,,,,,,,,,,,,,,,55.241501,,,,,,299.9962616,,,,
,28215984.61,299.99624635,-0.0891649797558785,-0.00757703205530515,2.0049052277019E-7,1,0.999253354069792,40.0298881530762,1.9965654119888,7.53999646753073,-0.0835165590104644,-0.0145088542284122,2.5,7.03067939191096E-6,-0.00757681185755202,2.00540099679525E-6,299.9962158,299.9962769,-0.0891649797558785,-0.0891649797558785,56.2639656997944,19.6124212193708,25.88013935,0,0,0,4369,300.3212,-0.0891649797558785,,,,,,,,,,,,,,,,,55.621811,,,,,,299.99624635,,,,
,28215997.59,299.99845885,-0.0891649797558785,-0.00755471231085785,4.89633518230442E-7,1,0.999253354069792,40.0298881530762,1.99672260698494,7.53999646753073,-0.0832786587441508,-0.0144575079763949,2.5,7.89204628502864E-6,-0.00755449270251033,2.88158502741304E-6,299.9979553,299.9989624,-0.0891649797558785,-0.0891649797558785,56.3773018350829,19.6128711053928,26.52967355,0,0,0,4369,300.32325,-0.0891649797558785,,,,,,,,,,,,,,,,,55.241501,,,,,,299.99845885,,,,
,28216010.58,300.0002289,-0.0891649797558785,-0.00753151026399004,4.23546811272708E-7,1,0.999253354069792,40.0298881530762,1.99667879202444,7.53999646753073,-0.0830222252635269,-0.0144063659339509,2.5,8.45128798876476E-6,-0.00753129118887952,3.45606811425261E-6,299.999939,300.0005188,-0.0891649797558785,-0.0891649797558785,56.2514596434867,19.6131847620299,25.88013935,0,0,0,4369,300.3167,-0.0891649797558785,,,,,,,,,,,,,,,,,54.100574,,,,,,300.0002289,,,,
,28216023.59,300.000824,-0.0891649797558785,-0.00750767810904663,6.46265786460323E-7,1,0.999253354069792,40.0298881530762,1.99667233488543,7.53999646753073,-0.082757269694935,-0.0143720800310683,2.5,7.39505180978999E-6,-0.00750745886956285,2.41565042322866E-6,300.0004883,300.0011597,-0.0891649797558785,-0.0891649797558785,56.374175321006,19.6115131330557,26.3971481,0,0,0,4369,300.31575,-0.0891649797558785,,,,,,,,,,,,,,,,,55.621811,,,,,,300.000824,,,,
,28216036.56,300.00094605,-0.0891649797558785,-0.00748851595195943,3.4035636015092E-7,1,0.999253354069792,40.0298881530762,1.99660590516257,7.53999646753073,-0.0825407748587464,-0.0143496987128218,2.5,6.03494355666073E-6,-0.00748829645299364,1.06947718019268E-6,300.0007324,300.0011597,-0.0891649797558785,-0.0891649797558785,56.2545861575636,19.6097301772881,25.88013935,0,0,0,4369,300.37625,-0.0891649797558785,,,,,,,,,,,,,,,,,55.621811,,,,,,300.00094605,,,,
,28216049.61,300.0075531,-0.0891649797558785,-0.00746643861746935,5.96508201278841E-7,1,0.999253354069792,40.0298881530762,1.99651670324129,7.53999646753073,-0.0822959842113992,-0.0142942977539529,2.5,7.14924212013584E-6,-0.00746621852048862,2.19744039851162E-6,300.0075073,300.0075989,-0.0891649797558785,-0.0891649797558785,56.3046103827944,19.6094255928693,25.88013935,0,0,0,4369,300.32815,-0.0891649797558785,,,,,,,,,,,,,,,,,56.002121,,,,,,300.0075531,,,,
,28216062.545,300.0070343,-0.0891649797558785,-0.00744686770111286,5.32264917645337E-7,1,0.999253354069792,40.0298881530762,1.99668752815976,7.53999646753073,-0.0820877567013879,-0.0142545742772951,2.5,7.44423750178361E-6,-0.00744664848403212,2.50479083030767E-6,300.0066528,300.0074158,-0.0891649797558785,-0.0891649797558785,56.323369467256,19.6128793600165,25.88013935,0,0,0,4369,300.2966,-0.0891649797558785,,,,,,,,,,,,,,,,,55.621811,,,,,,300.0070343,,,,
,28216075.535,300.0004883,-0.0891649797558785,-0.00742817098879634,5.04929081204694E-7,1,0.999253354069792,40.0298881530762,1.99662190724921,7.53999646753073,-0.0818783366803285,-0.0142223833988104,2.5,7.05776105308732E-6,-0.00742795397273774,2.13083920916051E-6,300.0004578,300.0005188,-0.0891649797558785,-0.0891649797558785,56.2577126716406,19.6123337974334,26.3971481,0,0,0,4369,300.30235,-0.0891649797558785,,,,,,,,,,,,,,,,,55.621811,,,,,,300.0004883,,,,
,28216088.58,299.99627685,-0.0891649797558785,-0.00740710564073548,3.69659924862343E-7,1,0.999253354069792,40.0298881530762,1.99659290985576,7.53999646753073,-0.0816448952914406,-0.0141824020931855,2.5,6.98773865581737E-6,-0.00740689041633389,2.07479464564562E-6,299.9960327,299.996521,-0.0891649797558785,-0.0891649797558785,56.381209977679,19.6094581230562,25.3631306,0,0,0,4369,300.30255,-0.0891649797558785,,,,,,,,,,,,,,,,,54.480885,,,,,,299.99627685,,,,
,28216101.525,299.99630735,-0.0891649797558785,-0.00738787931624312,2.82725904072073E-7,1,0.999253354069792,40.0298881530762,1.99667992396173,7.53999646753073,-0.0814374369303345,-0.014140547457135,2.5,7.48159745303451E-6,-0.0073876650077065,2.5816865245348E-6,299.9962158,299.9963989,-0.0891649797558785,-0.0891649797558785,56.259275928679,19.6131332412879,26.52967355,0,0,0,4369,300.31785,-0.0891649797558785,,,,,,,,,,,,,,,,,56.002121,,,,,,299.99630735,,,,
,28216114.525,299.99821475,-0.0891649797558785,-0.00736888799295144,5.27663519220877E-7,1,0.999253354069792,40.0298881530762,1.99663379960822,7.53999646753073,-0.081222317520384,-0.0141263830009263,2.5,5.42022501565581E-6,-0.00736867234145304,5.33029235407679E-7,299.9976807,299.9987488,-0.0891649797558785,-0.0891649797558785,56.3319673809675,19.6112226060894,26.52967355,0,0,0,4369,300.3209,-0.0891649797558785,,,,,,,,,,,,,,,,,55.621811,,,,,,299.99821475,,,,
,28216127.52,300.00012205,-0.0891649797558785,-0.0073496748979854,2.5044336223225E-7,1,0.999253354069792,40.0298881530762,1.99666771108749,7.53999646753073,-0.0810159250076871,-0.0140666649787023,2.5,7.5039949699858E-6,-0.00734946064194422,2.62931264492192E-6,299.9995117,300.0007324,-0.0891649797558785,-0.0891649797558785,56.2749084990636,19.615818347719,26.3971481,0,0,0,4369,300.31225,-0.0891649797558785,,,,,,,,,,,,,,,,,56.002121,,,,,,300.00012205,,,,
,28216140.5,299.99861145,-0.0891649797558785,-0.00733170867500098,7.56517954496831E-7,1,0.999253354069792,40.0298881530762,1.99671795224436,7.53999646753073,-0.0808192010532485,-0.014036510316579,2.5,7.13322127418092E-6,-0.00733149513719883,2.27045420009405E-6,299.9983521,299.9988708,-0.0891649797558785,-0.0891649797558785,56.3163348105829,19.6158692360989,25.88013935,0,0,0,4369,300.31165,-0.0891649797558785,,,,,,,,,,,,,,,,,55.621811,,,,,,299.99861145,,,,
,28216153.5,299.9988861,-0.0891649797558785,-0.00731385365665794,3.16341301335665E-7,1,0.999253354069792,40.0298881530762,1.99668315371569,7.53999646753073,-0.0806214668148,-0.0139994341048672,2.5,7.35655472442853E-6,-0.00731364072698629,2.5056936771581E-6,299.9984436,299.9993286,-0.0891649797558785,-0.0891649797558785,56.3163348105829,19.6124047921659,26.3971481,0,0,0,4369,300.31535,-0.0891649797558785,,,,,,,,,,,,,,,,,56.002121,,,,,,299.9988861,,,,
,28216166.485,299.9968567,-0.0891649797558785,-0.00729477063967226,9.25133409920994E-7,1,0.999253354069792,40.0298881530762,1.99668457500299,7.53999646753073,-0.0804111232058693,-0.0139632135778695,2.5,7.31063975725832E-6,-0.0072945588141353,2.47235233892949E-6,299.9965515,299.9971619,-0.0891649797558785,-0.0891649797558785,56.3773018350829,19.6137829242591,25.88013935,0,0,0,4369,300.31095,-0.0891649797558785,,,,,,,,,,,,,,,,,54.480885,,,,,,299.9968567,,,,
,28216179.5,299.9950714,-0.0891649797558785,-0.00727891143057233,4.8773812086665E-7,1,0.999253354069792,40.0298881530762,1.99671792202048,7.53999646753073,-0.0802362109420341,-0.0139411747255597,2.5,6.56077976630953E-6,-0.00727870008566589,1.73306916528489E-6,299.9946289,299.9955139,-0.0891649797558785,-0.0891649797558785,56.4359239740252,19.6140937701867,26.3971481,0,0,0,4369,300.31285,-0.0891649797558785,,,,,,,,,,,,,,,,,56.002121,,,,,,299.9950714,,,,
,28216192.43,299.99139405,-0.0891649797558785,-0.00725799171889165,1.11292627874662E-6,1,0.999253354069792,40.0298881530762,1.99685846458003,7.53999646753073,-0.080010241337591,-0.0139072130288409,2.5,6.07521666342531E-6,-0.00725778170115611,1.26133703388065E-6,299.9902039,299.9925842,-0.0891649797558785,-0.0891649797558785,56.3429101802367,19.6082395075353,26.3971481,0,0,0,4369,300.3098,-0.0891649797558785,,,,,,,,,,,,,,,,,54.480885,,,,,,299.99139405,,,,
,28216205.485,299.95910645,-0.0891649797558785,-0.00724296684927008,7.88337789504874E-7,1,0.999253354069792,40.0298881530762,1.99677174883977,7.53999646753073,-0.07984352371315,-0.0138651925650049,2.5,7.21185562626571E-6,-0.0072427670226161,2.40712610814923E-6,299.9583435,299.9598694,-0.0891649797558785,-0.0891649797558785,56.4515565444098,19.6099901660358,26.3971481,0,0,0,4369,300.26845,-0.0891649797558785,,,,,,,,,,,,,,,,,56.002121,,,,,,299.95910645,,,,
,28216210.43,299.95153805,-0.0891649797558785,-0.00723504796226687,3.55083714619904E-7,1,0.999253354069792,40.0298881530762,1.99678361255369,7.53999646753073,-0.0797551711805866,-0.0138589768252732,2.5,6.39848860159181E-6,-0.0072348500995804,1.60079988221613E-6,299.9512939,299.9517822,-0.0891649797558785,-0.0891649797558785,56.4836033136983,19.611842454865,25.88013935,0,0,0,4369,300.3616,-0.0891649797558785,,,,,,,,,,,,,,,,,56.002121,,,,,,299.95153805,,,,