File: sample-data/QD-PPMS.dat
[Header]
TITLE, default name
FILEOPENTIME,19270017.17,8/12/2014,12:48 PM
BYAPP, Resistivity, 2.1, 1.0
INFO, APPNAME, PPMS MultiVu Application, 1.5.11
INFO, Er_200nm, Sample1 Name
INFO, 1, Sample1 Cross Section
INFO, 1, Sample1 Length
INFO, Ohm, Sample1 Units
INFO, Er_5nm, Sample2 Name
INFO, 1, Sample2 Cross Section
INFO, 1, Sample2 Length
INFO, Ohm, Sample2 Units
INFO, Er_5nm, Sample3 Name
INFO, 1, Sample3 Cross Section
INFO, 1, Sample3 Length
INFO, Ohm, Sample3 Units
INFO, , Sample4 Name
INFO, 1, Sample4 Cross Section
INFO, 1, Sample4 Length
INFO, Ohm-m, Sample4 Units
FIELDGROUP, Resistivity,2,3,4,5,6,7,8,9,10,11,12,13,14,15,16,17,18,19,20,21,22,23,24,25,26,27,28,29,30,31,32,33,34,35,36,37,38,39,40,41
STARTUPGROUP, Resistivity
STARTUPAXIS, X, 2, LINEAR, AUTO
STARTUPAXIS, Y1, 7, LINEAR, AUTO
STARTUPAXIS, Y2, 9, LINEAR, AUTO
STARTUPAXIS, Y3, 11, LINEAR, AUTO
PLOT_APPEARANCE, ALL, HORZ_GRID_ON, VERT_GRID_ON, MARKERS_AND_LINES, ALL_LINES
DATATYPE, TIME, 2
DATATYPE, COMMENT, 1
[Data]
Comment,Time Stamp (sec),Status (code),Temperature (K),Magnetic Field (Oe),Sample Position (deg),Bridge 1 Resistivity (Ohm),Bridge 1 Excitation (uA),Bridge 2 Resistivity (Ohm),Bridge 2 Excitation (uA),Bridge 3 Resistivity (Ohm),Bridge 3 Excitation (uA),Bridge 4 Resistivity (Ohm-m),Bridge 4 Excitation (uA),Bridge 1 Std. Dev. (Ohm),Bridge 2 Std. Dev. (Ohm),Bridge 3 Std. Dev. (Ohm),Bridge 4 Std. Dev. (Ohm-m),Number of Readings,Bridge 1 Resistance (Ohms),Bridge 2 Resistance (Ohms),Bridge 3 Resistance (Ohms),Bridge 4 Resistance (Ohms),Signal 1 Vin (V),Signal 2 Vin (V),Digital Inputs (code),Drive 1 Iout (mA),Drive 1 Ipower (watts),Drive 2 Iout (mA),Drive 2 Ipower (watts),Pressure (),Map 20 (),Map 21 (),Map 22 (),Map 23 (),Map 24 (),Map 25 (),Map 26 (),Map 27 (),Map 28 (),Map 29 ()
,19270929.67,4370,200.008895874023,9999.712890625,0,0.892371401786804,99.9020004272461,11.6377216339111,99.9020004272461,9.23123027801514,99.9020004272461,,,0.000231871737928048,0.000908258839338647,0.000181909079269725,,25,0.892371401786804,11.6377216339111,9.23123027801514,
,19271136.72,4370,193.22265625,9999.712890625,0,0.878292028903961,99.9020004272461,11.4664265441895,99.9020004272461,9.10877285003662,99.9020004272461,,,0.00022812015775719,0.00213477780345731,0.00153380872713615,,25,0.878292028903961,11.4664265441895,9.10877285003662,
,19271340.19,4370,186.40340423584,9999.712890625,0,0.863131339550018,99.9020004272461,11.2700096511841,99.9020004272461,8.97770606994629,99.9020004272461,,,0.000301766368181767,0.00128859617761618,0.0016863994760859,,25,0.863131339550018,11.2700096511841,8.97770606994629,
,19271544.36,4370,179.597999572754,9999.712890625,0,0.848087501525879,99.9020004272461,11.1038820266724,99.9020004272461,8.84303112030029,99.9020004272461,,,0.000207589662594819,0.00117376815951317,0.00171382474247211,,25,0.848087501525879,11.1038820266724,8.84303112030029,
,19271748.52,4370,172.795799255371,9999.712890625,0,0.833023715019226,99.9020004272461,10.9403282928467,99.9020004272461,8.70629535675049,99.9020004272461,,,0.00024548688592984,0.00323324689216925,0.00176152854142675,,25,0.833023715019226,10.9403282928467,8.70629535675049,
,19271951.58,4370,166.020843505859,9999.712890625,0,0.81828916311264,99.9020004272461,10.7784392929077,99.9020004272461,8.56847248077393,99.9020004272461,,,0.000282465162487522,0.00254297185219086,0.00180038156389381,,25,0.81828916311264,10.7784392929077,8.56847248077393,
,19272161.78,4370,159.008399963379,9999.712890625,0,0.80307427406311,99.9020004272461,10.6005355834961,99.9020004272461,8.42407943725586,99.9020004272461,,,0.000268531677017573,0.00146469597754854,0.0018675751750062,,25,0.80307427406311,10.6005355834961,8.42407943725586,
,19272365.69,4370,152.216598510742,9999.712890625,0,0.78825031042099,99.9020004272461,10.4215085983276,99.9020004272461,8.28193862915039,99.9020004272461,,,0.000308512138390572,0.00167923387053207,0.00189360158000861,,25,0.78825031042099,10.4215085983276,8.28193862915039,
,19272570.86,4370,145.38655090332,9999.712890625,0,0.773502779006958,99.9020004272461,10.2508320617676,99.9020004272461,8.13652667999268,99.9020004272461,,,0.00029599521945669,0.00215024541749662,0.00192336981694211,,25,0.773502779006958,10.2508320617676,8.13652667999268,
,19272774.52,4370,138.595550537109,9999.712890625,0,0.758487088680267,99.9020004272461,10.0646920776367,99.9020004272461,7.98972650527954,99.9020004272461,,,0.000282752882173686,0.00208444572375339,0.00194588594568942,,25,0.758487088680267,10.0646920776367,7.98972650527954,
,19272978.25,4370,131.805000305176,9999.712890625,0,0.74334320306778,99.9020004272461,9.87688423156738,99.9020004272461,7.84005422592163,99.9020004272461,,,0.000283277057036327,0.00236938345301159,0.00193537256331202,,25,0.74334320306778,9.87688423156738,7.84005422592163,
,19273182.56,4370,124.993999481201,9999.712890625,0,0.727862546443939,99.9020004272461,9.6849817276001,99.9020004272461,7.68710708618164,99.9020004272461,,,0.000262108379073058,0.00256836406590906,0.00197693916693079,,25,0.727862546443939,9.6849817276001,7.68710708618164,
,19273392.30,4370,118.002048492432,9999.712890625,0,0.711829659938812,99.9020004272461,9.48991519927979,99.9020004272461,7.52759630203247,99.9020004272461,,,0.000336056817457404,0.00218724897803155,0.00201256101912291,,25,0.711829659938812,9.48991519927979,7.52759630203247,
,19273596.38,4370,111.20299911499,9999.712890625,0,0.696068716049194,99.9020004272461,9.29187931060791,99.9020004272461,7.37007160186768,99.9020004272461,,,0.00031702780033985,0.00234318231669829,0.00197669614393209,,25,0.696068716049194,9.29187931060791,7.37007160186768,
,19273799.67,4370,104.428150177002,9999.712890625,0,0.679960215091705,99.9020004272461,9.0920841217041,99.9020004272461,7.21003602981567,99.9020004272461,,,0.000265754612050447,0.00278311360160739,0.00208298224469183,,25,0.679960215091705,9.0920841217041,7.21003602981567,
,19274004.73,4370,97.6011505126953,9999.712890625,0,0.663569219112396,99.9020004272461,8.88639537811279,99.9020004272461,7.04559850692749,99.9020004272461,,,0.000261066004848812,0.00288221133775142,0.00218115038187527,,25,0.663569219112396,8.88639537811279,7.04559850692749,
,19274208.02,4370,90.8154983520508,9999.712890625,0,0.646871235370636,99.9020004272461,8.68097316741943,99.9020004272461,6.88062124252319,99.9020004272461,,,0.000216424166237772,0.00283131815842735,0.00220009697137928,,25,0.646871235370636,8.68097316741943,6.88062124252319,
,19274412.53,4370,84.0000991821289,9999.712890625,0,0.629820363521576,99.9020004272461,8.47140956878662,99.9020004272461,6.71224094390869,99.9020004272461,,,0.000310057713084886,0.00257333097958333,0.00216298629801687,,25,0.629820363521576,8.47140956878662,6.71224094390869,
,19274618.95,4370,77.1169509887695,9999.712890625,0,0.611520116329193,99.9020004272461,8.2579557800293,99.9020004272461,6.54081792831421,99.9020004272461,,,0.000423219531112005,0.00264275269469788,0.00214437497192621,,25,0.611520116329193,8.2579557800293,6.54081792831421,
,19274823.41,4370,70.2999992370605,9999.712890625,0,0.587809164524078,99.9020004272461,8.04519454956055,99.9020004272461,6.37099044799805,99.9020004272461,,,0.000458026140100982,0.00270849012674424,0.00217625568295308,,25,0.587809164524078,8.04519454956055,6.37099044799805,
,19275027.53,4370,63.4978504180908,9999.712890625,0,0.56018739938736,99.9020004272461,7.83256931304932,99.9020004272461,6.20370277404785,99.9020004272461,,,0.000420059907454358,0.00275826604088667,0.00215701086653471,,25,0.56018739938736,7.83256931304932,6.20370277404785,
,19275236.92,4370,56.5226497650146,9999.712890625,0,0.528910567760468,99.9020004272461,7.56075845718384,99.9020004272461,6.03659404754639,99.9020004272461,,,0.000462060481120237,0.00255311793924345,0.00204688182270329,,25,0.528910567760468,7.56075845718384,6.03659404754639,
,19275441.30,4370,49.7121486663818,9999.712890625,0,0.494609555006027,99.9020004272461,7.36930557250977,99.9020004272461,5.88121915817261,99.9020004272461,,,0.000487054188886241,0.00243727947993909,0.00186446920726768,,25,0.494609555006027,7.36930557250977,5.88121915817261,
,19275646.11,4370,42.8759002685547,9999.712890625,0,0.45506049990654,99.9020004272461,7.19168088912964,99.9020004272461,5.73799392700195,99.9020004272461,,,0.000567209700883529,0.0021469265848867,0.0017402627936918,,25,0.45506049990654,7.19168088912964,5.73799392700195,
,19275848.89,4370,36.1277503967285,9999.712890625,0,0.414385787248611,99.9020004272461,7.03690273284912,99.9020004272461,5.61383619308472,99.9020004272461,,,0.000585438165578124,0.00179065094432877,0.0014922822347923,,25,0.414385787248611,7.03690273284912,5.61383619308472,
,19276053.16,4370,29.3117504119873,9999.712890625,0,0.371193925142288,99.9020004272461,6.90947399139404,99.9020004272461,5.51275398254394,99.9020004272461,,,0.000671049496115083,0.00144078363173357,0.00116875528442434,,25,0.371193925142288,6.90947399139404,5.51275398254394,
,19276263.06,4370,22.327000617981,9999.712890625,0,0.324380688667297,99.9020004272461,6.81543607711792,99.9020004272461,5.43919984817505,99.9020004272461,,,0.000503010310332745,0.000966617997728138,0.000832830217756874,,25,0.324380688667297,6.81543607711792,5.43919984817505,
,19276466.52,4370,15.525399684906,9999.712890625,0,0.288805074691772,99.9020004272461,6.75962896347046,99.9020004272461,5.3966724395752,99.9020004272461,,,0.000482952574174559,0.000478901551783909,0.000391130752008833,,25,0.288805074691772,6.75962896347046,5.3966724395752,
,19276731.75,4375,9.19500017166138,9999.712890625,0,0.262014174461365,99.9020004272461,6.73406223297119,99.9020004272461,5.37755588531494,99.9020004272461,,,0.000218285728821159,0.000244763539967383,0.000246002905043884,,25,0.262014174461365,6.73406223297119,5.37755588531494,
,19277003.39,4375,7.45885014533997,9999.712890625,0,0.258954073190689,99.9020004272461,6.73067687988281,99.9020004272461,5.37441329956055,99.9020004272461,,,0.000392943071723759,0.000226573115877246,0.000170532492859882,,25,0.258954073190689,6.73067687988281,5.37441329956055,
,19278834.83,4370,198.446846008301,59999.703125,0,0.889555699825287,99.9020004272461,11.4670878601074,99.9020004272461,9.21078289031983,99.9020004272461,,,0.000249032145348287,0.00151720237211786,0.00117614794582443,,25,0.889555699825287,11.4670878601074,9.21078289031983,
,19279037.50,4370,191.194999694824,59999.703125,0,0.873579332828522,99.9020004272461,11.2954104995728,99.9020004272461,9.07181343078613,99.9020004272461,,,0.000285351874144551,0.00202655620785248,0.00159957945400126,,25,0.873579332828522,11.2954104995728,9.07181343078613,
,19279241.06,4370,184.394599914551,59999.703125,0,0.858414044380188,99.9020004272461,11.1314846038818,99.9020004272461,8.93915058135986,99.9020004272461,,,0.000258525491482311,0.00211148433726584,0.00174097423714278,,25,0.858414044380188,11.1314846038818,8.93915058135986,
,19279444.89,4370,177.586097717285,59999.703125,0,0.843098340034485,99.9020004272461,10.9604488754272,99.9020004272461,8.80372497558594,99.9020004272461,,,0.00039664397160278,0.00224858230356162,0.00175763262766965,,25,0.843098340034485,10.9604488754272,8.80372497558594,
,19279649.03,4370,170.788696289063,59999.703125,0,0.828101766109467,99.9020004272461,10.7947493362427,99.9020004272461,8.66662654876709,99.9020004272461,,,0.000264412465803185,0.00210245952168209,0.00179103512334791,,25,0.828101766109467,10.7947493362427,8.66662654876709,
,19279852.30,4370,164.022903442383,59999.703125,0,0.813237400054932,99.9020004272461,10.6221006011963,99.9020004272461,8.5284553527832,99.9020004272461,,,0.000258003920565202,0.00217508234813753,0.0017507615562298,,25,0.813237400054932,10.6221006011963,8.5284553527832,
,19280057.16,4370,157.187797546387,59999.703125,0,0.798270611763001,99.9020004272461,10.4433790206909,99.9020004272461,8.38693298339844,99.9020004272461,,,0.000280748992629815,0.00212221279300348,0.00181796748893408,,25,0.798270611763001,10.4433790206909,8.38693298339844,
,19280260.34,4370,150.420600891113,59999.703125,0,0.783448219299316,99.9020004272461,10.3145861434937,99.9020004272461,8.2446019744873,99.9020004272461,,,0.000260130142013636,0.001864902966608,0.00184569394304819,,25,0.783448219299316,10.3145861434937,8.2446019744873,
,19280464.81,4370,143.599647521973,59999.703125,0,0.768366978168488,99.9020004272461,10.1359775543213,99.9020004272461,8.09889080047607,99.9020004272461,,,0.000271951745169256,0.00215858626180946,0.00186695742965526,,25,0.768366978168488,10.1359775543213,8.09889080047607,
,19280669.27,4370,136.785743713379,59999.703125,0,0.752873249053955,99.9020004272461,9.95176895141602,99.9020004272461,7.95027086257935,99.9020004272461,,,0.00032106494918765,0.00233781288804536,0.00194002580795994,,25,0.752873249053955,9.95176895141602,7.95027086257935,
,19280873.30,4370,129.991096496582,59999.703125,0,0.737278764247894,99.9020004272461,9.7697163772583,99.9020004272461,7.79983848571777,99.9020004272461,,,0.000280700593633055,0.00267030791771285,0.0019306122188539,,25,0.737278764247894,9.7697163772583,7.79983848571777,
,19281077.25,4370,123.191650390625,59999.703125,0,0.721329894065857,99.9020004272461,9.58018035888672,99.9020004272461,7.64638828277588,99.9020004272461,,,0.000330028188394668,0.00272554691443671,0.00206977661861972,,25,0.721329894065857,9.58018035888672,7.64638828277588,
,19281281.23,4370,116.391948699951,59999.703125,0,0.705061848163605,99.9020004272461,9.38789443969727,99.9020004272461,7.49066211700439,99.9020004272461,,,0.000245427801623727,0.00247045576003161,0.00206094776914787,,25,0.705061848163605,9.38789443969727,7.49066211700439,
,19281491.38,4370,109.389198303223,59999.703125,0,0.687791891098022,99.9020004272461,9.18401119232178,99.9020004272461,7.32697160720825,99.9020004272461,,,0.000228801803024661,0.00268995018033927,0.00201682045972996,,25,0.687791891098022,9.18401119232178,7.32697160720825,
,19281701.17,4370,102.393997192383,59999.703125,0,0.669794795513153,99.9020004272461,8.98178497314453,99.9020004272461,7.16030870437622,99.9020004272461,,,0.000347192710150385,0.00276421433852748,0.002111682032988,,25,0.669794795513153,8.98178497314453,7.16030870437622,
,19281911.59,4370,95.3813972473145,59999.703125,0,0.650854635238648,99.9020004272461,8.76895210266113,99.9020004272461,6.99018487930298,99.9020004272461,,,0.000339357793666461,0.00265012488637168,0.00215241612208586,,25,0.650854635238648,8.76895210266113,6.99018487930298,
,19282114.47,4370,88.6150512695313,59999.703125,0,0.631191165447235,99.9020004272461,8.56176502227783,99.9020004272461,6.82314849853516,99.9020004272461,,,0.000299745372956877,0.00255799635457057,0.00212654050037962,,25,0.631191165447235,8.56176502227783,6.82314849853516,
,19282319.16,4370,81.7938499450684,59999.703125,0,0.609308481216431,99.9020004272461,8.34901519775391,99.9020004272461,6.65191963195801,99.9020004272461,,,0.000456902343367229,0.00272261521210074,0.00215442914366442,,25,0.609308481216431,8.34901519775391,6.65191963195801,
,19282523.09,4370,74.9971504211426,59999.703125,0,0.583940336704254,99.9020004272461,8.13619682312012,99.9020004272461,6.48080598831177,99.9020004272461,,,0.000483583006904803,0.00277276732772759,0.00224983782177775,,25,0.583940336704254,8.13619682312012,6.48080598831177,
,19282727.02,4370,68.2076530456543,59999.703125,0,0.553595974445343,99.9020004272461,7.92348913192749,99.9020004272461,6.30995597839356,99.9020004272461,,,0.000615504808665951,0.002671749184111,0.0021942344592936,,25,0.553595974445343,7.92348913192749,6.30995597839356,
,19282930.77,4370,61.4165992736816,59999.703125,0,0.517693524360657,99.9020004272461,7.69460723876953,99.9020004272461,6.14063386917114,99.9020004272461,,,0.000601629777802491,0.00259230361592631,0.002074726907101,,25,0.517693524360657,7.69460723876953,6.14063386917114,
,19283135.03,4370,54.608699798584,59999.703125,0,0.478995214700699,99.9020004272461,7.48951429367065,99.9020004272461,5.97600471496582,99.9020004272461,,,0.000503555228139066,0.00256602592681841,0.00201746553889016,,25,0.478995214700699,7.48951429367065,5.97600471496582,
,19283338.83,4370,47.8104496002197,59999.703125,0,0.439676022529602,99.9020004272461,7.29621187210083,99.9020004272461,5.82089870452881,99.9020004272461,,,0.00051250470837973,0.00230873623455732,0.00184785894451633,,25,0.439676022529602,7.29621187210083,5.82089870452881,
,19283543.11,4370,41.0030498504639,59999.703125,0,0.401196136474609,99.9020004272461,7.12038389205933,99.9020004272461,5.6802294921875,99.9020004272461,,,0.000505719779553498,0.0021759575667598,0.00174475488324788,,25,0.401196136474609,7.12038389205933,5.6802294921875,
,19283747.20,4370,34.1963996887207,59999.703125,0,0.364244384765625,99.9020004272461,6.97022361755371,99.9020004272461,5.56084405899048,99.9020004272461,,,0.000581522091663329,0.0017063028083168,0.00141611390693079,,25,0.364244384765625,6.97022361755371,5.56084405899048,
,19283951.25,4370,27.400899887085,59999.703125,0,0.324037781953812,99.9020004272461,6.85240682601929,99.9020004272461,5.4678472328186,99.9020004272461,,,0.000612832199355225,0.00135833714030542,0.000975148616476454,,25,0.324037781953812,6.85240682601929,5.4678472328186,
,19284154.55,4370,20.6111497879028,59999.703125,0,0.286604874134064,99.9020004272461,6.77060543060303,99.9020004272461,5.40387935638428,99.9020004272461,,,0.000508400143578908,0.000876521003568624,0.000704357688450509,,25,0.286604874134064,6.77060543060303,5.40387935638428,
,19284359.20,4370,13.7837500572205,59999.703125,0,0.257958974838257,99.9020004272461,6.72031232833862,99.9020004272461,5.36558815002441,99.9020004272461,,,0.000356577040183054,0.000527824650157696,0.000451584315683429,,25,0.257958974838257,6.72031232833862,5.36558815002441,
,19284663.52,4375,8.65659999847412,59999.703125,0,0.244893820285797,99.9020004272461,6.6975758934021,99.9020004272461,5.34861297607422,99.9020004272461,,,0.000229098036662425,0.000248462889380643,0.000209647889102573,,25,0.244893820285797,6.6975758934021,5.34861297607422,
,19285113.11,4374,6.58255004882813,59999.703125,0,0.242346928119659,99.9020004272461,6.69145030975342,99.9020004272461,5.34408355712891,99.9020004272461,,,0.000496312453410601,0.00083273728355748,0.00059111733508487,,25,0.242346928119659,6.69145030975342,5.34408355712891,
,19286396.30,4370,195.396499633789,49999.75390625,0,0.882997930049896,99.9020004272461,11.3959519958496,99.9020004272461,9.1531315612793,99.9020004272461,,,0.000351832196873311,0.00225539654136892,0.00176902804935161,,25,0.882997930049896,11.3959519958496,9.1531315612793,
,19286600.86,4370,188.624450683594,49999.75390625,0,0.867956318855286,99.9020004272461,11.2336085891724,99.9020004272461,9.02191432952881,99.9020004272461,,,0.000321850015912126,0.0021053507909689,0.00173895638622024,,25,0.867956318855286,11.2336085891724,9.02191432952881,
,19286806.64,4370,181.764450073242,49999.75390625,0,0.852471053600311,99.9020004272461,11.0665041351318,99.9020004272461,8.8866191482544,99.9020004272461,,,0.000281933055145925,0.00209505937809786,0.00170575626839076,,25,0.852471053600311,11.0665041351318,8.8866191482544,
,19287009.03,4370,175.009895324707,49999.75390625,0,0.837388186454773,99.9020004272461,10.8995658874512,99.9020004272461,8.75150714874268,99.9020004272461,,,0.000247013219990405,0.00220939617662033,0.00184945875247272,,25,0.837388186454773,10.8995658874512,8.75150714874268,
,19287213.48,4370,168.202453613281,49999.75390625,0,0.822463490962982,99.9020004272461,10.72894947052,99.9020004272461,8.61355037689209,99.9020004272461,,,0.00021123508188823,0.00211826642215444,0.00179512659897525,,25,0.822463490962982,10.72894947052,8.61355037689209,
,19287417.17,4370,161.416053771973,49999.75390625,0,0.807661731243134,99.9020004272461,10.5571354675293,99.9020004272461,8.47427658081055,99.9020004272461,,,0.000276499979678045,0.00223967828886965,0.00179287733365504,,25,0.807661731243134,10.5571354675293,8.47427658081055,
,19287620.64,4370,154.630447387695,49999.75390625,0,0.792897324562073,99.9020004272461,10.3847706985474,99.9020004272461,8.3331084060669,99.9020004272461,,,0.000264793788918789,0.00209257932588556,0.00185782682916481,,25,0.792897324562073,10.3847706985474,8.3331084060669,
,19287825.81,4370,147.793548583984,49999.75390625,0,0.777913036346435,99.9020004272461,10.208982925415,99.9020004272461,8.18860847473145,99.9020004272461,,,0.000288301656344715,0.00189832342849032,0.0019296572995257,,25,0.777913036346435,10.208982925415,8.18860847473145,
,19288029.63,4370,141.003898620605,49999.75390625,0,0.762821068763733,99.9020004272461,10.0293571090698,99.9020004272461,8.04239170074463,99.9020004272461,,,0.000283905798549859,0.00258076116611305,0.00188986123953042,,25,0.762821068763733,10.0293571090698,8.04239170074463,
,19288230.56,4370,134.301246643066,49999.75390625,0,0.747596931457519,99.9020004272461,9.84823028564453,99.9020004272461,7.89572996139526,99.9020004272461,,,0.000263789133583006,0.00229435939795279,0.00198173729471461,,25,0.747596931457519,9.84823028564453,7.89572996139526,
,19288435.08,4370,127.480949401855,49999.75390625,0,0.73198796749115,99.9020004272461,9.69712200164795,99.9020004272461,7.74333570480347,99.9020004272461,,,0.000277440612794666,0.00213781634818514,0.00198825860719195,,25,0.73198796749115,9.69712200164795,7.74333570480347,
,19288638.52,4370,120.707347869873,49999.75390625,0,0.716176538467407,99.9020004272461,9.52020904541016,99.9020004272461,7.58983352661133,99.9020004272461,,,0.000323843221027572,0.00221952002192733,0.00199860999305858,,25,0.716176538467407,9.52020904541016,7.58983352661133,
,19288853.97,4370,113.52379989624,49999.75390625,0,0.699039435386658,99.9020004272461,9.31395969390869,99.9020004272461,7.42401065826416,99.9020004272461,,,0.000320118079284144,0.00236144330450714,0.00204511129725554,,25,0.699039435386658,9.31395969390869,7.42401065826416,
,19289058.22,4370,106.708950042725,49999.75390625,0,0.682318472862244,99.9020004272461,9.11258979797363,99.9020004272461,7.26380641937256,99.9020004272461,,,0.000325672934850756,0.00299350300581741,0.00212250101158153,,25,0.682318472862244,9.11258979797363,7.26380641937256,
,19289262.30,4370,99.9128494262695,49999.75390625,0,0.664935472011566,99.9020004272461,8.90992000579834,99.9020004272461,7.10083436965942,99.9020004272461,,,0.000261317455797412,0.00251292814791952,0.00216143165786649,,25,0.664935472011566,8.90992000579834,7.10083436965942,
,19289467.06,4370,93.092098236084,49999.75390625,0,0.646746773719788,99.9020004272461,8.70503391265869,99.9020004272461,6.93468627929687,99.9020004272461,,,0.000327244669929654,0.00223970233962544,0.00215453720999488,,25,0.646746773719788,8.70503391265869,6.93468627929687,
,19289669.95,4370,86.3333511352539,49999.75390625,0,0.627421624660492,99.9020004272461,8.4961385345459,99.9020004272461,6.76668697357178,99.9020004272461,,,0.000350527597498731,0.00277384894415388,0.00215550013213502,,25,0.627421624660492,8.4961385345459,6.76668697357178,
,19289874.38,4370,79.5142021179199,49999.75390625,0,0.606156747341156,99.9020004272461,8.28335823059082,99.9020004272461,6.59601943969727,99.9020004272461,,,0.000391587395286284,0.00266332027787849,0.0021770202734661,,25,0.606156747341156,8.28335823059082,6.59601943969727,
,19290078.66,4370,72.705150604248,49999.75390625,0,0.581398046016693,99.9020004272461,8.07079029083252,99.9020004272461,6.42465677261353,99.9020004272461,,,0.000373994232739335,0.0028543402762819,0.00217161634457517,,25,0.581398046016693,8.07079029083252,6.42465677261353,
,19290282.89,4370,65.8900985717773,49999.75390625,0,0.550859682559967,99.9020004272461,7.85908142089844,99.9020004272461,6.25398384094238,99.9020004272461,,,0.000529805888444903,0.00273848073460896,0.00222141678683098,,25,0.550859682559967,7.85908142089844,6.25398384094238,
,19290486.22,4370,59.122501373291,49999.75390625,0,0.513596341609955,99.9020004272461,7.64945213317871,99.9020004272461,6.08666204452515,99.9020004272461,,,0.000524616468537917,0.00277099659238704,0.00209840199609249,,25,0.513596341609955,7.64945213317871,6.08666204452515,
,19290691.05,4370,52.2869510650635,49999.75390625,0,0.472451179027557,99.9020004272461,7.44607818603516,99.9020004272461,5.92394739151001,99.9020004272461,,,0.000514618790640337,0.00268433283724583,0.00201259737806158,,25,0.472451179027557,7.44607818603516,5.92394739151001,
,19290894.39,4370,45.5214500427246,49999.75390625,0,0.431788682937622,99.9020004272461,7.25853315353394,99.9020004272461,5.77378099441528,99.9020004272461,,,0.000589175495247182,0.00217977523745558,0.00188751540130687,,25,0.431788682937622,7.25853315353394,5.77378099441528,
,19291098.50,4370,38.7057514190674,49999.75390625,0,0.39264130115509,99.9020004272461,7.08931186676025,99.9020004272461,5.63932495117187,99.9020004272461,,,0.000499434746368264,0.00199885707733188,0.0015587928864265,,25,0.39264130115509,7.08931186676025,5.63932495117187,
,19291301.83,4370,31.9357500076294,49999.75390625,0,0.353115164041519,99.9020004272461,6.94879005432129,99.9020004272461,5.52862871170044,99.9020004272461,,,0.000497764926107673,0.00155441507612105,0.00128122832226985,,25,0.353115164041519,6.94879005432129,5.52862871170044,
,19291507.41,4370,25.0865001678467,49999.75390625,0,0.311915001869202,99.9020004272461,6.8418023109436,99.9020004272461,5.44480674743652,99.9020004272461,,,0.000540656794967718,0.00111688241677243,0.000877707307659896,,25,0.311915001869202,6.8418023109436,5.44480674743652,
,19291710.53,4370,18.3109998703003,49999.75390625,0,0.276505115032196,99.9020004272461,6.77139884948731,99.9020004272461,5.39065687179565,99.9020004272461,,,0.000404576426182202,0.000763992257448835,0.000597585776554674,,25,0.276505115032196,6.77139884948731,5.39065687179565,
,19291912.22,4370,11.599600315094,49999.75390625,0,0.251971663236618,99.9020004272461,6.73118394851685,99.9020004272461,5.36056158065796,99.9020004272461,,,0.000267983296728664,0.000442255258096891,0.000366152278882468,,25,0.251971663236618,6.73118394851685,5.36056158065796,
,19292211.53,4375,8.21420001983643,49999.75390625,0,0.244599807858467,99.9020004272461,6.71836336135864,99.9020004272461,5.35098648071289,99.9020004272461,,,0.000305629088009025,0.000282767425082254,0.000251909996502167,,25,0.244599807858467,6.71836336135864,5.35098648071289,
,19292654.92,4370,4.98889994621277,49999.75390625,0,0.241266326904297,99.9020004272461,6.70862483978271,99.9020004272461,5.34333362579346,99.9020004272461,,,0.000195450508151859,0.000204333711474258,0.000178880103107452,,25,0.241266326904297,6.70862483978271,5.34333362579346,
,19293866.17,4370,193.511154174805,39999.72265625,0,0.878657073974609,99.9020004272461,11.348676109314,99.9020004272461,9.11500747680664,99.9020004272461,,,0.000265248228342791,0.00194012568292848,0.00160235585486665,,25,0.878657073974609,11.348676109314,9.11500747680664,
,19294070.13,4370,186.711456298828,39999.72265625,0,0.863584971427917,99.9020004272461,11.1866296768188,99.9020004272461,8.98416290283203,99.9020004272461,,,0.000256442786582181,0.00205789319549027,0.00169391283435165,,25,0.863584971427917,11.1866296768188,8.98416290283203,
,19294274.28,4370,179.902549743652,39999.72265625,0,0.848449478149414,99.9020004272461,11.0201469802856,99.9020004272461,8.84941623687744,99.9020004272461,,,0.000304225072407871,0.00216339492755685,0.0016183398029765,,25,0.848449478149414,11.0201469802856,8.84941623687744,
,19294478.09,4370,173.105949401855,39999.72265625,0,0.833185620307922,99.9020004272461,10.8516017913818,99.9020004272461,8.71291202545166,99.9020004272461,,,0.000293544598639115,0.00211368334696317,0.00179927032155056,,25,0.833185620307922,10.8516017913818,8.71291202545166,
,19294682.08,4370,166.300994873047,39999.72265625,0,0.818304443359375,99.9020004272461,10.6804912948608,99.9020004272461,8.57447738647461,99.9020004272461,,,0.000312389475566022,0.00234438327248953,0.00174762361039592,,25,0.818304443359375,10.6804912948608,8.57447738647461,
,19294885.97,4370,159.508354187012,39999.72265625,0,0.803749361038208,99.9020004272461,10.5089322280884,99.9020004272461,8.43492446899414,99.9020004272461,,,0.000250037934459378,0.00230243674289031,0.00180656197199525,,25,0.803749361038208,10.5089322280884,8.43492446899414,
,19295090.22,4370,152.707405090332,39999.72265625,0,0.788794798851013,99.9020004272461,10.333688621521,99.9020004272461,8.29243751525879,99.9020004272461,,,0.000299780219879203,0.00231536809934896,0.00184957234999365,,25,0.788794798851013,10.333688621521,8.29243751525879,
,19295293.70,4370,145.919250488281,39999.72265625,0,0.77394951581955,99.9020004272461,10.1557571029663,99.9020004272461,8.14831253051758,99.9020004272461,,,0.000246645081488931,0.00227362278373478,0.00185807770155692,,25,0.77394951581955,10.1557571029663,8.14831253051758,
,19295497.94,4370,139.113349914551,39999.72265625,0,0.758793337345123,99.9020004272461,9.97307586669922,99.9020004272461,8.00101070404053,99.9020004272461,,,0.000324001575387961,0.00226405641100338,0.00186802830059856,,25,0.758793337345123,9.97307586669922,8.00101070404053,
,19295707.88,4370,132.118644714355,39999.72265625,0,0.7430415558815,99.9020004272461,9.78489772796631,99.9020004272461,7.84721448898315,99.9020004272461,,,0.000362128731524545,0.00238587147309041,0.00194104907045234,,25,0.7430415558815,9.78489772796631,7.84721448898315,
,19295911.88,4370,125.322853088379,39999.72265625,0,0.727434115409851,99.9020004272461,9.59746566772461,99.9020004272461,7.69457134246826,99.9020004272461,,,0.000341642760399609,0.00242376538587467,0.0019210882262877,,25,0.727434115409851,9.59746566772461,7.69457134246826,
,19296121.84,4370,118.317199707031,39999.72265625,0,0.71119428396225,99.9020004272461,9.40089920043945,99.9020004272461,7.53488409042358,99.9020004272461,,,0.000287015025060724,0.00253670228670782,0.00206693212970373,,25,0.71119428396225,9.40089920043945,7.53488409042358,
,19296325.81,4370,111.516849517822,39999.72265625,0,0.694987323284149,99.9020004272461,9.20698596954346,99.9020004272461,7.37723949432373,99.9020004272461,,,0.000309201612519734,0.0025162187364299,0.00201371702726169,,25,0.694987323284149,9.20698596954346,7.37723949432373,
,19296530.02,4370,104.714149475098,39999.72265625,0,0.678433601856232,99.9020004272461,9.01393920898438,99.9020004272461,7.216546459198,99.9020004272461,,,0.00024703805292223,0.00225973854677055,0.00212548350049905,,25,0.678433601856232,9.01393920898438,7.216546459198,
,19296734.75,4370,97.8873023986816,39999.72265625,0,0.661200265884399,99.9020004272461,8.82073066711426,99.9020004272461,7.05232809066773,99.9020004272461,,,0.000304857627320229,0.00221199881272634,0.00211321116801742,,25,0.661200265884399,8.82073066711426,7.05232809066773,
,19296939.02,4370,91.0837020874023,39999.72265625,0,0.643396399021149,99.9020004272461,8.61866706848144,99.9020004272461,6.8858517074585,99.9020004272461,,,0.000313260653011994,0.00297417473778075,0.00213686308902634,,25,0.643396399021149,8.61866706848144,6.8858517074585,
,19297143.03,4370,84.288200378418,39999.72265625,0,0.624469976425171,99.9020004272461,8.41420570373535,99.9020004272461,6.71661838531494,99.9020004272461,,,0.000338253891866042,0.00236245530212962,0.00227509749035702,,25,0.624469976425171,8.41420570373535,6.71661838531494,
,19297346.05,4370,77.5181503295898,39999.72265625,0,0.604228465557098,99.9020004272461,8.20643302917481,99.9020004272461,6.54699464797974,99.9020004272461,,,0.00041101388845142,0.0028134040602796,0.00225070399224376,,25,0.604228465557098,8.20643302917481,6.54699464797974,
,19297553.05,4370,70.6145515441895,39999.72265625,0,0.580497641563416,99.9020004272461,7.9938014793396,99.9020004272461,6.37427585601807,99.9020004272461,,,0.000308074584240826,0.00275950153848481,0.00218218461687202,,25,0.580497641563416,7.9938014793396,6.37427585601807,
,19297758.13,4370,63.7744998931885,39999.72265625,0,0.550581710338592,99.9020004272461,7.78101215362549,99.9020004272461,6.203740234375,99.9020004272461,,,0.000489650941687606,0.00303345004844181,0.00221545631582015,,25,0.550581710338592,7.78101215362549,6.203740234375,
,19297961.13,4370,57.0138492584229,39999.72265625,0,0.511780302524567,99.9020004272461,7.57516695022583,99.9020004272461,6.03816188812256,99.9020004272461,,,0.000576869692274593,0.00276827635860297,0.00209254458926923,,25,0.511780302524567,7.57516695022583,6.03816188812256,
,19298165.09,4370,50.2141494750977,39999.72265625,0,0.468082901239395,99.9020004272461,7.37472547531128,99.9020004272461,5.8789800453186,99.9020004272461,,,0.000603380762729879,0.00249150889032503,0.00198410620438038,,25,0.468082901239395,7.37472547531128,5.8789800453186,
,19298369.42,4370,43.4012489318848,39999.72265625,0,0.425529501438141,99.9020004272461,7.1893928527832,99.9020004272461,5.73263282775879,99.9020004272461,,,0.00066896729596331,0.00222817975177562,0.00182724033826512,,25,0.425529501438141,7.1893928527832,5.73263282775879,
,19298573.58,4370,36.6081504821777,39999.72265625,0,0.384518744945526,99.9020004272461,7.02864637374878,99.9020004272461,5.60460168838501,99.9020004272461,,,0.000622493884918842,0.00176522652548568,0.00146312111092159,,25,0.384518744945526,7.02864637374878,5.60460168838501,
,19298776.95,4370,29.8221502304077,39999.72265625,0,0.342073764801025,99.9020004272461,6.89919633865356,99.9020004272461,5.50179891586304,99.9020004272461,,,0.000567819262829362,0.00141628701198316,0.00118305725694423,,25,0.342073764801025,6.89919633865356,5.50179891586304,
,19298981.59,4370,23.0077991485596,39999.72265625,0,0.301400564908981,99.9020004272461,6.80328125,99.9020004272461,5.42753219604492,99.9020004272461,,,0.00055489546819013,0.000984984279064043,0.000747153803638789,,25,0.301400564908981,6.80328125,5.42753219604492,
,19299185.16,4370,16.2201499938965,39999.72265625,0,0.268546743392944,99.9020004272461,6.74316310882568,99.9020004272461,5.38172557830811,99.9020004272461,,,0.000413622291706661,0.000699147975710953,0.000422935798062535,,25,0.268546743392944,6.74316310882568,5.38172557830811,
,19299388.80,4375,9.39919996261597,39999.72265625,0,0.247530832886696,99.9020004272461,6.71069747924805,99.9020004272461,5.35781538009644,99.9020004272461,,,0.000555480709669639,0.000983388333257573,0.000469252737582282,,25,0.247530832886696,6.71069747924805,5.35781538009644,
,19299720.73,4375,7.57680010795593,39999.72265625,0,0.244202684164047,99.9020004272461,6.70464296340942,99.9020004272461,5.35346845626831,99.9020004272461,,,0.000279315953884186,0.00024099333582534,0.000196422781832995,,25,0.244202684164047,6.70464296340942,5.35346845626831,
,19301227.00,4370,198.414703369141,29999.619140625,0,0.88961984872818,99.9020004272461,11.4660317230225,99.9020004272461,9.21013061523437,99.9020004272461,,,0.00030243673713349,0.00194874060729019,0.00152514416264166,,25,0.88961984872818,11.4660317230225,9.21013061523437,
,19301431.31,4370,191.58519744873,29999.619140625,0,0.874491944313049,99.9020004272461,11.3037302017212,99.9020004272461,9.0787585067749,99.9020004272461,,,0.000298699328424941,0.00203671503164136,0.00165810330631149,,25,0.874491944313049,11.3037302017212,9.0787585067749,
,19301634.88,4370,184.785049438477,29999.619140625,0,0.859296865463257,99.9020004272461,11.1396880722046,99.9020004272461,8.94609710693359,99.9020004272461,,,0.000308930509643188,0.00219638347897477,0.0017228825954783,,25,0.859296865463257,11.1396880722046,8.94609710693359,
,19301838.91,4370,177.983200073242,29999.619140625,0,0.8441552734375,99.9020004272461,10.9728992843628,99.9020004272461,8.81084785461426,99.9020004272461,,,0.000301952344175635,0.00222498134332237,0.0018226875050551,,25,0.8441552734375,10.9728992843628,8.81084785461426,
,19302041.89,4370,171.218849182129,29999.619140625,0,0.829126651287079,99.9020004272461,10.8042151641846,99.9020004272461,8.67447353363037,99.9020004272461,,,0.000267725999754162,0.00216822382830602,0.00182637696564102,,25,0.829126651287079,10.8042151641846,8.67447353363037,
,19302246.59,4370,164.401298522949,29999.619140625,0,0.81434779882431,99.9020004272461,10.6237884140015,99.9020004272461,8.53551033020019,99.9020004272461,,,0.000232834290952725,0.00252979622440696,0.0017724293058022,,25,0.81434779882431,10.6237884140015,8.53551033020019,
,19302451.03,4370,157.588645935059,29999.619140625,0,0.799556651115418,99.9020004272461,10.4369091033936,99.9020004272461,8.39457134246826,99.9020004272461,,,0.000334431362353887,0.00224353298302887,0.00182693649386039,,25,0.799556651115418,10.4369091033936,8.39457134246826,
,19302654.06,4370,150.816955566406,29999.619140625,0,0.784790802001953,99.9020004272461,10.268076133728,99.9020004272461,8.25231826782227,99.9020004272461,,,0.000341991441334315,0.00232557834425048,0.00190685075356339,,25,0.784790802001953,10.268076133728,8.25231826782227,
,19302858.73,4370,143.996002197266,29999.619140625,0,0.769911911487579,99.9020004272461,10.0867237472534,99.9020004272461,8.10678882598877,99.9020004272461,,,0.000242373209103036,0.00235100856159361,0.00182095847974951,,25,0.769911911487579,10.0867237472534,8.10678882598877,
,19303064.92,4370,137.129402160645,29999.619140625,0,0.754542675018311,99.9020004272461,9.90292137145996,99.9020004272461,7.95748077392578,99.9020004272461,,,0.000256807283837162,0.00253452869662806,0.00197268384201911,,25,0.754542675018311,9.90292137145996,7.95748077392578,
,19303269.66,4370,130.298400878906,29999.619140625,0,0.739233045578003,99.9020004272461,9.71874881744385,99.9020004272461,7.80628940582275,99.9020004272461,,,0.000282748643116057,0.00235938290757824,0.00200745856235575,,25,0.739233045578003,9.71874881744385,7.80628940582275,
,19303472.94,4370,123.52449798584,29999.619140625,0,0.723682878017426,99.9020004272461,9.53357814788818,99.9020004272461,7.65372577667236,99.9020004272461,,,0.000298816362740074,0.00233935160180664,0.00211415619345448,,25,0.723682878017426,9.53357814788818,7.65372577667236,
,19303677.47,4370,116.703147888184,29999.619140625,0,0.707921104431152,99.9020004272461,9.35342769622803,99.9020004272461,7.49772085189819,99.9020004272461,,,0.000254111433398623,0.0024689228747601,0.00194665319452467,,25,0.707921104431152,9.35342769622803,7.49772085189819,
,19303881.48,4370,109.907199859619,29999.619140625,0,0.691778316497803,99.9020004272461,9.15112007141113,99.9020004272461,7.33928066253662,99.9020004272461,,,0.000304934630949016,0.00250344547152893,0.00198060025958153,,25,0.691778316497803,9.15112007141113,7.33928066253662,
,19304085.08,4370,103.112251281738,29999.619140625,0,0.675377330780029,99.9020004272461,8.95552635192871,99.9020004272461,7.17835609436035,99.9020004272461,,,0.00025761318778058,0.00249011288306089,0.00210300274074422,,25,0.675377330780029,8.95552635192871,7.17835609436035,
,19304289.97,4370,96.2929496765137,29999.619140625,0,0.658462469577789,99.9020004272461,8.75857116699219,99.9020004272461,7.01347423553467,99.9020004272461,,,0.000290011838693604,0.00259896562486875,0.00209191399906186,,25,0.658462469577789,8.75857116699219,7.01347423553467,
,19304493.92,4370,89.4937477111816,29999.619140625,0,0.641002240180969,99.9020004272461,8.55135131835937,99.9020004272461,6.84731527328491,99.9020004272461,,,0.000334240978292745,0.00205233482258288,0.00205369211643099,,25,0.641002240180969,8.55135131835937,6.84731527328491,
,19304697.73,4370,82.6991500854492,29999.619140625,0,0.62267914056778,99.9020004272461,8.34587409973144,99.9020004272461,6.67816679000854,99.9020004272461,,,0.000343317153151771,0.00337445780360616,0.00220903968434759,,25,0.62267914056778,8.34587409973144,6.67816679000854,
,19304902.00,4370,75.8908500671387,29999.619140625,0,0.603267736434936,99.9020004272461,8.14012516021729,99.9020004272461,6.50786563873291,99.9020004272461,,,0.000247336520204323,0.00235390229680201,0.00220377592225441,,25,0.603267736434936,8.14012516021729,6.50786563873291,
,19305111.50,4370,68.9067497253418,29999.619140625,0,0.581295697689056,99.9020004272461,7.94143350601196,99.9020004272461,6.33338125228882,99.9020004272461,,,0.000284920833420746,0.00303611536918007,0.00221155137264972,,25,0.581295697689056,7.94143350601196,6.33338125228882,
,19305315.92,4370,62.0982513427734,29999.619140625,0,0.553016350269318,99.9020004272461,7.74947341918945,99.9020004272461,6.16460363388062,99.9020004272461,,,0.000506234402113269,0.00292388802025647,0.00212074476654937,,25,0.553016350269318,7.74947341918945,6.16460363388062,
,19305520.23,4370,55.3008499145508,29999.619140625,0,0.514876282215118,99.9020004272461,7.54744440078735,99.9020004272461,5.99990737915039,99.9020004272461,,,0.000601894034297327,0.00203458435601891,0.00206244419050714,,25,0.514876282215118,7.54744440078735,5.99990737915039,
,19305723.81,4370,48.5009498596191,29999.619140625,0,0.471058995723724,99.9020004272461,7.3533352470398,99.9020004272461,5.8437068939209,99.9020004272461,,,0.000542653150412995,0.00274905162017538,0.00190894912274806,,25,0.471058995723724,7.3533352470398,5.8437068939209,
,19305927.53,4370,41.7047996520996,29999.619140625,0,0.426313037872314,99.9020004272461,7.17703947067261,99.9020004272461,5.70152870178223,99.9020004272461,,,0.000629099416203201,0.00266825813675555,0.00173386023065729,,25,0.426313037872314,7.17703947067261,5.70152870178223,
,19306132.36,4370,34.8752994537354,29999.619140625,0,0.380167989730835,99.9020004272461,7.02460187911987,99.9020004272461,5.57856386184692,99.9020004272461,,,0.000577898003371287,0.00192353039046729,0.0014375880748281,,25,0.380167989730835,7.02460187911987,5.57856386184692,
,19306335.75,4370,28.0908002853394,29999.619140625,0,0.333918353319168,99.9020004272461,6.90314611434937,99.9020004272461,5.48251586914062,99.9020004272461,,,0.000654772900061825,0.00123732980462201,0.00110947766851252,,25,0.333918353319168,6.90314611434937,5.48251586914062,
,19306539.83,4370,21.2968492507935,29999.619140625,0,0.293719398975372,99.9020004272461,6.81700773239136,99.9020004272461,5.41589668273926,99.9020004272461,,,0.000586953930059209,0.000881426026249783,0.000755533427743576,,25,0.293719398975372,6.81700773239136,5.41589668273926,
,19306743.80,4370,14.5015997886658,29999.619140625,0,0.262718274593353,99.9020004272461,6.76469442367554,99.9020004272461,5.37669368743896,99.9020004272461,,,0.000363585432621028,0.00051374626757903,0.000375788580990923,,25,0.262718274593353,6.76469442367554,5.37669368743896,
,19307046.53,4375,8.82635021209717,29999.619140625,0,0.246830532550812,99.9020004272461,6.74168306350708,99.9020004272461,5.35990940093994,99.9020004272461,,,0.000179176427638591,0.000226088549678649,0.000228335817671935,,25,0.246830532550812,6.74168306350708,5.35990940093994,
,19307323.66,4375,7.07714986801147,29999.619140625,0,0.244062163233757,99.9020004272461,6.73724603652954,99.9020004272461,5.35671489715576,99.9020004272461,,,0.000283745533372077,0.000224674504181614,0.000204947786688768,,25,0.244062163233757,6.73724603652954,5.35671489715576,
,19308753.03,4370,195.367546081543,19999.732421875,0,0.882893304824829,99.9020004272461,11.393649597168,99.9020004272461,9.15163082122803,99.9020004272461,,,0.000358424344731135,0.00194893645478082,0.00158010070513754,,25,0.882893304824829,11.393649597168,9.15163082122803,
,19308967.41,4370,188.315948486328,19999.732421875,0,0.867144508361816,99.9020004272461,11.2248138809204,99.9020004272461,9.01490291595459,99.9020004272461,,,0.00025007113665178,0.00216658403935353,0.0017526671475206,,25,0.867144508361816,11.2248138809204,9.01490291595459,
,19309171.28,4370,181.517547607422,19999.732421875,0,0.851948668956757,99.9020004272461,11.0591948699951,99.9020004272461,8.88107021331787,99.9020004272461,,,0.000263882911686169,0.00219760141550652,0.00168032913274235,,25,0.851948668956757,11.0591948699951,8.88107021331787,
,19309375.77,4370,174.694999694824,19999.732421875,0,0.836800935268402,99.9020004272461,10.890862159729,99.9020004272461,8.74480125427246,99.9020004272461,,,0.000292409671167105,0.00214700193444905,0.00163513780839154,,25,0.836800935268402,10.890862159729,8.74480125427246,
,19309579.88,4370,167.895851135254,19999.732421875,0,0.821992287635803,99.9020004272461,10.7208122253418,99.9020004272461,8.6067077255249,99.9020004272461,,,0.000250223077411797,0.00223275084417944,0.00182737767302095,,25,0.821992287635803,10.7208122253418,8.6067077255249,
,19309783.23,4370,161.114295959473,19999.732421875,0,0.807295918464661,99.9020004272461,10.5454349899292,99.9020004272461,8.46766368865967,99.9020004272461,,,0.000307861309830461,0.00207554343701602,0.00180296743654735,,25,0.807295918464661,10.5454349899292,8.46766368865967,
,19309987.67,4370,154.302299499512,19999.732421875,0,0.792500202655792,99.9020004272461,10.3718011474609,99.9020004272461,8.32565032958984,99.9020004272461,,,0.00025172392939699,0.00246833230135683,0.00185235058002592,,25,0.792500202655792,10.3718011474609,8.32565032958984,
,19310197.69,4370,147.294654846191,19999.732421875,0,0.777319660186768,99.9020004272461,10.1900206375122,99.9020004272461,8.17715702056885,99.9020004272461,,,0.000301311811223777,0.00230918373498825,0.0018263342946924,,25,0.777319660186768,10.1900206375122,8.17715702056885,
,19310401.83,4370,140.500747680664,19999.732421875,0,0.762281877994537,99.9020004272461,10.0097121429443,99.9020004272461,8.03085163116455,99.9020004272461,,,0.000348651157185356,0.00243402056658892,0.00195085060838222,,25,0.762281877994537,10.0097121429443,8.03085163116455,
,19310604.94,4370,133.730697631836,19999.732421875,0,0.747172346115112,99.9020004272461,9.82693778991699,99.9020004272461,7.88225622177124,99.9020004272461,,,0.000273475602531522,0.00234599045874697,0.0019612115662607,,25,0.747172346115112,9.82693778991699,7.88225622177124,
,19310808.91,4370,126.922100067139,19999.732421875,0,0.731769552230835,99.9020004272461,9.63983413696289,99.9020004272461,7.73046915054321,99.9020004272461,,,0.000320158904812239,0.00236400063311063,0.00198323075826413,,25,0.731769552230835,9.63983413696289,7.73046915054321,
,19311013.72,4370,120.094650268555,19999.732421875,0,0.716106286048889,99.9020004272461,9.44933753967285,99.9020004272461,7.57563739776611,99.9020004272461,,,0.000346348598871991,0.00244808637612492,0.00197285904369132,,25,0.716106286048889,9.44933753967285,7.57563739776611,
,19311217.78,4370,113.298202514648,19999.732421875,0,0.700309450626373,99.9020004272461,9.25793270111084,99.9020004272461,7.41854427337647,99.9020004272461,,,0.000225966646725303,0.0024609089216465,0.00208961849061912,,25,0.700309450626373,9.25793270111084,7.41854427337647,
,19311422.27,4370,106.485050201416,19999.732421875,0,0.684184951782227,99.9020004272461,9.06093097686768,99.9020004272461,7.25855762481689,99.9020004272461,,,0.000261986094481172,0.0024612332356281,0.00209869031231649,,25,0.684184951782227,9.06093097686768,7.25855762481689,
,19311625.84,4370,99.6994514465332,19999.732421875,0,0.667829055786133,99.9020004272461,8.86168643951416,99.9020004272461,7.09640726089478,99.9020004272461,,,0.000326097832579345,0.00261005465074704,0.00209103684132696,,25,0.667829055786133,8.86168643951416,7.09640726089478,
,19311829.38,4370,92.9163970947266,19999.732421875,0,0.650970704555511,99.9020004272461,8.65931575775146,99.9020004272461,6.93141008377075,99.9020004272461,,,0.00028026363056941,0.00260733862916864,0.0021358974617126,,25,0.650970704555511,8.65931575775146,6.93141008377075,
,19312033.95,4370,86.096851348877,19999.732421875,0,0.633611297607422,99.9020004272461,8.45354923248291,99.9020004272461,6.7637314414978,99.9020004272461,,,0.000311592710874562,0.00251608264288747,0.00216788870204959,,25,0.633611297607422,8.45354923248291,6.7637314414978,
,19312238.16,4370,79.2910995483398,19999.732421875,0,0.615698266029358,99.9020004272461,8.24799041748047,99.9020004272461,6.59404460906982,99.9020004272461,,,0.000323463142492909,0.00286848101738782,0.00219442725966424,,25,0.615698266029358,8.24799041748047,6.59404460906982,
,19312442.14,4370,72.4885482788086,19999.732421875,0,0.596122663021088,99.9020004272461,8.03826717376709,99.9020004272461,6.42410459518433,99.9020004272461,,,0.00034707436272663,0.00264085817078909,0.00218637982635844,,25,0.596122663021088,8.03826717376709,6.42410459518433,
,19312645.91,4370,65.7002983093262,19999.732421875,0,0.570377259254456,99.9020004272461,7.83371793746948,99.9020004272461,6.25595268249512,99.9020004272461,,,0.0003664053432939,0.00311295367595329,0.00218379214292764,,25,0.570377259254456,7.83371793746948,6.25595268249512,
,19312850.17,4370,58.8980503082275,19999.732421875,0,0.540679008960724,99.9020004272461,7.62874715805054,99.9020004272461,6.08953269958496,99.9020004272461,,,0.000446515973110406,0.0022306826636037,0.00204993132955063,,25,0.540679008960724,7.62874715805054,6.08953269958496,
,19313052.78,4370,52.1286010742188,19999.732421875,0,0.506299328804016,99.9020004272461,7.4317727470398,99.9020004272461,5.93019203186035,99.9020004272461,,,0.000559934465669019,0.00256995235332984,0.0020416699756508,,25,0.506299328804016,7.4317727470398,5.93019203186035,
,19313257.47,4370,45.3050498962402,19999.732421875,0,0.463589371442795,99.9020004272461,7.24452796936035,99.9020004272461,5.77960632324219,99.9020004272461,,,0.000605357188691945,0.00233289945549292,0.00189043918815601,,25,0.463589371442795,7.24452796936035,5.77960632324219,
,19313461.73,4370,38.5041007995605,19999.732421875,0,0.419303907155991,99.9020004272461,7.07534101486206,99.9020004272461,5.64514122009277,99.9020004272461,,,0.000641567806488586,0.0020917208212265,0.00158511665318864,,25,0.419303907155991,7.07534101486206,5.64514122009277,
,19313665.98,4370,31.6957998275757,19999.732421875,0,0.374033298492432,99.9020004272461,6.93461608886719,99.9020004272461,5.53381954193115,99.9020004272461,,,0.000652377534080908,0.00169834483268523,0.00119123119711584,,25,0.374033298492432,6.93461608886719,5.53381954193115,
,19313869.98,4370,24.9091501235962,19999.732421875,0,0.328832205533981,99.9020004272461,6.82927556991577,99.9020004272461,5.45082612991333,99.9020004272461,,,0.000555032628001348,0.00115878777383816,0.000874882831689034,,25,0.328832205533981,6.82927556991577,5.45082612991333,
,19314074.08,4370,18.1014499664307,19999.732421875,0,0.289319031238556,99.9020004272461,6.75983821868897,99.9020004272461,5.39758354187012,99.9020004272461,,,0.000479769745850715,0.00078573559767027,0.000569269961133121,,25,0.289319031238556,6.75983821868897,5.39758354187012,
,19314280.94,4370,11.2050499916077,19999.732421875,0,0.261692645549774,99.9020004272461,6.72175947189331,99.9020004272461,5.36931491851807,99.9020004272461,,,0.000293848574394141,0.000448912982603767,0.000385820285514397,,25,0.261692645549774,6.72175947189331,5.36931491851807,
,19314596.17,4375,8.06969976425171,19999.732421875,0,0.254311624765396,99.9020004272461,6.71261203765869,99.9020004272461,5.36272514343262,99.9020004272461,,,0.000221138488566862,0.000286317659818981,0.000231113810812243,,25,0.254311624765396,6.71261203765869,5.36272514343262,
,19315047.13,4370,4.98484992980957,19999.732421875,0,0.250929250717163,99.9020004272461,6.70679048538208,99.9020004272461,5.35602912902832,99.9020004272461,,,0.000215899028715067,0.000224404086349347,0.000208955029895355,,25,0.250929250717163,6.70679048538208,5.35602912902832,