File: sample-data/QD-SQUID-VSM.dat
[Header]
; SQUID VSM Data File (default extension .dat)
; Copyright (c) 2007, Quantum Design, Inc. All rights reserved.
TITLE,
FILEOPENTIME,3540392668.062,03/08/2012,6:24 pm
BYAPP,SQUID AC,0.9.1.0
INFO,SQUID VSM Measurement Release 1.1.7 Build 37,APPNAME
INFO,0,MOMENT_UNITS
INFO,FeNi,SAMPLE_MATERIAL
INFO,Penrose lattice,SAMPLE_COMMENT
INFO,1,SAMPLE_MASS
INFO,,SAMPLE_VOLUME
INFO,,SAMPLE_MOLECULAR_WEIGHT
INFO,,SAMPLE_SIZE
INFO,,SAMPLE_SHAPE
INFO,Quartz,SAMPLE_HOLDER
INFO,65.55,SAMPLE_OFFSET
DATATYPE,COMMENT,1
DATATYPE,TIME,2
STARTUPAXIS,X,2
STARTUPAXIS,Y1,5
[Data]
Comment,Time Stamp (sec),Temperature (K),Magnetic Field (Oe),Moment (emu),M. Std. Err. (emu),Transport Action,Averaging Time (sec),Frequency (Hz),Peak Amplitude (mm),Center Position (mm),Lockin Signal' (V),Lockin Signal" (V),Range,M. Quad. Signal (emu),M. Raw' (emu),M. Raw" (emu),AC Moment (emu),AC M. Std Err. (emu),AC Phase (deg),AC Phase Std. Err.(deg),AC Susceptibility (emu/Oe),AC Suscept. Std Err. (emu/Oe),AC X' (emu/Oe),AC X' Std Err. (emu/Oe),AC X'' (emu/Oe),AC X'' Std Err. (emu/Oe),AC Drive (Oe),AC Frequency (Hz),AC Averaging Time (sec),AC Cycles,AC Range,AC Measure Type,AC Signal' (V),AC Signal'' (V),AC Trim Coil Ratio,AC Trim Coil Phase,Min. Temperature (K),Max. Temperature (K),Min. Field (Oe),Max. Field (Oe),Mass (grams),Motor Lag (deg),Pressure (Torr),Measure Count,Measurement Number,SQUID Status (code),Motor Status (code),Measure Status (code),Motor Current (amps),Motor Temp. (C),Temp. Status (code),Field Status (code),Chamber Status (code),Chamber Temp (K),Redirection State,Map 01,Map 02,Map 03,Map 04,Map 05,Map 06,Map 07,Map 08,Map 09,Map 10,Map 11,Map 12,Map 13,Map 14,Map 15,Map 16
,3540392694.757,300.170120239258,-0.0127035938203335,-5.83112565852534E-6,9.94637144860301E-9,1,1,13.9012460708618,7.97201451426939,32.5399996340275,-0.0116221944583298,-0.00174627571742401,1,1.86306659786261E-8,-5.83112565852534E-6,1.86306659786261E-8,,,,,,,,,,,,,,,,,,,,,300.169342041016,300.1708984375,-0.0127035938203335,-0.0127035938203335,52.3624669460536,5.67370149219273,6.65090703964233,14,1,0,0,0,0.499343872070313,30.3030319213867,1,1,1,300.1708984375,0,,,,,,,,,,,,,,,,
,3540392721.937,300.287170410156,1.13061988353729,-5.8201045325249E-6,1.07142611311115E-8,1,1,13.9012460708618,7.98168503788632,32.5399996340275,-0.0116077986510121,-0.00174736852145245,1,1.69990870985177E-8,-5.8201045325249E-6,1.69990870985177E-8,,,,,,,,,,,,,,,,,,,,,300.285522460937,300.288818359375,1.13061988353729,1.13061988353729,52.4035024433132,5.67516255164104,6.64917707443237,14,1,0,0,0,0.497360229492188,31.2805480957031,1,1,1,300.285522460937,0,,,,,,,,,,,,,,,,
,3540392747.187,300.206939697266,1.82931756973267,-5.80700034062631E-6,1.00331727789036E-8,1,1,13.9012460708618,7.98166315491031,32.5399996340275,-0.0115817066492421,-0.00174303060975811,1,1.71619195016678E-8,-5.80700034062631E-6,1.71619195016678E-8,,,,,,,,,,,,,,,,,,,,,300.205871582031,300.2080078125,1.82931756973267,1.82931756973267,52.4480552689094,5.67513946431591,6.65531015396118,14,1,0,0,0,0.500717163085937,32.2580642700195,1,1,1,300.205871582031,0,,,,,,,,,,,,,,,,
,3540392773.422,300.137313842773,2.47720074653626,-5.81653746063446E-6,1.32712715122543E-8,1,1,13.9012460708618,7.98170004801549,32.5399996340275,-0.0115989849741085,-0.00175745002339298,1,1.13953172990948E-8,-5.81653746063446E-6,1.13953172990948E-8,,,,,,,,,,,,,,,,,,,,,300.136688232422,300.137939453125,2.47720074653626,2.47720074653626,52.4109279142459,5.67558912683474,6.64881706237793,14,1,0,0,0,0.501327514648438,32.2580642700195,1,1,1,300.136688232422,0,,,,,,,,,,,,,,,,
,3540392799.906,300.074615478516,3.2902307510376,-5.81330728102663E-6,9.13512940607662E-9,1,1,13.9012460708618,7.98172351070348,32.5399996340275,-0.0115947964857395,-0.00174192879059522,1,1.86866463936835E-8,-5.81330728102663E-6,1.86866463936835E-8,,,,,,,,,,,,,,,,,,,,,300.070526123047,300.078704833984,3.2902307510376,3.2902307510376,52.3655934601305,5.67558786735972,6.65207386016846,14,1,0,0,0,0.49774169921875,32.7468223571777,1,1,1,300.070526123047,0,,,,,,,,,,,,,,,,
,3540392833.266,299.870910644531,4.76384735107422,-5.80786352643485E-6,1.16492416770369E-8,1,1,13.9012460708618,7.98182757936227,32.5399996340275,-0.0115848819956317,-0.00173472867946234,1,2.14691063366543E-8,-5.80786352643485E-6,2.14691063366543E-8,,,,,,,,,,,,,,,,,,,,,299.863708496094,299.878112792969,4.76384735107422,4.76384735107422,52.5363792915825,5.67524790571926,6.65637397766113,14,1,0,0,0,0.499725341796875,33.2355842590332,1,1,1,299.863708496094,0,,,,,,,,,,,,,,,,
,3540392866.984,299.737976074219,6.58046150207519,-5.80447577609104E-6,9.98008058134979E-9,1,1,13.9012460708618,7.98176801343261,32.5499983131886,-0.0115755694722655,-0.00175003053743673,1,1.32696155811236E-8,-5.80447577609104E-6,1.32696155811236E-8,,,,,,,,,,,,,,,,,,,,,299.733917236328,299.742034912109,6.58046150207519,6.58046150207519,52.4386757266786,5.67547958433749,6.65488338470459,14,1,0,0,0,0.49774169921875,33.2355842590332,1,1,1,299.733917236328,0,,,,,,,,,,,,,,,,
,3540392912.062,299.577392578125,9.09577369689941,-5.79350387929279E-6,1.08611692915982E-8,1,1,13.9012460708618,7.98181045933348,32.5399996340275,-0.0115559888448493,-0.00173197450619576,1,2.06450530233733E-8,-5.79350387929279E-6,2.06450530233733E-8,,,,,,,,,,,,,,,,,,,,,299.577026367188,299.577758789063,9.09577369689941,9.09577369689941,52.4617337679959,5.6758457340211,6.66781234741211,14,1,0,0,0,0.497589111328125,33.7243423461914,1,1,1,299.577758789063,0,,,,,,,,,,,,,,,,
,3540393026.734,299.979843139648,12.5257434844971,-5.77852923052791E-6,1.07822554424531E-8,1,1,13.9012460708618,7.98180046827894,32.5399996340275,-0.0115240987152696,-0.00174060716180841,1,1.40152051783411E-8,-5.77852923052791E-6,1.40152051783411E-8,,,,,,,,,,,,,,,,,,,,,299.969177246094,299.990509033203,12.5257434844971,12.5257434844971,52.4742398243036,5.67581631468274,6.6531982421875,14,1,0,0,0,0.4974365234375,33.7243423461914,1,1,1,299.990509033203,0,,,,,,,,,,,,,,,,
,3540393054.906,299.990707397461,17.1879634857178,-5.75021746009836E-6,1.08963222940339E-8,1,1,13.9012460708618,7.98180096354009,32.5399996340275,-0.0114631052777934,-0.00176159792957464,1,-8.60571238967599E-10,-5.75021746009836E-6,-8.60571238967599E-10,,,,,,,,,,,,,,,,,,,,,299.989074707031,299.992340087891,17.1879634857178,17.1879634857178,52.4527450400248,5.6759213035461,6.65748453140259,14,1,0,0,0,0.497589111328125,33.7243423461914,1,1,1,299.989074707031,0,,,,,,,,,,,,,,,,
,3540393083.031,300.065216064453,23.9208679199219,-5.70858461077727E-6,1.17740050511858E-8,1,1,13.9012460708618,7.98181265782375,32.5399996340275,-0.0113779814643046,-0.00176277079449038,1,-7.83972920946121E-9,-5.70858461077727E-6,-7.83972920946117E-9,,,,,,,,,,,,,,,,,,,,,300.063995361328,300.066436767578,23.9208679199219,23.9208679199219,52.3374548334382,5.6757276443645,6.65992498397827,14,1,0,0,0,0.500869750976562,33.7243423461914,1,1,1,300.066436767578,0,,,,,,,,,,,,,,,,
,3540393114.913,299.977493286133,32.9658241271973,-5.64183926854519E-6,1.23577392965536E-8,1,1,13.9012460708618,7.98179142921049,32.5399996340275,-0.0112411747924009,-0.00176663026096364,1,-2.00239431030757E-8,-5.64183926854519E-6,-2.00239431030757E-8,,,,,,,,,,,,,,,,,,,,,299.976806640625,299.978179931641,32.9658241271973,32.9658241271973,52.4300778129671,5.67582104355768,6.65421676635742,14,1,0,0,0,0.4974365234375,33.7243423461914,1,1,1,299.976806640625,0,,,,,,,,,,,,,,,,
,3540393146.867,299.844741821289,45.5423851013184,-5.57943931819077E-6,9.85205193152095E-9,1,1,13.9012460708618,7.98184309659461,32.5399996340275,-0.0111124706161313,-0.00177585860696662,1,-3.42295267819762E-8,-5.57943931819077E-6,-3.42295267819762E-8,,,,,,,,,,,,,,,,,,,,,299.843902587891,299.845581054687,45.5423851013184,45.5423851013184,52.372237302544,5.67578031297331,6.66534233093262,14,1,0,0,0,0.501022338867188,33.7243423461914,1,1,1,299.845581054687,0,,,,,,,,,,,,,,,,
,3540393175.835,300.132400512695,63.0352325439453,-5.47274675542188E-6,1.1371951755463E-8,1,1,13.9012460708618,7.98174955622343,32.5399996340275,-0.0108981965411483,-0.00175298371769311,1,-3.91407051333898E-8,-5.47274675542188E-6,-3.91407051333898E-8,,,,,,,,,,,,,,,,,,,,,300.12353515625,300.141265869141,63.0352325439453,63.0352325439453,52.3601220604959,5.6763268952098,6.65540456771851,14,1,0,0,0,0.494155883789063,33.7243423461914,1,1,1,300.141265869141,0,,,,,,,,,,,,,,,,
,3540393236.234,300.429382324219,86.892578125,-5.37143069751843E-6,1.21263942649794E-8,1,1,13.9012460708618,7.98193518175586,32.5399996340275,-0.0107037641037802,-0.00167377254082207,1,-1.49500247503909E-8,-5.37143069751843E-6,-1.49500247503909E-8,,,,,,,,,,,,,,,,,,,,,300.426971435547,300.431793212891,86.892578125,86.892578125,52.4875275091306,5.67533625280656,6.65562677383423,14,1,0,0,0,0.500869750976562,33.7243423461914,1,1,1,300.426971435547,0,,,,,,,,,,,,,,,,
,3540393265.344,300.332580566406,120.20140838623,-5.17838424816138E-6,1.69862566387081E-8,1,1,13.9012460708618,7.9819673446725,32.5399996340275,-0.010287507791369,-0.00181940491913024,1,-1.17635787727891E-7,-5.17838424816138E-6,-1.17635787727891E-7,,,,,,,,,,,,,,,,,,,,,300.328369140625,300.336791992188,120.20140838623,120.20140838623,52.4949529800632,5.67561729018729,6.67032432556152,14,1,0,0,0,0.499343872070313,33.7243423461914,1,1,1,300.326629638672,0,,,,,,,,,,,,,,,,
,3540393297.578,300.143508911133,165.692977905273,-4.9742375179792E-6,1.8171413772264E-8,1,1,13.9012460708618,7.98189166059456,32.5399996340275,-0.00988676454858822,-0.00171592612434839,1,-9.70754420279507E-8,-4.9742375179792E-6,-9.70754420279507E-8,,,,,,,,,,,,,,,,,,,,,300.142913818359,300.144104003906,165.692977905273,165.692977905273,52.4042840718325,5.67575770554851,6.65656232833862,14,1,0,0,0,0.49713134765625,34.2131004333496,1,1,1,300.144104003906,0,,,,,,,,,,,,,,,,
,3540393328.695,300.249938964844,228.512252807617,-4.66595434737683E-6,2.07775273574186E-8,1,1,13.9012460708618,7.98186516275118,32.5399996340275,-0.00926864034075334,-0.00164452196852974,1,-1.08588050914669E-7,-4.66595434737683E-6,-1.08588050914669E-7,,,,,,,,,,,,,,,,,,,,,300.246795654297,300.253082275391,228.512252807617,228.512252807617,52.4496185259478,5.67609349357061,6.66289186477661,14,1,0,0,0,0.500411987304687,34.2131004333496,1,1,1,300.253082275391,0,,,,,,,,,,,,,,,,
,3540393362.882,300.151794433594,315.074523925781,-4.34585307335076E-6,2.45406745035594E-8,1,1,13.9012460708618,7.98189946771398,32.5399996340275,-0.00862817162972952,-0.00156184972067821,1,-1.16259208708488E-7,-4.34585307335076E-6,-1.16259208708488E-7,,,,,,,,,,,,,,,,,,,,,300.149688720703,300.153900146484,315.074523925781,315.074523925781,52.4218707135152,5.67573321748159,6.66712045669556,14,1,0,0,0,0.493850708007812,34.2131004333496,1,1,1,300.149688720703,0,,,,,,,,,,,,,,,,
,3540393400.257,300.217361450195,434.844024658203,-3.88717376699921E-6,2.17002242228179E-8,1,1,13.9012460708618,7.98185048220444,32.5499983131886,-0.00770496112339381,-0.00147862104866854,1,-1.44930695744986E-7,-3.88717376699921E-6,-1.44930695744986E-7,,,,,,,,,,,,,,,,,,,,,300.213806152344,300.220916748047,434.844024658203,434.844024658203,52.5058957793325,5.67569077070944,6.65479755401611,14,1,0,0,0,0.49835205078125,34.2131004333496,1,1,1,300.224456787109,0,,,,,,,,,,,,,,,,
,3540393447.344,300.350891113281,599.95263671875,-5.04102191534555E-7,1.89295120244405E-8,1,1,13.9012460708618,7.98190047300918,32.5399996340275,-0.00098553268856856,-0.000280841443445598,1,-6.34828514157883E-8,-5.04102191534555E-7,-6.34828514157883E-8,,,,,,,,,,,,,,,,,,,,,300.349212646484,300.352569580078,599.95263671875,599.95263671875,52.5035508937748,5.67597886896808,6.66075372695923,14,1,0,0,0,0.496978759765625,34.2131004333496,1,1,1,300.349212646484,0,,,,,,,,,,,,,,,,
,3540393499.007,300.369827270508,827.880493164062,6.35123567582603E-6,1.38328527941204E-8,1,1,13.9012460708618,7.98185894698186,32.5399996340275,0.012690744818655,0.00175388608127392,1,-9.52811502112779E-8,6.35123567582603E-6,-9.52811502112779E-8,,,,,,,,,,,,,,,,,,,,,300.366180419922,300.373474121094,827.880493164062,827.880493164062,52.4781479668998,5.67602526415778,6.65525436401367,14,1,0,0,0,0.500411987304687,34.2131004333496,1,1,1,300.366180419922,0,,,,,,,,,,,,,,,,
,3540393555.695,300.294692993164,1142.19287109375,6.32276270789605E-6,1.18750419824005E-7,1,1,13.9012460708618,7.9819199806444,32.5399996340275,0.0127023999597171,0.00129988507645092,1,-3.18646316444386E-7,6.32276270789605E-6,-3.18646316444386E-7,,,,,,,,,,,,,,,,,,,,,300.294036865234,300.295349121094,1142.19287109375,1142.19287109375,52.4273421131498,5.67603804495721,6.67222213745117,14,1,0,0,0,0.50079345703125,34.2131004333496,1,1,1,300.294036865234,0,,,,,,,,,,,,,,,,
,3540393623.992,300.146087646484,1575.8173828125,5.4814998985559E-6,2.1616751825169E-8,1,1,13.9012460708618,7.98193167771027,32.5399996340275,0.0109747496311845,0.00137163039268506,1,-1.53505975338065E-7,5.4814998985559E-6,-1.53505975338065E-7,,,,,,,,,,,,,,,,,,,,,300.145874023438,300.146301269531,1575.8173828125,1575.8173828125,52.4515725972459,5.67574076585382,6.65374803543091,14,1,0,0,0,0.50079345703125,34.2131004333496,1,1,1,300.145874023438,0,,,,,,,,,,,,,,,,
,3540393708.710,300.27766418457,2174.15649414062,4.13648437624435E-6,1.69833499313327E-8,1,1,13.9012460708618,7.9819615683355,32.5399996340275,0.00831533513289826,0.000816978989401443,1,-2.25236839429658E-7,4.13648437624435E-6,-2.25236839429658E-7,,,,,,,,,,,,,,,,,,,,,300.274871826172,300.280456542969,2174.15649414062,2174.15649414062,52.4543082970632,5.67582306192552,6.67002296447754,14,1,0,0,0,0.500946044921875,34.2131004333496,1,1,1,300.274871826172,0,,,,,,,,,,,,,,,,
,3540393819.437,300.088195800781,2999.94091796875,2.05008389758631E-6,2.07934065524974E-8,1,1,13.9012460708618,7.98193301576733,32.5399996340275,0.00415737940094824,0.000168957272310575,1,-2.29982532872316E-7,2.05008389758631E-6,-2.29982532872316E-7,,,,,,,,,,,,,,,,,,,,,300.087768554687,300.088623046875,2999.94091796875,2999.94091796875,52.4476644546498,5.67576818869546,6.66079711914062,14,1,0,0,0,0.500946044921875,34.2131004333496,1,1,1,300.087768554687,0,,,,,,,,,,,,,,,,
,3540393933.398,299.911346435547,2174.42333984375,4.04307609809958E-6,1.22369723951667E-8,1,1,13.9012460708618,7.98195483970825,32.5399996340275,0.00804717659182699,0.00132211114243188,1,4.24835551061637E-8,4.04307609809958E-6,4.24835551061637E-8,,,,,,,,,,,,,,,,,,,,,299.909851074219,299.912841796875,2174.42333984375,2174.42333984375,52.5187926498998,5.67564856901989,6.66404533386231,14,1,0,0,0,0.50048828125,33.7243423461914,1,1,1,299.912841796875,0,,,,,,,,,,,,,,,,
,3540394024.554,299.954452514648,1575.8173828125,5.4183689326573E-6,1.04107637161281E-8,1,1,13.9012460708618,7.98205201195642,32.5499983131886,0.0107894747493919,0.00173996532502401,1,4.09397525070942E-8,5.4183689326573E-6,4.09397525070942E-8,,,,,,,,,,,,,,,,,,,,,299.950592041016,299.958312988281,1575.8173828125,1575.8173828125,52.4886999519094,5.67564116111808,6.66546487808228,14,1,0,0,0,0.4962158203125,34.2131004333496,1,1,1,299.950592041016,0,,,,,,,,,,,,,,,,
,3540394099.070,299.983001708984,1142.16748046875,6.15607233913397E-6,1.44765610034742E-8,1,1,13.9012460708618,7.9819272746905,32.5399996340275,0.0122444104075707,0.00206755754228658,1,9.20178946290576E-8,6.15607233913397E-6,9.20178946290576E-8,,,,,,,,,,,,,,,,,,,,,299.982238769531,299.983764648438,1142.16748046875,1142.16748046875,52.5180110213805,5.67583806853073,6.67274713516235,14,1,0,0,0,0.500946044921875,34.2131004333496,1,1,1,299.983764648438,0,,,,,,,,,,,,,,,,
,3540394155.530,300.116851806641,827.867797851562,6.53894006388068E-6,1.2786740653324E-8,1,1,13.9012460708618,7.98199282022901,32.5399996340275,0.0130081322612133,0.00218222997761898,1,9.07551311073653E-8,6.53894006388068E-6,9.07551311073653E-8,,,,,,,,,,,,,,,,,,,,,300.114776611328,300.118927001953,827.867797851562,827.867797851562,52.5379425486209,5.67544992096825,6.66515064239502,14,1,0,0,0,0.496444702148438,34.2131004333496,1,1,1,300.114776611328,0,,,,,,,,,,,,,,,,
,3540394203.820,299.981811523438,599.825622558594,6.69320189060305E-6,1.80441594321759E-8,1,1,13.9012460708618,7.98195846175409,32.5399996340275,0.0133083686191022,0.00227675593403436,1,1.14490463650597E-7,6.69320189060305E-6,1.14490463650597E-7,,,,,,,,,,,,,,,,,,,,,299.981353759766,299.982269287109,599.825622558594,599.825622558594,52.4914356517267,5.67552946605843,6.67405223846436,14,1,0,0,0,0.49652099609375,34.2131004333496,1,1,1,299.982177734375,0,,,,,,,,,,,,,,,,
,3540394251.867,299.99772644043,434.831298828125,6.68023612535379E-6,1.33073223431877E-8,1,1,13.9012460708618,7.98197114077955,32.5399996340275,0.0132819368584895,0.00227666907784815,1,1.16436393116511E-7,6.68023612535379E-6,1.16436393116511E-7,,,,,,,,,,,,,,,,,,,,,299.993621826172,300.001831054687,434.831298828125,434.831298828125,52.4257788561113,5.67575302883344,6.65628623962402,14,1,0,0,0,0.498275756835937,34.2131004333496,1,1,1,300.001831054687,0,,,,,,,,,,,,,,,,
,3540394289.328,300.139633178711,315.150756835937,6.60795848137513E-6,1.39722026775526E-8,1,1,13.9012460708618,7.98198642789024,32.5399996340275,0.0131418926762239,0.00222828326358894,1,1.03260559903827E-7,6.60795848137513E-6,1.03260559903827E-7,,,,,,,,,,,,,,,,,,,,,300.138275146484,300.140991210937,315.150756835937,315.150756835937,52.4601705109575,5.6757150355698,6.66110372543335,14,1,0,0,0,0.501251220703125,33.7243423461914,1,1,1,300.138275146484,0,,,,,,,,,,,,,,,,
,3540394326.398,300.136489868164,228.512252807617,6.46606781155499E-6,1.63522314698377E-8,1,1,13.9012460708618,7.9819011155725,32.5399996340275,0.012859032082481,0.00218426739093772,1,1.02971821333459E-7,6.46606781155499E-6,1.02971821333459E-7,,,,,,,,,,,,,,,,,,,,,300.133453369141,300.139526367188,228.512252807617,228.512252807617,52.4644694678132,5.67602527648818,6.67251634597778,14,1,0,0,0,0.500946044921875,34.2131004333496,1,1,1,300.139526367188,0,,,,,,,,,,,,,,,,
,3540394360.866,299.930877685547,165.400802612305,6.36420689993266E-6,1.32637559522886E-8,1,1,13.9012460708618,7.9819498298297,32.5399996340275,0.0126662855428367,0.00208616461707668,1,6.93964516852367E-8,6.36420689993266E-6,6.93964516852367E-8,,,,,,,,,,,,,,,,,,,,,299.923614501953,299.938140869141,165.400802612305,165.400802612305,52.5606097756786,5.67597891271575,6.66319036483765,14,1,0,0,0,0.499343872070313,34.2131004333496,1,1,1,299.923614501953,0,,,,,,,,,,,,,,,,
,3540394396.132,299.799987792969,119.845703125,6.2198849385487E-6,1.04179254333545E-8,1,1,13.9012460708618,7.98189587520175,32.5399996340275,0.0123840710546798,0.00200583479023006,1,5.12626157100927E-8,6.2198849385487E-6,5.12626157100927E-8,,,,,,,,,,,,,,,,,,,,,299.796508789063,299.803466796875,119.845703125,119.845703125,52.4519634115056,5.67585445020298,6.66576433181763,14,1,0,0,0,0.500564575195313,34.2131004333496,1,1,1,299.796508789063,0,,,,,,,,,,,,,,,,
,3540394433.515,299.692138671875,86.8798751831055,6.10507301366232E-6,9.50820500909738E-9,1,1,13.9012460708618,7.98190294572152,32.5399996340275,0.0121571221026329,0.00195812391407628,1,4.49558946516488E-8,6.10507301366232E-6,4.49558946516488E-8,,,,,,,,,,,,,,,,,,,,,299.687652587891,299.696624755859,86.8798751831055,86.8798751831055,52.4011575577555,5.67598441419947,6.67121601104736,14,1,0,0,0,0.500564575195313,33.7243423461914,1,1,1,299.687652587891,0,,,,,,,,,,,,,,,,
,3540394489.429,299.565872192383,63.1622695922852,6.02126776361085E-6,1.09516151465903E-8,1,1,13.9012460708618,7.98200400795103,32.5399996340275,0.0119933131241891,0.0019118023648702,1,3.45794367006596E-8,6.02126776361085E-6,3.45794367006597E-8,,,,,,,,,,,,,,,,,,,,,299.563873291016,299.56787109375,63.1622695922852,63.1622695922852,52.4918264659863,5.67570421380155,6.65686893463135,14,1,0,0,0,0.497360229492188,33.7243423461914,1,1,1,299.56787109375,0,,,,,,,,,,,,,,,,
,3540394527.218,299.636856079102,45.5042724609375,5.96412051212017E-6,1.10949104139142E-8,1,1,13.9012460708618,7.98193380554438,32.5399996340275,0.0118863616043636,0.00184847228199347,1,1.15905031171376E-8,5.96412051212017E-6,1.15905031171376E-8,,,,,,,,,,,,,,,,,,,,,299.633026123047,299.640686035156,45.5042724609375,45.5042724609375,52.4328135127844,5.67568679261146,6.67375183105469,14,1,0,0,0,0.500564575195313,34.2131004333496,1,1,1,299.633026123047,0,,,,,,,,,,,,,,,,
,3540394567.953,299.624069213867,32.9658241271973,5.92169759028686E-6,1.10726703778668E-8,1,1,13.9012460708618,7.98193983858911,32.5399996340275,0.0117994288674718,0.00185089182840748,1,1.93166387846032E-8,5.92169759028686E-6,1.93166387846032E-8,,,,,,,,,,,,,,,,,,,,,299.621276855469,299.626861572266,32.9658241271973,32.9658241271973,52.5137120645248,5.6758110468445,6.67476081848145,14,1,0,0,0,0.499649047851562,33.7243423461914,1,1,1,299.621276855469,0,,,,,,,,,,,,,,,,
,3540394608.679,299.582778930664,23.9462757110596,5.88747071608166E-6,8.97803368983671E-9,1,1,13.9012460708618,7.98192161615529,32.5399996340275,0.0117381332623807,0.00179512097528865,1,-3.40291440705325E-9,5.88747071608166E-6,-3.40291440705325E-9,,,,,,,,,,,,,,,,,,,,,299.579498291016,299.586059570313,23.9462757110596,23.9462757110596,52.4304686272267,5.67591390905085,6.67483329772949,14,1,0,0,0,0.497360229492188,34.2131004333496,1,1,1,299.579498291016,0,,,,,,,,,,,,,,,,
,3540394659.968,299.572998046875,17.6834030151367,5.85162532453798E-6,1.17237872677314E-8,1,1,13.9012460708618,7.98189647059128,32.5399996340275,0.0116675151777269,0.00177852405986094,1,-6.2234617534996E-9,5.85162532453798E-6,-6.2234617534996E-9,,,,,,,,,,,,,,,,,,,,,299.571990966797,299.574005126953,17.6834030151367,17.6834030151367,52.4867458806113,5.67589745170086,6.6657657623291,14,1,0,0,0,0.4974365234375,34.2131004333496,1,1,1,299.571990966797,0,,,,,,,,,,,,,,,,
,3540394710.820,299.511352539063,12.7798147201538,5.82948857966713E-6,1.07911876525662E-8,1,1,13.9012460708618,7.98191291332403,32.5399996340275,0.0116238243162802,0.00176897256448206,1,-7.61717975781869E-9,5.82948857966713E-6,-7.61717975781869E-9,,,,,,,,,,,,,,,,,,,,,299.509307861328,299.513397216797,12.7798147201538,12.7798147201538,52.4046748860921,5.67608135376422,6.65555000305176,14,1,0,0,0,0.496902465820313,34.2131004333496,1,1,1,299.513397216797,0,,,,,,,,,,,,,,,,
,3540394822.874,299.862442016602,9.24821662902832,5.81663161945218E-6,1.03422448362734E-8,1,1,13.9012460708618,7.98195881574333,32.5399996340275,0.0115989960684046,0.00176006104269775,1,-1.01163828026108E-8,5.81663161945218E-6,-1.01163828026108E-8,,,,,,,,,,,,,,,,,,,,,299.859069824219,299.865814208984,9.24821662902832,9.24821662902832,52.4390665409382,5.67590112852791,6.67615413665772,14,1,0,0,0,0.49774169921875,34.2131004333496,1,1,1,299.859069824219,0,,,,,,,,,,,,,,,,
,3540394853.500,299.80500793457,6.60586833953857,5.80155497838013E-6,1.0571860681194E-8,1,1,13.9012460708618,7.98196569463292,32.5399996340275,0.0115659802790833,0.00177476104394649,1,-4.28537728552542E-10,5.80155497838013E-6,-4.28537728552542E-10,,,,,,,,,,,,,,,,,,,,,299.799743652344,299.810272216797,6.60586833953857,6.60586833953857,52.5015968224767,5.67598264277562,6.66315269470215,14,1,0,0,0,0.497283935546875,34.2131004333496,1,1,1,299.799743652344,0,,,,,,,,,,,,,,,,
,3540394889.734,299.673080444336,4.8908839225769,5.81342902699777E-6,1.21051772589404E-8,1,1,13.9012460708618,7.98192815295046,32.5399996340275,0.0115925291227085,0.00175944760042664,1,-9.93048637168277E-9,5.81342902699777E-6,-9.93048637168281E-9,,,,,,,,,,,,,,,,,,,,,299.669311523438,299.676849365234,4.8908839225769,4.8908839225769,52.3695016027267,5.67583228242606,6.67230701446533,14,1,0,0,0,0.493392944335937,34.2131004333496,1,1,1,299.669311523438,0,,,,,,,,,,,,,,,,
,3540394919.383,299.898300170898,3.62052416801453,5.80040501621527E-6,9.98518716833342E-9,1,1,13.9012460708618,7.98191736318024,32.5399996340275,0.0115648996465845,0.00176624842242277,1,-4.51895160029105E-9,5.80040501621527E-6,-4.51895160029105E-9,,,,,,,,,,,,,,,,,,,,,299.891754150391,299.904846191406,3.62052416801453,3.62052416801453,52.5844494455152,5.67577978542292,6.65947008132935,14,1,0,0,0,0.497283935546875,34.2131004333496,1,1,1,299.904846191406,0,,,,,,,,,,,,,,,,
,3540394943.476,299.89453125,2.66775488853455,5.79023429627855E-6,9.27521277208638E-9,1,1,13.9012460708618,7.9819512441903,32.5499983131886,0.0115434739905081,0.00177081042014095,1,-6.71318028256343E-10,5.79023429627855E-6,-6.71318028256383E-10,,,,,,,,,,,,,,,,,,,,,299.893127441406,299.895935058594,2.66775488853455,2.66775488853455,52.5324711489863,5.67573497623103,6.66895151138306,14,1,0,0,0,0.500030517578125,34.2131004333496,1,1,1,299.895935058594,0,,,,,,,,,,,,,,,,
,3540394970.359,299.952178955078,2.00716781616211,5.78307366591512E-6,7.23769370074515E-9,1,1,13.9012460708618,7.98193831763216,32.5399996340275,0.0115340844996065,0.00173672326979777,1,-1.66696968254845E-8,5.78307366591512E-6,-1.66696968254844E-8,,,,,,,,,,,,,,,,,,,,,299.946441650391,299.957916259766,2.00716781616211,2.00716781616211,52.4269512988902,5.67556275476202,6.66793966293335,14,1,0,0,0,0.50048828125,34.2131004333496,1,1,1,299.946441650391,0,,,,,,,,,,,,,,,,
,3540394997.148,299.723587036133,1.47361695766449,5.77708766118455E-6,1.06509668281202E-8,1,1,13.9012460708618,7.98191121528471,32.5399996340275,0.0115229138182252,0.00172977322843879,1,-1.92352516484375E-8,5.77708766118455E-6,-1.92352516484375E-8,,,,,,,,,,,,,,,,,,,,,299.721374511719,299.725799560547,1.47361695766449,1.47361695766449,52.5406782484383,5.67575106434178,6.65761661529541,14,1,0,0,0,0.497512817382812,34.2131004333496,1,1,1,299.721374511719,0,,,,,,,,,,,,,,,,
,3540395031.718,299.592681884766,-1.19413793087006,5.77488209218602E-6,1.02843651918708E-8,1,1,13.9012460708618,7.98193665267554,32.5399996340275,0.0115163345823908,0.0017434526747835,1,-1.20364547453392E-8,5.77488209218602E-6,-1.20364547453392E-8,,,,,,,,,,,,,,,,,,,,,299.592132568359,299.593231201172,-1.19413793087006,-1.19413793087006,52.453526668544,5.67582320882829,6.65857601165772,14,1,0,0,0,0.49774169921875,34.2131004333496,1,1,1,299.592132568359,0,,,,,,,,,,,,,,,,
,3540395046.539,299.648574829102,-1.30847024917603,5.76258805198823E-6,6.75388550133018E-9,1,1,13.9012460708618,7.98195166869182,32.5399996340275,0.0114933639743175,0.00172975119243844,1,-1.70228041906274E-8,5.76258805198823E-6,-1.70228041906274E-8,,,,,,,,,,,,,,,,,,,,,299.643188476562,299.653961181641,-1.30847024917603,-1.30847024917603,52.6360369277844,5.67583485406259,6.6740460395813,14,1,0,0,0,0.498809814453125,34.2131004333496,1,1,1,299.653961181641,0,,,,,,,,,,,,,,,,
,3540395067.468,299.833938598633,-1.8166139125824,5.76983331885028E-6,1.10029708121562E-8,1,1,13.9012460708618,7.98191403280748,32.5399996340275,0.0115064027403899,0.00174091531236066,1,-1.2532713091404E-8,5.76983331885028E-6,-1.2532713091404E-8,,,,,,,,,,,,,,,,,,,,,299.833892822266,299.833984375,-1.8166139125824,-1.8166139125824,52.5590465186402,5.67574690447866,6.66136312484741,14,1,0,0,0,0.499801635742188,34.2131004333496,1,1,1,299.833892822266,0,,,,,,,,,,,,,,,,
,3540395136.038,299.540191650391,-2.64234757423401,5.75000118591484E-6,9.04200095740017E-9,1,1,13.9012460708618,7.98197818742694,32.5399996340275,0.0114656302720728,0.00174324555853528,1,-8.32317267276313E-9,5.75000118591484E-6,-8.32317267276313E-9,,,,,,,,,,,,,,,,,,,,,299.538940429687,299.541442871094,-2.64234757423401,-2.64234757423401,52.5199650926786,5.67560439558594,6.67365217208862,14,1,0,0,0,0.4998779296875,34.2131004333496,1,1,1,299.541442871094,0,,,,,,,,,,,,,,,,
,3540395165.929,299.668045043945,-3.76026391983032,5.74650418834208E-6,1.0339079791558E-8,1,1,13.9012460708618,7.98194298006064,32.5399996340275,0.0114581479662751,0.00174530980181681,1,-6.74865411826094E-9,5.74650418834208E-6,-6.74865411826098E-9,,,,,,,,,,,,,,,,,,,,,299.666168212891,299.669921875,-3.76026391983032,-3.76026391983032,52.4515725972459,5.6754149620215,6.6573634147644,14,1,0,0,0,0.500717163085937,34.2131004333496,1,1,1,299.666168212891,0,,,,,,,,,,,,,,,,
,3540395224.656,299.580108642578,-5.17036294937134,5.74887428629151E-6,9.57528533518833E-9,1,1,13.9012460708618,7.98190893988535,32.5399996340275,0.0114702203235848,0.00169799024926148,1,-3.08464798788302E-8,5.74887428629151E-6,-3.08464798788302E-8,,,,,,,,,,,,,,,,,,,,,299.579223632812,299.580993652344,-5.17036294937134,-5.17036294937134,52.5731158319863,5.67551749833618,6.66668891906738,14,1,0,0,0,0.497512817382812,33.7243423461914,1,1,1,299.579223632812,0,,,,,,,,,,,,,,,,
,3540395266.585,299.659133911133,-6.9107551574707,5.74320823687531E-6,1.0458628996052E-8,1,1,13.9012460708618,7.9819178256799,32.5399996340275,0.0114545479306086,0.00172481342351133,1,-1.65223164246119E-8,5.74320823687531E-6,-1.65223164246119E-8,,,,,,,,,,,,,,,,,,,,,299.6552734375,299.662994384766,-6.9107551574707,-6.9107551574707,52.4597796966979,5.67543247640759,6.67344856262207,14,1,0,0,0,0.500869750976562,34.2131004333496,1,1,1,299.662994384766,0,,,,,,,,,,,,,,,,
,3540395303.070,299.63444519043,-9.73095226287842,5.72534656699965E-6,9.34926420871343E-9,1,1,13.9012460708618,7.98189068801633,32.5499983131886,0.0114180979598378,0.00172468003290748,1,-1.38453826379734E-8,5.72534656699965E-6,-1.38453826379734E-8,,,,,,,,,,,,,,,,,,,,,299.631591796875,299.637298583984,-9.73095226287842,-9.73095226287842,52.5039417080344,5.67575667954694,6.67171001434326,14,1,0,0,0,0.500640869140625,34.2131004333496,1,1,1,299.631591796875,0,,,,,,,,,,,,,,,,
,3540395334.163,299.646545410156,-13.6944751739502,5.68839197809521E-6,9.65623304674125E-9,1,1,13.9012460708618,7.98188492900348,32.5399996340275,0.0113409704034361,0.00173585082057203,1,-2.56825358099457E-9,5.68839197809521E-6,-2.56825358099457E-9,,,,,,,,,,,,,,,,,,,,,299.644836425781,299.648254394531,-13.6944751739502,-13.6944751739502,52.539896619919,5.67547916205613,6.66381692886353,14,1,0,0,0,0.497894287109375,34.2131004333496,1,1,1,299.648254394531,0,,,,,,,,,,,,,,,,
,3540395368.023,299.645462036133,-18.8013191223145,5.67731499601762E-6,7.29754132385704E-9,1,1,13.9012460708618,7.98189550060746,32.5399996340275,0.011317539880536,0.00174129709689565,1,1.86357587017946E-9,5.67731499601762E-6,1.86357587017946E-9,,,,,,,,,,,,,,,,,,,,,299.643463134766,299.6474609375,-18.8013191223145,-18.8013191223145,52.5133212502652,5.67530823467075,6.66834831237793,14,1,0,0,0,0.50079345703125,34.2131004333496,1,1,1,299.643463134766,0,,,,,,,,,,,,,,,,
,3540395404.515,299.622467041016,-26.2202167510986,5.6253351540696E-6,1.07319724898021E-8,1,1,13.9012460708618,7.98188729853716,32.5399996340275,0.0112151346409707,0.00171739716257439,1,-2.14438103442424E-9,5.6253351540696E-6,-2.14438103442424E-9,,,,,,,,,,,,,,,,,,,,,299.618072509766,299.626861572266,-26.2202167510986,-26.2202167510986,52.5516210477075,5.67537342059174,6.66757440567017,14,1,0,0,0,0.500411987304687,34.2131004333496,1,1,1,299.618072509766,0,,,,,,,,,,,,,,,,
,3540395456.288,299.583267211914,-35.9384651184082,5.57964522509059E-6,1.09079684213611E-8,1,1,13.9012460708618,7.98191700047367,32.5399996340275,0.0111205002394235,0.00172668500586193,1,9.52710811234407E-9,5.57964522509059E-6,9.52710811234407E-9,,,,,,,,,,,,,,,,,,,,,299.580230712891,299.586303710937,-35.9384651184082,-35.9384651184082,52.4836193665344,5.67523442287118,6.66298580169678,14,1,0,0,0,0.500869750976562,34.2131004333496,1,1,1,299.586303710937,0,,,,,,,,,,,,,,,,
,3540395511.968,299.527694702148,-49.5694236755371,5.50864359684114E-6,1.05471238155572E-8,1,1,13.9012460708618,7.9818980646776,32.5399996340275,0.0109809150658393,0.00169207805443658,1,3.06930764749218E-9,5.50864359684114E-6,3.06930764749218E-9,,,,,,,,,,,,,,,,,,,,,299.525421142578,299.529968261719,-49.5694236755371,-49.5694236755371,52.4457103833517,5.67542421531139,6.65722799301148,14,1,0,0,0,0.497817993164063,33.7243423461914,1,1,1,299.529968261719,0,,,,,,,,,,,,,,,,
,3540395549.476,299.584289550781,-68.3961486816406,5.41111998865965E-6,9.98276882266184E-9,1,1,13.9012460708618,7.98191250611898,32.5399996340275,0.0107818935739518,0.00169227789050275,1,1.81407160946532E-8,5.41111998865965E-6,1.81407160946532E-8,,,,,,,,,,,,,,,,,,,,,299.579559326172,299.589019775391,-68.3961486816406,-68.3961486816406,52.4593888824382,5.67570585735546,6.66550540924072,14,1,0,0,0,0.501022338867188,34.2131004333496,1,1,1,299.579559326172,0,,,,,,,,,,,,,,,,
,3540395605.976,299.52864074707,-94.2733688354492,5.29005450420472E-6,1.03940046518991E-8,1,1,13.9012460708618,7.98187332879389,32.5399996340275,0.0105425504919159,0.00164193899712111,1,1.14786434890713E-8,5.29005450420472E-6,1.14786434890713E-8,,,,,,,,,,,,,,,,,,,,,299.526519775391,299.53076171875,-94.2733688354492,-94.2733688354492,52.614151329246,5.67540273452676,6.66440439224243,14,1,0,0,0,0.499114990234375,34.2131004333496,1,1,1,299.53076171875,0,,,,,,,,,,,,,,,,
,3540395640.804,299.751541137695,-130.033981323242,5.07911306859357E-6,1.01150819486251E-8,1,1,13.9012460708618,7.98185799449052,32.5399996340275,0.0101050608865544,0.00168780548250331,1,6.68710569079664E-8,5.07911306859357E-6,6.68710569079664E-8,,,,,,,,,,,,,,,,,,,,,299.748687744141,299.75439453125,-130.033981323242,-130.033981323242,52.4672051676305,5.67536809733607,6.66405630111694,14,1,0,0,0,0.501327514648438,34.2131004333496,1,1,1,299.748687744141,0,,,,,,,,,,,,,,,,
,3540395753.984,299.881271362305,-179.51448059082,4.8860131039647E-6,1.11393173021037E-8,1,1,13.9012460708618,7.98182482684044,32.5399996340275,0.00973451067341333,0.00153471173810717,1,1.97239590083199E-8,4.8860131039647E-6,1.97239590083199E-8,,,,,,,,,,,,,,,,,,,,,299.878723144531,299.883819580078,-179.51448059082,-179.51448059082,52.5305170776882,5.67574132105838,6.67234563827515,14,1,0,0,0,0.500717163085937,34.2131004333496,1,1,1,299.883819580078,0,,,,,,,,,,,,,,,,
,3540395788.859,299.941482543945,-247.631149291992,4.56861686039986E-6,2.32945546539516E-8,1,1,13.9012460708618,7.98179622407666,32.5399996340275,0.00907197227968209,0.00163149519178542,1,1.17001141170277E-7,4.56861686039986E-6,1.17001141170277E-7,,,,,,,,,,,,,,,,,,,,,299.941192626953,299.941772460937,-247.631149291992,-247.631149291992,52.5324711489863,5.67550976548098,6.6710844039917,14,1,0,0,0,0.50079345703125,34.2131004333496,1,1,1,299.941192626953,0,,,,,,,,,,,,,,,,
,3540395822.828,299.956619262695,-341.663177490234,4.18382639495815E-6,1.73031841587595E-8,1,1,13.9012460708618,7.98183525096987,32.5399996340275,0.00829337786534068,0.00158875298649209,1,1.54632607093206E-7,4.18382639495815E-6,1.54632607093206E-7,,,,,,,,,,,,,,,,,,,,,299.951995849609,299.961242675781,-341.663177490234,-341.663177490234,52.4566531826209,5.67555974801672,6.67412424087524,14,1,0,0,0,0.501022338867188,34.2131004333496,1,1,1,299.961242675781,0,,,,,,,,,,,,,,,,
,3540395860.437,300.108612060547,-471.214416503906,3.61613864224395E-6,2.79780877305361E-8,1,1,13.9012460708618,7.98167232065801,32.5499983131886,0.00715469827114033,0.00145978820525712,1,1.77103123759022E-7,3.61613864224395E-6,1.77103123759022E-7,,,,,,,,,,,,,,,,,,,,,300.103363037109,300.113861083984,-471.214416503906,-471.214416503906,52.5039417080344,5.67538618093327,6.66838359832764,14,1,0,0,0,0.497665405273438,34.2131004333496,1,1,1,300.113861083984,0,,,,,,,,,,,,,,,,
,3540395903.343,300.19905090332,-650.195373535156,-3.07151006653119E-6,2.7755491495399E-8,1,1,13.9012460708618,7.98158905048403,32.5399996340275,-0.00618801246280652,-0.000517398464810639,1,2.1200552520043E-7,-3.07151006653119E-6,2.1200552520043E-7,,,,,,,,,,,,,,,,,,,,,300.196319580078,300.201782226562,-650.195373535156,-650.195373535156,52.4187441994382,5.67567089458665,6.67070293426514,14,1,0,0,0,0.497894287109375,34.2131004333496,1,1,1,300.201782226562,0,,,,,,,,,,,,,,,,
,3540395962.148,300.341171264648,-897.064331054687,-6.53453308172742E-6,4.70665884101003E-8,1,1,13.9012460708618,7.98154604520554,32.5499983131886,-0.0131040167043786,-0.00149631279288725,1,2.52607107018306E-7,-6.53453308172742E-6,2.52607107018306E-7,,,,,,,,,,,,,,,,,,,,,300.338745117188,300.343597412109,-897.064331054687,-897.064331054687,52.4449287548325,5.67595655526837,6.67457962036133,14,1,0,0,0,0.493621826171875,34.2131004333496,1,1,1,300.338745117188,0,,,,,,,,,,,,,,,,
,3540396021.812,300.390594482422,-1237.99060058594,-6.13173087800916E-6,4.08829321080119E-8,1,1,13.9012460708618,7.98155429743982,32.5399996340275,-0.0122724640538819,-0.00155911121537146,1,1.59267148007956E-7,-6.13173087800916E-6,1.59267148007956E-7,,,,,,,,,,,,,,,,,,,,,300.389038085937,300.392150878906,-1237.99060058594,-1237.99060058594,52.5051141508132,5.67599882547958,6.67075490951538,14,1,0,0,0,0.497894287109375,34.2131004333496,1,1,1,300.389038085937,0,,,,,,,,,,,,,,,,
,3540396093.788,300.037750244141,-1708.02355957031,-5.19810089989352E-6,1.66843262610358E-8,1,1,13.9012460708618,7.98153800830088,32.5399996340275,-0.0104358916080971,-0.00111281912889005,1,2.39805035038334E-7,-5.19810089989352E-6,2.39805035038334E-7,,,,,,,,,,,,,,,,,,,,,300.037506103516,300.037994384766,-1708.02355957031,-1708.02355957031,52.4546991113229,5.67603366644891,6.67049551010132,14,1,0,0,0,0.501480102539063,34.2131004333496,1,1,1,300.037994384766,0,,,,,,,,,,,,,,,,
,3540396186.382,300.208862304687,-2356.4150390625,-3.6902995650978E-6,1.67724482904186E-8,1,1,13.9012460708618,7.98152938490298,32.5399996340275,-0.00744125868788278,-0.000578414362169672,1,2.76395193157688E-7,-3.6902995650978E-6,2.76395193157688E-7,,,,,,,,,,,,,,,,,,,,,300.207855224609,300.209869384766,-2356.4150390625,-2356.4150390625,52.5606097756786,5.67610302657669,6.67353963851929,14,1,0,0,0,0.5010986328125,34.2131004333496,1,1,1,300.207855224609,0,,,,,,,,,,,,,,,,
,3540400705.375,299.979965209961,-3000.04272460937,-1.93977699868975E-6,1.35729397986226E-8,1,1,13.9012460708618,7.97241325645622,32.5399996340275,-0.00386775912018935,-0.000571686111921053,1,1.08382751960247E-8,-1.93977699868975E-6,1.08382751960247E-8,,,,,,,,,,,,,,,,,,,,,299.979949951172,299.97998046875,-3000.04272460937,-3000.04272460937,52.3956861581209,5.67256187151511,6.66863965988159,14,1,0,0,0,0.498199462890625,29.8142719268799,1,1,1,299.979949951172,0,,,,,,,,,,,,,,,,
,3540400813.007,300.171051025391,-2174.44873046875,-4.0467445581146E-6,1.49694735596932E-8,1,1,13.9012460708618,7.98183523423183,32.5399996340275,-0.00806570317117508,-0.00124973376942422,1,-5.62042955542657E-9,-4.0467445581146E-6,-5.62042955542657E-9,,,,,,,,,,,,,,,,,,,,,300.170379638672,300.171722412109,-2174.44873046875,-2174.44873046875,52.4257788561113,5.67445087851256,6.6613826751709,14,1,0,0,0,0.500335693359375,32.2580642700195,1,1,1,300.170379638672,0,,,,,,,,,,,,,,,,
,3540400897.992,300.079086303711,-1575.90625,-5.39410173458392E-6,1.11918011230605E-8,1,1,13.9012460708618,7.98177820211272,32.5499983131886,-0.0107496456665364,-0.00167544256481789,1,-1.23166615020168E-8,-5.39410173458392E-6,-1.23166615020168E-8,,,,,,,,,,,,,,,,,,,,,300.076873779297,300.081298828125,-1575.90625,-1575.90625,52.4171809423998,5.67493485473792,6.65164375305176,14,1,0,0,0,0.496292114257812,32.7468223571777,1,1,1,300.076873779297,0,,,,,,,,,,,,,,,,
,3540400966.211,300.083740234375,-1142.34533691406,-6.1572420601058E-6,1.21239764118939E-8,1,1,13.9012460708618,7.9818654981232,32.5399996340275,-0.0122524859984049,-0.00203014112398794,1,-7.30742869610768E-8,-6.1572420601058E-6,-7.30742869610768E-8,,,,,,,,,,,,,,,,,,,,,300.082061767578,300.085418701172,-1142.34533691406,-1142.34533691406,52.4101462857267,5.67514862230766,6.6679630279541,14,1,0,0,0,0.496978759765625,33.2355842590332,1,1,1,300.082061767578,0,,,,,,,,,,,,,,,,
,3540401022.757,300.139053344727,-827.867797851562,-6.54003447552124E-6,1.05837549375568E-8,1,1,13.9012460708618,7.9818737063996,32.5399996340275,-0.0130161346703189,-0.00214391016056923,1,-7.13746842562583E-8,-6.54003447552124E-6,-7.13746842562583E-8,,,,,,,,,,,,,,,,,,,,,300.135955810547,300.142150878906,-827.867797851562,-827.867797851562,52.5774147888421,5.67480696547809,6.65887069702148,14,1,0,0,0,0.49957275390625,33.2355842590332,1,1,1,300.142150878906,0,,,,,,,,,,,,,,,,
,3540401082.695,300.405990600586,-600.130493164062,-6.7183762459E-6,9.35191464403972E-9,1,1,13.9012460708618,7.98189265386424,32.5399996340275,-0.0133871246818621,-0.00209794953841529,1,-2.09393277290517E-8,-6.7183762459E-6,-2.09393277290516E-8,,,,,,,,,,,,,,,,,,,,,300.405426025391,300.406555175781,-600.130493164062,-600.130493164062,52.4500093402075,5.67489492150349,6.65853071212769,14,1,0,0,0,0.500640869140625,33.2355842590332,1,1,1,300.405426025391,0,,,,,,,,,,,,,,,,
,3540401124.195,300.142593383789,-434.831298828125,-6.70339473141377E-6,1.25467521202442E-8,1,1,13.9012460708618,7.98189442817768,32.5399996340275,-0.0133292186828166,-0.0022760159109612,1,-1.12559663557141E-7,-6.70339473141377E-6,-1.12559663557141E-7,,,,,,,,,,,,,,,,,,,,,300.138824462891,300.146362304687,-434.831298828125,-434.831298828125,52.3624669460536,5.67481540272701,6.66595649719238,14,1,0,0,0,0.500946044921875,33.2355842590332,1,1,1,300.138824462891,0,,,,,,,,,,,,,,,,
,3540401166.054,300.285140991211,-315.290496826172,-6.60623301734282E-6,1.20464504082024E-8,1,1,13.9012460708618,7.98183742007997,32.5399996340275,-0.0131323271985949,-0.00226671939804544,1,-1.22817533789181E-7,-6.60623301734282E-6,-1.22817533789181E-7,,,,,,,,,,,,,,,,,,,,,300.284881591797,300.285400390625,-315.290496826172,-315.290496826172,52.5985187588613,5.67523185651673,6.6696605682373,14,1,0,0,0,0.497283935546875,33.7243423461914,1,1,1,300.284881591797,0,,,,,,,,,,,,,,,,
,3540401199.562,300.18522644043,-228.461441040039,-6.49177495022138E-6,1.41451271808612E-8,1,1,13.9012460708618,7.98188050826499,32.5399996340275,-0.0129047607423266,-0.00222796547966848,1,-1.20946386420717E-7,-6.49177495022138E-6,-1.20946386420717E-7,,,,,,,,,,,,,,,,,,,,,300.183288574219,300.187164306641,-228.461441040039,-228.461441040039,52.4222615277748,5.67509061903489,6.66882133483887,14,1,0,0,0,0.4962158203125,33.7243423461914,1,1,1,300.187164306641,0,,,,,,,,,,,,,,,,
,3540401237.484,300.161834716797,-165.654861450195,-6.34177701885176E-6,8.00829640959629E-8,1,1,13.9012460708618,7.98192739819518,32.5399996340275,-0.0126427953715044,-0.00194090775025629,1,2.09970288213961E-11,-6.34177701885176E-6,2.09970288213961E-11,,,,,,,,,,,,,,,,,,,,,300.152404785156,300.171264648438,-165.654861450195,-165.654861450195,52.555138376044,5.67529321968559,6.66518115997314,14,1,0,0,0,0.50018310546875,33.7243423461914,1,1,1,300.152404785156,0,,,,,,,,,,,,,,,,
,3540401269.780,299.939559936523,-119.985450744629,-6.24260459535734E-6,1.4876307784689E-8,1,1,13.9012460708618,7.98191892229794,32.5399996340275,-0.0124183203754422,-0.00208486161259589,1,-8.74138242941537E-8,-6.24260459535734E-6,-8.74138242941537E-8,,,,,,,,,,,,,,,,,,,,,299.939361572266,299.939758300781,-119.985450744629,-119.985450744629,52.5781964173613,5.67488865302772,6.67411327362061,14,1,0,0,0,0.497055053710937,34.2131004333496,1,1,1,299.939361572266,0,,,,,,,,,,,,,,,,
,3540401301.656,299.934417724609,-87.0323257446289,-6.12140540417503E-6,1.75386401221746E-8,1,1,13.9012460708618,7.98182358294298,32.5399996340275,-0.01217554580248,-0.00205473854389849,1,-9.09175236790901E-8,-6.12140540417503E-6,-9.091752367909E-8,,,,,,,,,,,,,,,,,,,,,299.933288574219,299.935546875,-87.0323257446289,-87.0323257446289,52.4660327248517,5.67530536233356,6.65619564056397,14,1,0,0,0,0.5010986328125,33.7243423461914,1,1,1,299.933288574219,0,,,,,,,,,,,,,,,,
,3540401330.632,299.955459594727,-63.0733451843262,-6.06182278599032E-6,1.38503098762601E-8,1,1,13.9012460708618,7.98196380830985,32.5399996340275,-0.0120638565600813,-0.00199111552287263,1,-6.81404394863856E-8,-6.06182278599032E-6,-6.81404394863856E-8,,,,,,,,,,,,,,,,,,,,,299.954864501953,299.9560546875,-63.0733451843262,-63.0733451843262,52.5590465186402,5.67480805060425,6.65976572036743,14,1,0,0,0,0.499038696289063,33.7243423461914,1,1,1,299.954864501953,0,,,,,,,,,,,,,,,,
,3540401381.890,299.608093261719,-45.7964553833008,-5.99642438171627E-6,1.15845802749429E-8,1,1,13.9012460708618,7.98197401424366,32.5399996340275,-0.0119434264101831,-0.00190636859462754,1,-3.56698710160194E-8,-5.99642438171627E-6,-3.56698710160194E-8,,,,,,,,,,,,,,,,,,,,,299.603942871094,299.612243652344,-45.7964553833008,-45.7964553833008,52.5785872316209,5.67502606889997,6.67254638671875,14,1,0,0,0,0.5010986328125,33.7243423461914,1,1,1,299.612243652344,0,,,,,,,,,,,,,,,,
,3540401410.836,300.055953979492,-33.245304107666,-5.94985652278038E-6,1.31919485943793E-8,1,1,13.9012460708618,7.98194236712154,32.5399996340275,-0.0118524583008066,-0.00187976560679708,1,-2.94768712821784E-8,-5.94985652278038E-6,-2.94768712821784E-8,,,,,,,,,,,,,,,,,,,,,300.050109863281,300.061798095703,-33.245304107666,-33.245304107666,52.5539659332652,5.67509378913339,6.67342042922974,14,1,0,0,0,0.500411987304687,33.7243423461914,1,1,1,300.061798095703,0,,,,,,,,,,,,,,,,
,3540401442.617,299.994400024414,-24.0479030609131,-5.92767046463115E-6,1.35791650082417E-8,1,1,13.9012460708618,7.98195868571417,32.5399996340275,-0.0118117764135191,-0.00184995892978717,1,-1.79304650982031E-8,-5.92767046463115E-6,-1.79304650982031E-8,,,,,,,,,,,,,,,,,,,,,299.989227294922,299.999572753906,-24.0479030609131,-24.0479030609131,52.5203559069382,5.67526875095006,6.67075872421265,14,1,0,0,0,0.497283935546875,33.7243423461914,1,1,1,299.989227294922,0,,,,,,,,,,,,,,,,
,3540401471.476,300.205368041992,-17.4293308258057,-5.90589306024699E-6,1.22714718663401E-8,1,1,13.9012460708618,7.98194496067426,32.5399996340275,-0.0117698503289351,-0.00183351882286672,1,-1.30281453761806E-8,-5.90589306024699E-6,-1.30281453761806E-8,,,,,,,,,,,,,,,,,,,,,300.194885253906,300.215850830078,-17.4293308258057,-17.4293308258057,52.5531843047459,5.67507345081396,6.66544961929321,14,1,0,0,0,0.497665405273438,34.2131004333496,1,1,1,300.215850830078,0,,,,,,,,,,,,,,,,
,3540401502.780,300.250244140625,-12.6527795791626,-5.85745061650959E-6,1.40395923171015E-8,1,1,13.9012460708618,7.98200242822648,32.5399996340275,-0.0116738580127596,-0.0018152263525714,1,-1.12856800827067E-8,-5.85745061650959E-6,-1.12856800827067E-8,,,,,,,,,,,,,,,,,,,,,300.244567871094,300.255920410156,-12.6527795791626,-12.6527795791626,52.4468828261306,5.6750363277913,6.66187477111816,14,1,0,0,0,0.500946044921875,33.7243423461914,1,1,1,300.244567871094,0,,,,,,,,,,,,,,,,
,3540401530.828,299.870956420898,-9.17199516296387,-5.85846130408191E-6,1.27862070631364E-8,1,1,13.9012460708618,7.98202599415477,32.5399996340275,-0.0116770333936398,-0.00180810788790469,1,-7.55829811287245E-9,-5.85846130408191E-6,-7.55829811287245E-9,,,,,,,,,,,,,,,,,,,,,299.869964599609,299.871948242188,-9.17199516296387,-9.17199516296387,52.5430231339959,5.67493868634399,6.67522239685059,14,1,0,0,0,0.497055053710937,34.2131004333496,1,1,1,299.869964599609,0,,,,,,,,,,,,,,,,
,3540401559.422,299.938720703125,-6.68209075927734,-5.85202973046752E-6,1.13465986694782E-8,1,1,13.9012460708618,7.9819828793721,32.5399996340275,-0.0116657560354217,-0.00179583878653519,1,-2.3941797591275E-9,-5.85202973046752E-6,-2.3941797591275E-9,,,,,,,,,,,,,,,,,,,,,299.932708740234,299.944732666016,-6.68209075927734,-6.68209075927734,52.4703316817075,5.6751126161579,6.65345525741577,14,1,0,0,0,0.500564575195313,33.7243423461914,1,1,1,299.932708740234,0,,,,,,,,,,,,,,,,
,3540401593.125,299.695938110352,-4.8908839225769,-5.84267399579422E-6,7.3725031975005E-9,1,1,13.9012460708618,7.98200073651925,32.5399996340275,-0.0116500290082326,-0.00177402606293005,1,7.11212834185544E-9,-5.84267399579422E-6,7.11212834185544E-9,,,,,,,,,,,,,,,,,,,,,299.687133789063,299.704742431641,-4.8908839225769,-4.8908839225769,52.478929595419,5.67505258299589,6.66289043426514,14,1,0,0,0,0.500640869140625,34.2131004333496,1,1,1,299.687133789063,0,,,,,,,,,,,,,,,,
,3540401668.422,299.535308837891,-3.59511709213257,-5.84092906147922E-6,1.1920871750835E-8,1,1,13.9012460708618,7.98205310542989,32.5399996340275,-0.0116505334938661,-0.00174783780941456,1,1.99838057532154E-8,-5.84092906147922E-6,1.99838057532154E-8,,,,,,,,,,,,,,,,,,,,,299.533843994141,299.536773681641,-3.59511709213257,-3.59511709213257,52.5809321171786,5.67499330004042,6.66308546066284,14,1,0,0,0,0.500106811523438,34.2131004333496,1,1,1,299.536773681641,0,,,,,,,,,,,,,,,,
,3540401698.820,299.63786315918,-2.6042366027832,-5.84163329373637E-6,1.08556448151281E-8,1,1,13.9012460708618,7.98194096419855,32.5399996340275,-0.0116482815284152,-0.00177124384587252,1,8.34414371990051E-9,-5.84163329373637E-6,8.34414371990055E-9,,,,,,,,,,,,,,,,,,,,,299.637420654297,299.638305664063,-2.6042366027832,-2.6042366027832,52.6798081248613,5.67520013009284,6.66355323791504,14,1,0,0,0,0.499038696289063,34.2131004333496,1,1,1,299.637420654297,0,,,,,,,,,,,,,,,,
,3540401749.179,299.569061279297,-1.96905708312988,-5.84205145006565E-6,1.0392504422518E-8,1,1,13.9012460708618,7.98199034472617,32.5399996340275,-0.0116521508823069,-0.00175187235933417,1,1.81284096366581E-8,-5.84205145006565E-6,1.81284096366581E-8,,,,,,,,,,,,,,,,,,,,,299.566223144531,299.571899414063,-1.96905708312988,-1.96905708312988,52.5000335654383,5.67499421216128,6.65676069259644,14,1,0,0,0,0.500717163085937,34.2131004333496,1,1,1,299.571899414063,0,,,,,,,,,,,,,,,,
,3540401796.461,299.530838012695,-1.46091330051422,-5.82178264850398E-6,8.10140083580287E-9,1,1,13.9012460708618,7.9820124810908,32.5399996340275,-0.0116085173576771,-0.00176680490611075,1,7.52778745295998E-9,-5.82178264850398E-6,7.52778745295998E-9,,,,,,,,,,,,,,,,,,,,,299.528991699219,299.532684326172,-1.46091330051422,-1.46091330051422,52.458607253919,5.67510482924381,6.66533994674683,14,1,0,0,0,0.496978759765625,34.2131004333496,1,1,1,299.532684326172,0,,,,,,,,,,,,,,,,
,3540401821.937,299.630142211914,0.965473115444183,-5.8284245705383E-6,9.52867995968171E-9,1,1,13.9012460708618,7.98204633282751,32.5399996340275,-0.0116254428510613,-0.00174502715721823,1,1.94735084758866E-8,-5.8284245705383E-6,1.94735084758866E-8,,,,,,,,,,,,,,,,,,,,,299.628692626953,299.631591796875,0.965473115444183,0.965473115444183,52.5019876367363,5.6749194493347,6.66314840316772,14,1,0,0,0,0.500259399414063,34.2131004333496,1,1,1,299.628692626953,0,,,,,,,,,,,,,,,,
,3540401859.148,299.565582275391,1.30847024917603,-5.81108843632105E-6,9.54882547711791E-9,1,1,13.9012460708618,7.98205671276399,32.5399996340275,-0.0115875266493708,-0.00176163262898097,1,8.48324607929293E-9,-5.81108843632105E-6,8.48324607929293E-9,,,,,,,,,,,,,,,,,,,,,299.565002441406,299.566162109375,1.30847024917603,1.30847024917603,52.595783059044,5.67504619095128,6.6593165397644,14,1,0,0,0,0.4998779296875,34.2131004333496,1,1,1,299.565002441406,0,,,,,,,,,,,,,,,,
,3540401895.765,299.588516235352,1.99446427822113,-5.81226861343693E-6,9.1283466699962E-9,1,1,13.9012460708618,7.98216652614847,32.5399996340275,-0.0115889638611122,-0.00176856469020947,1,5.19422597876905E-9,-5.81226861343693E-6,5.19422597876909E-9,,,,,,,,,,,,,,,,,,,,,299.587249755859,299.589782714844,1.99446427822113,1.99446427822113,52.4898723946882,5.67460197563878,6.64745855331421,14,1,0,0,0,0.500259399414063,34.2131004333496,1,1,1,299.587249755859,0,,,,,,,,,,,,,,,,
,3540401920.344,299.601226806641,2.32475757598877,-5.81316185539928E-6,9.78479854273498E-9,1,1,13.9012460708618,7.98210133966826,32.5399996340275,-0.011594627335354,-0.0017431868760321,1,1.80568831556794E-8,-5.81316185539928E-6,1.80568831556794E-8,,,,,,,,,,,,,,,,,,,,,299.600921630859,299.601531982422,2.32475757598877,2.32475757598877,52.4691592389286,5.67473918954129,6.65439033508301,14,1,0,0,0,0.500869750976562,34.2131004333496,1,1,1,299.601531982422,0,,,,,,,,,,,,,,,,